Workbook

Sheet 담당자별 현황
A1: SQ 요청 회신 현황 — 담당자별 (회신 기한 2026-11-05 · 한온 SQ 심사 2026-12-10 · 담당자 정정본4 기준 2026-10-28)
A2: '상세' 시트의 발송일·회신 상태를 입력하면 자동 집계됩니다. 지연 = 발송했으나 회신 완료가 아니고 기한이 지난 건(오늘 기준). 담당자는 정정본4 기준(미지정 4건은 2026-10-28 지성규·이광재로 확정)이며 인쇄물 전달 당시와 다른 건은 상세 R열에 표시했습니다. SQ NO 목록은 2026-10-27 기준(보완 필요는 상세 참고).
A4: 담당자 | B4: 발송 메시지 | C4: 총 건수 | D4: 판단 보류 | E4: 미비 | F4: 보완 필요 | G4: 보유 확인 | H4: 미발송 | I4: 발송(회신 대기) | J4: 일부 회신 | K4: 재요청 | L4: 회신 완료 | M4: 회신율 | N4: 미회신(회신 완료 제외) | O4: 지연 | P4: 조치 완료 | Q4: 최근 발송일 | R4: 가장 이른 미회신 기한 | S4: 다음 조치 | T4: 판단 보류 SQ NO | U4: 미비 SQ NO | V4: 보유 확인 SQ NO | W4: 한 통 묶음 여부
A5: 지성규 | B5: 메시지_지성규.txt | C5: =COUNTIFS(상세!$H:$H,$A5) | D5: =COUNTIFS(상세!$H:$H,$A5,상세!$E:$E,"판단 보류") | E5: =COUNTIFS(상세!$H:$H,$A5,상세!$E:$E,"미비") | F5: =COUNTIFS(상세!$H:$H,$A5,상세!$E:$E,"보완 필요") | G5: =COUNTIFS(상세!$H:$H,$A5,상세!$E:$E,"보유 확인") | H5: =COUNTIFS(상세!$H:$H,$A5,상세!$L:$L,"미발송") | I5: =COUNTIFS(상세!$H:$H,$A5,상세!$L:$L,"발송(회신 대기)") | J5: =COUNTIFS(상세!$H:$H,$A5,상세!$L:$L,"일부 회신") | K5: =COUNTIFS(상세!$H:$H,$A5,상세!$L:$L,"재요청") | L5: =COUNTIFS(상세!$H:$H,$A5,상세!$L:$L,"회신 완료") | M5: =IF(C5=0,0,L5/C5) | N5: =COUNTIFS(상세!$H:$H,$A5,상세!$L:$L,"<>회신 완료") | O5: =COUNTIFS(상세!$H:$H,$A5,상세!$L:$L,"<>회신 완료",상세!$K:$K,"<>",상세!$J:$J,"<"&TODAY()) | P5: =COUNTIFS(상세!$H:$H,$A5,상세!$Q:$Q,"완료") | Q5: =IF(COUNTIFS(상세!$H:$H,$A5,상세!$K:$K,"<>")=0,"",_xlfn.MAXIFS(상세!$K:$K,상세!$H:$H,$A5)) | R5: =IF(N5=0,"",_xlfn.MINIFS(상세!$J:$J,상세!$H:$H,$A5,상세!$L:$L,"<>회신 완료")) | S5: =IF(C5=L5,"회신 완료 — 조치 완료 여부 확인",IF(O5>0,"지연 — 재촉 필요",IF(H5=C5,"발송 필요",IF(H5>0,"일부 미발송 — 확인","회신 대기")))) | T5: 7, 45, 71, 123, 126, 133, 135, 170, 197, 230 | U5: - | V5: 4, 115, 140 | W5: 보유 확인 합쳐 한 통
A6: 이광재 | B6: 메시지_이광재.txt | C6: =COUNTIFS(상세!$H:$H,$A6) | D6: =COUNTIFS(상세!$H:$H,$A6,상세!$E:$E,"판단 보류") | E6: =COUNTIFS(상세!$H:$H,$A6,상세!$E:$E,"미비") | F6: =COUNTIFS(상세!$H:$H,$A6,상세!$E:$E,"보완 필요") | G6: =COUNTIFS(상세!$H:$H,$A6,상세!$E:$E,"보유 확인") | H6: =COUNTIFS(상세!$H:$H,$A6,상세!$L:$L,"미발송") | I6: =COUNTIFS(상세!$H:$H,$A6,상세!$L:$L,"발송(회신 대기)") | J6: =COUNTIFS(상세!$H:$H,$A6,상세!$L:$L,"일부 회신") | K6: =COUNTIFS(상세!$H:$H,$A6,상세!$L:$L,"재요청") | L6: =COUNTIFS(상세!$H:$H,$A6,상세!$L:$L,"회신 완료") | M6: =IF(C6=0,0,L6/C6) | N6: =COUNTIFS(상세!$H:$H,$A6,상세!$L:$L,"<>회신 완료") | O6: =COUNTIFS(상세!$H:$H,$A6,상세!$L:$L,"<>회신 완료",상세!$K:$K,"<>",상세!$J:$J,"<"&TODAY()) | P6: =COUNTIFS(상세!$H:$H,$A6,상세!$Q:$Q,"완료") | Q6: =IF(COUNTIFS(상세!$H:$H,$A6,상세!$K:$K,"<>")=0,"",_xlfn.MAXIFS(상세!$K:$K,상세!$H:$H,$A6)) | R6: =IF(N6=0,"",_xlfn.MINIFS(상세!$J:$J,상세!$H:$H,$A6,상세!$L:$L,"<>회신 완료")) | S6: =IF(C6=L6,"회신 완료 — 조치 완료 여부 확인",IF(O6>0,"지연 — 재촉 필요",IF(H6=C6,"발송 필요",IF(H6>0,"일부 미발송 — 확인","회신 대기")))) | T6: 14, 15, 41, 185 | U6: - | V6: - | W6: 보유 확인 합쳐 한 통
A7: 김명용 | B7: 메시지_김명용.txt | C7: =COUNTIFS(상세!$H:$H,$A7) | D7: =COUNTIFS(상세!$H:$H,$A7,상세!$E:$E,"판단 보류") | E7: =COUNTIFS(상세!$H:$H,$A7,상세!$E:$E,"미비") | F7: =COUNTIFS(상세!$H:$H,$A7,상세!$E:$E,"보완 필요") | G7: =COUNTIFS(상세!$H:$H,$A7,상세!$E:$E,"보유 확인") | H7: =COUNTIFS(상세!$H:$H,$A7,상세!$L:$L,"미발송") | I7: =COUNTIFS(상세!$H:$H,$A7,상세!$L:$L,"발송(회신 대기)") | J7: =COUNTIFS(상세!$H:$H,$A7,상세!$L:$L,"일부 회신") | K7: =COUNTIFS(상세!$H:$H,$A7,상세!$L:$L,"재요청") | L7: =COUNTIFS(상세!$H:$H,$A7,상세!$L:$L,"회신 완료") | M7: =IF(C7=0,0,L7/C7) | N7: =COUNTIFS(상세!$H:$H,$A7,상세!$L:$L,"<>회신 완료") | O7: =COUNTIFS(상세!$H:$H,$A7,상세!$L:$L,"<>회신 완료",상세!$K:$K,"<>",상세!$J:$J,"<"&TODAY()) | P7: =COUNTIFS(상세!$H:$H,$A7,상세!$Q:$Q,"완료") | Q7: =IF(COUNTIFS(상세!$H:$H,$A7,상세!$K:$K,"<>")=0,"",_xlfn.MAXIFS(상세!$K:$K,상세!$H:$H,$A7)) | R7: =IF(N7=0,"",_xlfn.MINIFS(상세!$J:$J,상세!$H:$H,$A7,상세!$L:$L,"<>회신 완료")) | S7: =IF(C7=L7,"회신 완료 — 조치 완료 여부 확인",IF(O7>0,"지연 — 재촉 필요",IF(H7=C7,"발송 필요",IF(H7>0,"일부 미발송 — 확인","회신 대기")))) | T7: 51, 75, 76, 224 | U7: - | V7: - | W7: 요청만
A8: 이은주 | B8: 메시지_이은주.txt | C8: =COUNTIFS(상세!$H:$H,$A8) | D8: =COUNTIFS(상세!$H:$H,$A8,상세!$E:$E,"판단 보류") | E8: =COUNTIFS(상세!$H:$H,$A8,상세!$E:$E,"미비") | F8: =COUNTIFS(상세!$H:$H,$A8,상세!$E:$E,"보완 필요") | G8: =COUNTIFS(상세!$H:$H,$A8,상세!$E:$E,"보유 확인") | H8: =COUNTIFS(상세!$H:$H,$A8,상세!$L:$L,"미발송") | I8: =COUNTIFS(상세!$H:$H,$A8,상세!$L:$L,"발송(회신 대기)") | J8: =COUNTIFS(상세!$H:$H,$A8,상세!$L:$L,"일부 회신") | K8: =COUNTIFS(상세!$H:$H,$A8,상세!$L:$L,"재요청") | L8: =COUNTIFS(상세!$H:$H,$A8,상세!$L:$L,"회신 완료") | M8: =IF(C8=0,0,L8/C8) | N8: =COUNTIFS(상세!$H:$H,$A8,상세!$L:$L,"<>회신 완료") | O8: =COUNTIFS(상세!$H:$H,$A8,상세!$L:$L,"<>회신 완료",상세!$K:$K,"<>",상세!$J:$J,"<"&TODAY()) | P8: =COUNTIFS(상세!$H:$H,$A8,상세!$Q:$Q,"완료") | Q8: =IF(COUNTIFS(상세!$H:$H,$A8,상세!$K:$K,"<>")=0,"",_xlfn.MAXIFS(상세!$K:$K,상세!$H:$H,$A8)) | R8: =IF(N8=0,"",_xlfn.MINIFS(상세!$J:$J,상세!$H:$H,$A8,상세!$L:$L,"<>회신 완료")) | S8: =IF(C8=L8,"회신 완료 — 조치 완료 여부 확인",IF(O8>0,"지연 — 재촉 필요",IF(H8=C8,"발송 필요",IF(H8>0,"일부 미발송 — 확인","회신 대기")))) | T8: 142, 143, 145, 155 | U8: - | V8: 147 | W8: 보유 확인 합쳐 한 통
A9: 황지환 | B9: 메시지_황지환.txt | C9: =COUNTIFS(상세!$H:$H,$A9) | D9: =COUNTIFS(상세!$H:$H,$A9,상세!$E:$E,"판단 보류") | E9: =COUNTIFS(상세!$H:$H,$A9,상세!$E:$E,"미비") | F9: =COUNTIFS(상세!$H:$H,$A9,상세!$E:$E,"보완 필요") | G9: =COUNTIFS(상세!$H:$H,$A9,상세!$E:$E,"보유 확인") | H9: =COUNTIFS(상세!$H:$H,$A9,상세!$L:$L,"미발송") | I9: =COUNTIFS(상세!$H:$H,$A9,상세!$L:$L,"발송(회신 대기)") | J9: =COUNTIFS(상세!$H:$H,$A9,상세!$L:$L,"일부 회신") | K9: =COUNTIFS(상세!$H:$H,$A9,상세!$L:$L,"재요청") | L9: =COUNTIFS(상세!$H:$H,$A9,상세!$L:$L,"회신 완료") | M9: =IF(C9=0,0,L9/C9) | N9: =COUNTIFS(상세!$H:$H,$A9,상세!$L:$L,"<>회신 완료") | O9: =COUNTIFS(상세!$H:$H,$A9,상세!$L:$L,"<>회신 완료",상세!$K:$K,"<>",상세!$J:$J,"<"&TODAY()) | P9: =COUNTIFS(상세!$H:$H,$A9,상세!$Q:$Q,"완료") | Q9: =IF(COUNTIFS(상세!$H:$H,$A9,상세!$K:$K,"<>")=0,"",_xlfn.MAXIFS(상세!$K:$K,상세!$H:$H,$A9)) | R9: =IF(N9=0,"",_xlfn.MINIFS(상세!$J:$J,상세!$H:$H,$A9,상세!$L:$L,"<>회신 완료")) | S9: =IF(C9=L9,"회신 완료 — 조치 완료 여부 확인",IF(O9>0,"지연 — 재촉 필요",IF(H9=C9,"발송 필요",IF(H9>0,"일부 미발송 — 확인","회신 대기")))) | T9: 77, 99 | U9: - | V9: 19 | W9: 요청만
A10: 한상돈 | B10: 메시지_한상돈.txt | C10: =COUNTIFS(상세!$H:$H,$A10) | D10: =COUNTIFS(상세!$H:$H,$A10,상세!$E:$E,"판단 보류") | E10: =COUNTIFS(상세!$H:$H,$A10,상세!$E:$E,"미비") | F10: =COUNTIFS(상세!$H:$H,$A10,상세!$E:$E,"보완 필요") | G10: =COUNTIFS(상세!$H:$H,$A10,상세!$E:$E,"보유 확인") | H10: =COUNTIFS(상세!$H:$H,$A10,상세!$L:$L,"미발송") | I10: =COUNTIFS(상세!$H:$H,$A10,상세!$L:$L,"발송(회신 대기)") | J10: =COUNTIFS(상세!$H:$H,$A10,상세!$L:$L,"일부 회신") | K10: =COUNTIFS(상세!$H:$H,$A10,상세!$L:$L,"재요청") | L10: =COUNTIFS(상세!$H:$H,$A10,상세!$L:$L,"회신 완료") | M10: =IF(C10=0,0,L10/C10) | N10: =COUNTIFS(상세!$H:$H,$A10,상세!$L:$L,"<>회신 완료") | O10: =COUNTIFS(상세!$H:$H,$A10,상세!$L:$L,"<>회신 완료",상세!$K:$K,"<>",상세!$J:$J,"<"&TODAY()) | P10: =COUNTIFS(상세!$H:$H,$A10,상세!$Q:$Q,"완료") | Q10: =IF(COUNTIFS(상세!$H:$H,$A10,상세!$K:$K,"<>")=0,"",_xlfn.MAXIFS(상세!$K:$K,상세!$H:$H,$A10)) | R10: =IF(N10=0,"",_xlfn.MINIFS(상세!$J:$J,상세!$H:$H,$A10,상세!$L:$L,"<>회신 완료")) | S10: =IF(C10=L10,"회신 완료 — 조치 완료 여부 확인",IF(O10>0,"지연 — 재촉 필요",IF(H10=C10,"발송 필요",IF(H10>0,"일부 미발송 — 확인","회신 대기")))) | T10: 83, 84, 88 | U10: - | V10: 86 | W10: 요청만
A11: 김주태 | B11: 메시지_김주태.txt | C11: =COUNTIFS(상세!$H:$H,$A11) | D11: =COUNTIFS(상세!$H:$H,$A11,상세!$E:$E,"판단 보류") | E11: =COUNTIFS(상세!$H:$H,$A11,상세!$E:$E,"미비") | F11: =COUNTIFS(상세!$H:$H,$A11,상세!$E:$E,"보완 필요") | G11: =COUNTIFS(상세!$H:$H,$A11,상세!$E:$E,"보유 확인") | H11: =COUNTIFS(상세!$H:$H,$A11,상세!$L:$L,"미발송") | I11: =COUNTIFS(상세!$H:$H,$A11,상세!$L:$L,"발송(회신 대기)") | J11: =COUNTIFS(상세!$H:$H,$A11,상세!$L:$L,"일부 회신") | K11: =COUNTIFS(상세!$H:$H,$A11,상세!$L:$L,"재요청") | L11: =COUNTIFS(상세!$H:$H,$A11,상세!$L:$L,"회신 완료") | M11: =IF(C11=0,0,L11/C11) | N11: =COUNTIFS(상세!$H:$H,$A11,상세!$L:$L,"<>회신 완료") | O11: =COUNTIFS(상세!$H:$H,$A11,상세!$L:$L,"<>회신 완료",상세!$K:$K,"<>",상세!$J:$J,"<"&TODAY()) | P11: =COUNTIFS(상세!$H:$H,$A11,상세!$Q:$Q,"완료") | Q11: =IF(COUNTIFS(상세!$H:$H,$A11,상세!$K:$K,"<>")=0,"",_xlfn.MAXIFS(상세!$K:$K,상세!$H:$H,$A11)) | R11: =IF(N11=0,"",_xlfn.MINIFS(상세!$J:$J,상세!$H:$H,$A11,상세!$L:$L,"<>회신 완료")) | S11: =IF(C11=L11,"회신 완료 — 조치 완료 여부 확인",IF(O11>0,"지연 — 재촉 필요",IF(H11=C11,"발송 필요",IF(H11>0,"일부 미발송 — 확인","회신 대기")))) | T11: - | U11: - | V11: - | W11: 요청만
A12: 박철호 | B12: 메시지_박철호.txt | C12: =COUNTIFS(상세!$H:$H,$A12) | D12: =COUNTIFS(상세!$H:$H,$A12,상세!$E:$E,"판단 보류") | E12: =COUNTIFS(상세!$H:$H,$A12,상세!$E:$E,"미비") | F12: =COUNTIFS(상세!$H:$H,$A12,상세!$E:$E,"보완 필요") | G12: =COUNTIFS(상세!$H:$H,$A12,상세!$E:$E,"보유 확인") | H12: =COUNTIFS(상세!$H:$H,$A12,상세!$L:$L,"미발송") | I12: =COUNTIFS(상세!$H:$H,$A12,상세!$L:$L,"발송(회신 대기)") | J12: =COUNTIFS(상세!$H:$H,$A12,상세!$L:$L,"일부 회신") | K12: =COUNTIFS(상세!$H:$H,$A12,상세!$L:$L,"재요청") | L12: =COUNTIFS(상세!$H:$H,$A12,상세!$L:$L,"회신 완료") | M12: =IF(C12=0,0,L12/C12) | N12: =COUNTIFS(상세!$H:$H,$A12,상세!$L:$L,"<>회신 완료") | O12: =COUNTIFS(상세!$H:$H,$A12,상세!$L:$L,"<>회신 완료",상세!$K:$K,"<>",상세!$J:$J,"<"&TODAY()) | P12: =COUNTIFS(상세!$H:$H,$A12,상세!$Q:$Q,"완료") | Q12: =IF(COUNTIFS(상세!$H:$H,$A12,상세!$K:$K,"<>")=0,"",_xlfn.MAXIFS(상세!$K:$K,상세!$H:$H,$A12)) | R12: =IF(N12=0,"",_xlfn.MINIFS(상세!$J:$J,상세!$H:$H,$A12,상세!$L:$L,"<>회신 완료")) | S12: =IF(C12=L12,"회신 완료 — 조치 완료 여부 확인",IF(O12>0,"지연 — 재촉 필요",IF(H12=C12,"발송 필요",IF(H12>0,"일부 미발송 — 확인","회신 대기")))) | T12: - | U12: - | V12: - | W12: 요청만
A13: 김운주 | B13: 메시지_김운주.txt | C13: =COUNTIFS(상세!$H:$H,$A13) | D13: =COUNTIFS(상세!$H:$H,$A13,상세!$E:$E,"판단 보류") | E13: =COUNTIFS(상세!$H:$H,$A13,상세!$E:$E,"미비") | F13: =COUNTIFS(상세!$H:$H,$A13,상세!$E:$E,"보완 필요") | G13: =COUNTIFS(상세!$H:$H,$A13,상세!$E:$E,"보유 확인") | H13: =COUNTIFS(상세!$H:$H,$A13,상세!$L:$L,"미발송") | I13: =COUNTIFS(상세!$H:$H,$A13,상세!$L:$L,"발송(회신 대기)") | J13: =COUNTIFS(상세!$H:$H,$A13,상세!$L:$L,"일부 회신") | K13: =COUNTIFS(상세!$H:$H,$A13,상세!$L:$L,"재요청") | L13: =COUNTIFS(상세!$H:$H,$A13,상세!$L:$L,"회신 완료") | M13: =IF(C13=0,0,L13/C13) | N13: =COUNTIFS(상세!$H:$H,$A13,상세!$L:$L,"<>회신 완료") | O13: =COUNTIFS(상세!$H:$H,$A13,상세!$L:$L,"<>회신 완료",상세!$K:$K,"<>",상세!$J:$J,"<"&TODAY()) | P13: =COUNTIFS(상세!$H:$H,$A13,상세!$Q:$Q,"완료") | Q13: =IF(COUNTIFS(상세!$H:$H,$A13,상세!$K:$K,"<>")=0,"",_xlfn.MAXIFS(상세!$K:$K,상세!$H:$H,$A13)) | R13: =IF(N13=0,"",_xlfn.MINIFS(상세!$J:$J,상세!$H:$H,$A13,상세!$L:$L,"<>회신 완료")) | S13: =IF(C13=L13,"회신 완료 — 조치 완료 여부 확인",IF(O13>0,"지연 — 재촉 필요",IF(H13=C13,"발송 필요",IF(H13>0,"일부 미발송 — 확인","회신 대기")))) | T13: 102 | U13: - | V13: - | W13: 요청만
A14: 안종명 | B14: 메시지_안종명.txt | C14: =COUNTIFS(상세!$H:$H,$A14) | D14: =COUNTIFS(상세!$H:$H,$A14,상세!$E:$E,"판단 보류") | E14: =COUNTIFS(상세!$H:$H,$A14,상세!$E:$E,"미비") | F14: =COUNTIFS(상세!$H:$H,$A14,상세!$E:$E,"보완 필요") | G14: =COUNTIFS(상세!$H:$H,$A14,상세!$E:$E,"보유 확인") | H14: =COUNTIFS(상세!$H:$H,$A14,상세!$L:$L,"미발송") | I14: =COUNTIFS(상세!$H:$H,$A14,상세!$L:$L,"발송(회신 대기)") | J14: =COUNTIFS(상세!$H:$H,$A14,상세!$L:$L,"일부 회신") | K14: =COUNTIFS(상세!$H:$H,$A14,상세!$L:$L,"재요청") | L14: =COUNTIFS(상세!$H:$H,$A14,상세!$L:$L,"회신 완료") | M14: =IF(C14=0,0,L14/C14) | N14: =COUNTIFS(상세!$H:$H,$A14,상세!$L:$L,"<>회신 완료") | O14: =COUNTIFS(상세!$H:$H,$A14,상세!$L:$L,"<>회신 완료",상세!$K:$K,"<>",상세!$J:$J,"<"&TODAY()) | P14: =COUNTIFS(상세!$H:$H,$A14,상세!$Q:$Q,"완료") | Q14: =IF(COUNTIFS(상세!$H:$H,$A14,상세!$K:$K,"<>")=0,"",_xlfn.MAXIFS(상세!$K:$K,상세!$H:$H,$A14)) | R14: =IF(N14=0,"",_xlfn.MINIFS(상세!$J:$J,상세!$H:$H,$A14,상세!$L:$L,"<>회신 완료")) | S14: =IF(C14=L14,"회신 완료 — 조치 완료 여부 확인",IF(O14>0,"지연 — 재촉 필요",IF(H14=C14,"발송 필요",IF(H14>0,"일부 미발송 — 확인","회신 대기")))) | T14: 233 | U14: - | V14: - | W14: 요청만
A15: 이은주·박철호(공동) | B15: 메시지_이은주_박철호공동.txt | C15: =COUNTIFS(상세!$H:$H,$A15) | D15: =COUNTIFS(상세!$H:$H,$A15,상세!$E:$E,"판단 보류") | E15: =COUNTIFS(상세!$H:$H,$A15,상세!$E:$E,"미비") | F15: =COUNTIFS(상세!$H:$H,$A15,상세!$E:$E,"보완 필요") | G15: =COUNTIFS(상세!$H:$H,$A15,상세!$E:$E,"보유 확인") | H15: =COUNTIFS(상세!$H:$H,$A15,상세!$L:$L,"미발송") | I15: =COUNTIFS(상세!$H:$H,$A15,상세!$L:$L,"발송(회신 대기)") | J15: =COUNTIFS(상세!$H:$H,$A15,상세!$L:$L,"일부 회신") | K15: =COUNTIFS(상세!$H:$H,$A15,상세!$L:$L,"재요청") | L15: =COUNTIFS(상세!$H:$H,$A15,상세!$L:$L,"회신 완료") | M15: =IF(C15=0,0,L15/C15) | N15: =COUNTIFS(상세!$H:$H,$A15,상세!$L:$L,"<>회신 완료") | O15: =COUNTIFS(상세!$H:$H,$A15,상세!$L:$L,"<>회신 완료",상세!$K:$K,"<>",상세!$J:$J,"<"&TODAY()) | P15: =COUNTIFS(상세!$H:$H,$A15,상세!$Q:$Q,"완료") | Q15: =IF(COUNTIFS(상세!$H:$H,$A15,상세!$K:$K,"<>")=0,"",_xlfn.MAXIFS(상세!$K:$K,상세!$H:$H,$A15)) | R15: =IF(N15=0,"",_xlfn.MINIFS(상세!$J:$J,상세!$H:$H,$A15,상세!$L:$L,"<>회신 완료")) | S15: =IF(C15=L15,"회신 완료 — 조치 완료 여부 확인",IF(O15>0,"지연 — 재촉 필요",IF(H15=C15,"발송 필요",IF(H15>0,"일부 미발송 — 확인","회신 대기")))) | T15: - | U15: - | V15: - | W15: 요청만
A16: (미지정) | B16: (담당자 미지정) | C16: =COUNTIFS(상세!$H:$H,$A16) | D16: =COUNTIFS(상세!$H:$H,$A16,상세!$E:$E,"판단 보류") | E16: =COUNTIFS(상세!$H:$H,$A16,상세!$E:$E,"미비") | F16: =COUNTIFS(상세!$H:$H,$A16,상세!$E:$E,"보완 필요") | G16: =COUNTIFS(상세!$H:$H,$A16,상세!$E:$E,"보유 확인") | H16: =COUNTIFS(상세!$H:$H,$A16,상세!$L:$L,"미발송") | I16: =COUNTIFS(상세!$H:$H,$A16,상세!$L:$L,"발송(회신 대기)") | J16: =COUNTIFS(상세!$H:$H,$A16,상세!$L:$L,"일부 회신") | K16: =COUNTIFS(상세!$H:$H,$A16,상세!$L:$L,"재요청") | L16: =COUNTIFS(상세!$H:$H,$A16,상세!$L:$L,"회신 완료") | M16: =IF(C16=0,0,L16/C16) | N16: =COUNTIFS(상세!$H:$H,$A16,상세!$L:$L,"<>회신 완료") | O16: =COUNTIFS(상세!$H:$H,$A16,상세!$L:$L,"<>회신 완료",상세!$K:$K,"<>",상세!$J:$J,"<"&TODAY()) | P16: =COUNTIFS(상세!$H:$H,$A16,상세!$Q:$Q,"완료") | Q16: =IF(COUNTIFS(상세!$H:$H,$A16,상세!$K:$K,"<>")=0,"",_xlfn.MAXIFS(상세!$K:$K,상세!$H:$H,$A16)) | R16: =IF(N16=0,"",_xlfn.MINIFS(상세!$J:$J,상세!$H:$H,$A16,상세!$L:$L,"<>회신 완료")) | S16: =IF(C16=L16,"회신 완료 — 조치 완료 여부 확인",IF(O16>0,"지연 — 재촉 필요",IF(H16=C16,"발송 필요",IF(H16>0,"일부 미발송 — 확인","회신 대기")))) | T16: - | U16: - | V16: - | W16: 담당자 지정 필요
A17: 합계 | C17: =SUM(C5:C16) | D17: =SUM(D5:D16) | E17: =SUM(E5:E16) | F17: =SUM(F5:F16) | G17: =SUM(G5:G16) | H17: =SUM(H5:H16) | I17: =SUM(I5:I16) | J17: =SUM(J5:J16) | ... L17: =SUM(L5:L16) | M17: =IF(C17=0,0,L17/C17) | N17: =SUM(N5:N16) | O17: =SUM(O5:O16) | P17: =SUM(P5:P16)

Sheet 유형별 현황
A1: 요청 유형별 현황
A3: 요청 유형 | B3: 총 건수 | C3: 미발송 | D3: 발송(회신 대기) | E3: 일부 회신 | F3: 재요청 | G3: 회신 완료 | H3: 회신율 | I3: 조치 완료
A4: 판단 보류 | B4: =COUNTIFS(상세!$E:$E,$A4) | C4: =COUNTIFS(상세!$E:$E,$A4,상세!$L:$L,"미발송") | D4: =COUNTIFS(상세!$E:$E,$A4,상세!$L:$L,"발송(회신 대기)") | E4: =COUNTIFS(상세!$E:$E,$A4,상세!$L:$L,"일부 회신") | F4: =COUNTIFS(상세!$E:$E,$A4,상세!$L:$L,"재요청") | G4: =COUNTIFS(상세!$E:$E,$A4,상세!$L:$L,"회신 완료") | H4: =IF(B4=0,0,G4/B4) | I4: =COUNTIFS(상세!$E:$E,$A4,상세!$Q:$Q,"완료")
A5: 미비 | B5: =COUNTIFS(상세!$E:$E,$A5) | C5: =COUNTIFS(상세!$E:$E,$A5,상세!$L:$L,"미발송") | D5: =COUNTIFS(상세!$E:$E,$A5,상세!$L:$L,"발송(회신 대기)") | E5: =COUNTIFS(상세!$E:$E,$A5,상세!$L:$L,"일부 회신") | F5: =COUNTIFS(상세!$E:$E,$A5,상세!$L:$L,"재요청") | G5: =COUNTIFS(상세!$E:$E,$A5,상세!$L:$L,"회신 완료") | H5: =IF(B5=0,0,G5/B5) | I5: =COUNTIFS(상세!$E:$E,$A5,상세!$Q:$Q,"완료")
A6: 보완 필요 | B6: =COUNTIFS(상세!$E:$E,$A6) | C6: =COUNTIFS(상세!$E:$E,$A6,상세!$L:$L,"미발송") | D6: =COUNTIFS(상세!$E:$E,$A6,상세!$L:$L,"발송(회신 대기)") | E6: =COUNTIFS(상세!$E:$E,$A6,상세!$L:$L,"일부 회신") | F6: =COUNTIFS(상세!$E:$E,$A6,상세!$L:$L,"재요청") | G6: =COUNTIFS(상세!$E:$E,$A6,상세!$L:$L,"회신 완료") | H6: =IF(B6=0,0,G6/B6) | I6: =COUNTIFS(상세!$E:$E,$A6,상세!$Q:$Q,"완료")
A7: 보유 확인 | B7: =COUNTIFS(상세!$E:$E,$A7) | C7: =COUNTIFS(상세!$E:$E,$A7,상세!$L:$L,"미발송") | D7: =COUNTIFS(상세!$E:$E,$A7,상세!$L:$L,"발송(회신 대기)") | E7: =COUNTIFS(상세!$E:$E,$A7,상세!$L:$L,"일부 회신") | F7: =COUNTIFS(상세!$E:$E,$A7,상세!$L:$L,"재요청") | G7: =COUNTIFS(상세!$E:$E,$A7,상세!$L:$L,"회신 완료") | H7: =IF(B7=0,0,G7/B7) | I7: =COUNTIFS(상세!$E:$E,$A7,상세!$Q:$Q,"완료")
A8: 합계 | B8: =SUM(B4:B7) | C8: =SUM(C4:C7) | D8: =SUM(D4:D7) | E8: =SUM(E4:E7) | F8: =SUM(F4:F7) | G8: =SUM(G4:G7) | H8: =IF(B8=0,0,G8/B8) | I8: =SUM(I4:I7)

Sheet 상세
A1: SQ NO | B1: 분야 | C1: 번호 | D1: 필요서류 | E1: 요청 유형 | F1: 배정 FM | G1: 대표 FM | H1: 담당자 | I1: 발송 메시지 파일 | J1: 회신 기한 | K1: 발송일(입력) | L1: 회신 상태(입력) | M1: 회신일(입력) | N1: 회신 내용 요약(입력) | O1: 확인자(입력) | P1: 회신 후 필요한 조치 | Q1: 조치 완료(입력) | R1: 메모 | S1: 기한까지 남은 일수 | T1: 기한 상태
A2: 51 | B2: 검사시험 | C2: 2-5 | D2: 계측기관리대장 | E2: 판단 보류 | F2: SH-FM-173 | G2: SH-FM-023 | H2: 김명용 | I2: 발송용_담당자변경_20261027/메시지_김명용_20261027.txt | J2: 46331 | K2: 46322 | L2: 발송(회신 대기) | P2: 원본 양식·승인 증빙 확보 → 대표 번호 릴리스 여부 결정 | Q2: 미완료 | R2: 담당자 변경 재안내 발송 2026-10-27 | S2: =IF(L2="회신 완료","",J2-TODAY()) | T2: =IF(L2="회신 완료","완료",IF(J2<TODAY(),"지연",IF(J2-TODAY()<=1,"임박(D-1 이내)",IF(J2-TODAY()<=3,"임박(D-3 이내)","여유"))))
A3: 75 | B3: 검사시험 | C3: 2-8 | D3: 완성품보관장소선정 | E3: 판단 보류 | F3: SH-FM-197 | G3: SH-FM-197 | H3: 김명용 | I3: 발송용_담당자변경_20261027/메시지_김명용_20261027.txt | J3: 46331 | K3: 46322 | L3: 발송(회신 대기) | P3: 현물 증빙(사진·위치) 확인 → 매핑표에 현물 보유 반영 검토 | Q3: 미완료 | R3: 담당자 변경 재안내 발송 2026-10-27 | S3: =IF(L3="회신 완료","",J3-TODAY()) | T3: =IF(L3="회신 완료","완료",IF(J3<TODAY(),"지연",IF(J3-TODAY()<=1,"임박(D-1 이내)",IF(J3-TODAY()<=3,"임박(D-3 이내)","여유"))))
A4: 76 | B4: 검사시험 | C4: 2-8 | D4: 완성검사관리대제작 | E4: 판단 보류 | F4: SH-FM-198 | G4: SH-FM-198 | H4: 김명용 | I4: 발송용_담당자변경_20261027/메시지_김명용_20261027.txt | J4: 46331 | K4: 46322 | L4: 발송(회신 대기) | P4: 현물 증빙(사진·위치) 확인 → 매핑표에 현물 보유 반영 검토 | Q4: 미완료 | R4: 담당자 변경 재안내 발송 2026-10-27 | S4: =IF(L4="회신 완료","",J4-TODAY()) | T4: =IF(L4="회신 완료","완료",IF(J4<TODAY(),"지연",IF(J4-TODAY()<=1,"임박(D-1 이내)",IF(J4-TODAY()<=3,"임박(D-3 이내)","여유"))))
A5: 77 | B5: 검사시험 | C5: 2-8 | D5: (QMS SYSTEM 운영시 컴퓨터설치운영) | E5: 판단 보류 | F5: SH-FM-199 | G5: SH-FM-199 | H5: 황지환 | I5: 발송용_담당자변경_20261027/메시지_황지환_20261027.txt | J5: 46331 | K5: 46322 | L5: 발송(회신 대기) | P5: 현물 증빙(사진·위치) 확인 → 매핑표에 현물 보유 반영 검토 | Q5: 미완료 | R5: 담당자 정정본3 기준 변경(인쇄물 전달 당시: 김명용); 담당자 변경 재안내 발송 2026-10-27 | S5: =IF(L5="회신 완료","",J5-TODAY()) | T5: =IF(L5="회신 완료","완료",IF(J5<TODAY(),"지연",IF(J5-TODAY()<=1,"임박(D-1 이내)",IF(J5-TODAY()<=3,"임박(D-3 이내)","여유"))))
A6: 224 | B6: 품질경영체제 | C6: 6-11 | D6: 품질종합현황판 제작설치 | E6: 판단 보류 | F6: SH-FM-346 | G6: SH-FM-346 | H6: 김명용 | I6: 발송용_담당자변경_20261027/메시지_김명용_20261027.txt | J6: 46331 | K6: 46322 | L6: 발송(회신 대기) | P6: 현물 증빙(사진·위치) 확인 → 매핑표에 현물 보유 반영 검토 | Q6: 미완료 | R6: 담당자 변경 재안내 발송 2026-10-27 | S6: =IF(L6="회신 완료","",J6-TODAY()) | T6: =IF(L6="회신 완료","완료",IF(J6<TODAY(),"지연",IF(J6-TODAY()<=1,"임박(D-1 이내)",IF(J6-TODAY()<=3,"임박(D-3 이내)","여유"))))
A7: 38 | B7: 검사시험 | C7: 2-2 | D7: 외주품 수입검사기준서 | E7: 보완 필요 | F7: SH-FM-160 | G7: SH-FM-160 | H7: 김명용 | I7: 발송용_담당자변경_20261027/메시지_김명용_20261027.txt | J7: 46331 | K7: 46322 | L7: 발송(회신 대기) | P7: 항목·기준 작성 파일 수령 → 같은 Rev.00 재개정(recheck → 승인·배포) → 매핑표 '보유'로 갱신 | Q7: 미완료 | R7: 담당자 변경 재안내 발송 2026-10-27 | S7: =IF(L7="회신 완료","",J7-TODAY()) | T7: =IF(L7="회신 완료","완료",IF(J7<TODAY(),"지연",IF(J7-TODAY()<=1,"임박(D-1 이내)",IF(J7-TODAY()<=3,"임박(D-3 이내)","여유"))))
A8: 40 | B8: 검사시험 | C8: 2-2 | D8: 외주품 부적합처리기준서 | E8: 보완 필요 | F8: SH-FM-162 | G8: SH-FM-162 | H8: 김명용 | I8: 발송용_담당자변경_20261027/메시지_김명용_20261027.txt | J8: 46331 | K8: 46322 | L8: 발송(회신 대기) | P8: 항목·기준 작성 파일 수령 → 같은 Rev.00 재개정(recheck → 승인·배포) → 매핑표 '보유'로 갱신 | Q8: 미완료 | R8: 담당자 변경 재안내 발송 2026-10-27 | S8: =IF(L8="회신 완료","",J8-TODAY()) | T8: =IF(L8="회신 완료","완료",IF(J8<TODAY(),"지연",IF(J8-TODAY()<=1,"임박(D-1 이내)",IF(J8-TODAY()<=3,"임박(D-3 이내)","여유"))))
A9: 42 | B9: 검사시험 | C9: 2-2 | D9: 외주품 검사기준서 | E9: 보완 필요 | F9: SH-FM-164 | G9: SH-FM-160 | H9: 김명용 | I9: 발송용_담당자변경_20261027/메시지_김명용_20261027.txt | J9: 46331 | K9: 46322 | L9: 발송(회신 대기) | P9: 항목·기준 작성 파일 수령 → 같은 Rev.00 재개정(recheck → 승인·배포) → 매핑표 '보유'로 갱신 | Q9: 미완료 | R9: 담당자 변경 재안내 발송 2026-10-27 | S9: =IF(L9="회신 완료","",J9-TODAY()) | T9: =IF(L9="회신 완료","완료",IF(J9<TODAY(),"지연",IF(J9-TODAY()<=1,"임박(D-1 이내)",IF(J9-TODAY()<=3,"임박(D-3 이내)","여유"))))
A10: 43 | B10: 검사시험 | C10: 2-3 | D10: 한도견본 관리대장(외주품/완성품) | E10: 보완 필요 | F10: SH-FM-165 | G10: SH-FM-165 | H10: 김명용 | I10: 발송용_담당자변경_20261027/메시지_김명용_20261027.txt | J10: 46331 | K10: 46322 | L10: 발송(회신 대기) | P10: 항목·기준 작성 파일 수령 → 같은 Rev.00 재개정(recheck → 승인·배포) → 매핑표 '보유'로 갱신 | Q10: 미완료 | R10: 담당자 변경 재안내 발송 2026-10-27 | S10: =IF(L10="회신 완료","",J10-TODAY()) | T10: =IF(L10="회신 완료","완료",IF(J10<TODAY(),"지연",IF(J10-TODAY()<=1,"임박(D-1 이내)",IF(J10-TODAY()<=3,"임박(D-3 이내)","여유"))))
A11: 44 | B11: 검사시험 | C11: 2-3 | D11: 한도견본 식별표 | E11: 보완 필요 | F11: SH-FM-166 | G11: SH-FM-166 | H11: 김명용 | I11: 발송용_담당자변경_20261027/메시지_김명용_20261027.txt | J11: 46331 | K11: 46322 | L11: 발송(회신 대기) | P11: 항목·기준 작성 파일 수령 → 같은 Rev.00 재개정(recheck → 승인·배포) → 매핑표 '보유'로 갱신 | Q11: 미완료 | R11: 담당자 변경 재안내 발송 2026-10-27 | S11: =IF(L11="회신 완료","",J11-TODAY()) | T11: =IF(L11="회신 완료","완료",IF(J11<TODAY(),"지연",IF(J11-TODAY()<=1,"임박(D-1 이내)",IF(J11-TODAY()<=3,"임박(D-3 이내)","여유"))))
A12: 46 | B12: 검사시험 | C12: 2-3 | D12: 외관검사기준서 | E12: 보완 필요 | F12: SH-FM-168 | G12: SH-FM-168 | H12: 김명용 | I12: 발송용_담당자변경_20261027/메시지_김명용_20261027.txt | J12: 46331 | K12: 46322 | L12: 발송(회신 대기) | P12: 항목·기준 작성 파일 수령 → 같은 Rev.00 재개정(recheck → 승인·배포) → 매핑표 '보유'로 갱신 | Q12: 미완료 | R12: 담당자 변경 재안내 발송 2026-10-27 | S12: =IF(L12="회신 완료","",J12-TODAY()) | T12: =IF(L12="회신 완료","완료",IF(J12<TODAY(),"지연",IF(J12-TODAY()<=1,"임박(D-1 이내)",IF(J12-TODAY()<=3,"임박(D-3 이내)","여유"))))
A13: 52 | B13: 검사시험 | C13: 2-5 | D13: 계측기이력카드 | E13: 보완 필요 | F13: SH-FM-174 | G13: SH-FM-174 | H13: 김명용 | I13: 발송용_담당자변경_20261027/메시지_김명용_20261027.txt | J13: 46331 | K13: 46322 | L13: 발송(회신 대기) | P13: 항목·기준 작성 파일 수령 → 같은 Rev.00 재개정(recheck → 승인·배포) → 매핑표 '보유'로 갱신 | Q13: 미완료 | R13: 담당자 변경 재안내 발송 2026-10-27 | S13: =IF(L13="회신 완료","",J13-TODAY()) | T13: =IF(L13="회신 완료","완료",IF(J13<TODAY(),"지연",IF(J13-TODAY()<=1,"임박(D-1 이내)",IF(J13-TODAY()<=3,"임박(D-3 이내)","여유"))))
... A34: 240 | B34: 품질경영체제 | C34: 6-13 | D34: 정성품질 포상실행 품의서 | E34: 보완 필요 | F34: SH-FM-362 | G34: SH-FM-362 | H34: 김명용 | I34: 발송용_담당자변경_20261027/메시지_김명용_20261027.txt | J34: 46331 | K34: 46322 | L34: 발송(회신 대기) | P34: 항목·기준 작성 파일 수령 → 같은 Rev.00 재개정(recheck → 승인·배포) → 매핑표 '보유'로 갱신 | Q34: 미완료 | R34: 담당자 변경 재안내 발송 2026-10-27 | S34: =IF(L34="회신 완료","",J34-TODAY()) | T34: =IF(L34="회신 완료","완료",IF(J34<TODAY(),"지연",IF(J34-TODAY()<=1,"임박(D-1 이내)",IF(J34-TODAY()<=3,"임박(D-3 이내)","여유"))))
A35: 102 | B35: 설비관리 | C35: 3-3 | D35: 용접전극드레싱/교환 F/P장비설치 | E35: 판단 보류 | F35: SH-FM-224 | G35: SH-FM-224 | H35: 김운주 | I35: 발송용_최종_20261008/메시지_김운주.txt | J35: 46331 | K35: 46303 | L35: 발송(회신 대기) | P35: 현물 증빙(사진·위치) 확인 → 매핑표에 현물 보유 반영 검토 | Q35: 미완료 | S35: =IF(L35="회신 완료","",J35-TODAY()) | T35: =IF(L35="회신 완료","완료",IF(J35<TODAY(),"지연",IF(J35-TODAY()<=1,"임박(D-1 이내)",IF(J35-TODAY()<=3,"임박(D-3 이내)","여유"))))
A36: 100 | B36: 설비관리 | C36: 3-3 | D36: CO2용접원점확인장치 | E36: 보완 필요 | F36: SH-FM-222 | G36: SH-FM-222 | H36: 김운주 | I36: 발송용_최종_20261008/메시지_김운주.txt | J36: 46331 | K36: 46303 | L36: 발송(회신 대기) | P36: 항목·기준 작성 파일 수령 → 같은 Rev.00 재개정(recheck → 승인·배포) → 매핑표 '보유'로 갱신 | Q36: 미완료 | S36: =IF(L36="회신 완료","",J36-TODAY()) | T36: =IF(L36="회신 완료","완료",IF(J36<TODAY(),"지연",IF(J36-TODAY()<=1,"임박(D-1 이내)",IF(J36-TODAY()<=3,"임박(D-3 이내)","여유"))))
A37: 101 | B37: 설비관리 | C37: 3-3 | D37: 스폿로봇 원점확인장치 | E37: 보완 필요 | F37: SH-FM-223 | G37: SH-FM-223 | H37: 김운주 | I37: 발송용_최종_20261008/메시지_김운주.txt | J37: 46331 | K37: 46303 | L37: 발송(회신 대기) | P37: 항목·기준 작성 파일 수령 → 같은 Rev.00 재개정(recheck → 승인·배포) → 매핑표 '보유'로 갱신 | Q37: 미완료 | S37: =IF(L37="회신 완료","",J37-TODAY()) | T37: =IF(L37="회신 완료","완료",IF(J37<TODAY(),"지연",IF(J37-TODAY()<=1,"임박(D-1 이내)",IF(J37-TODAY()<=3,"임박(D-3 이내)","여유"))))
A38: 56 | B38: 검사시험 | C38: 2-5 | D38: 검사구관리대장 | E38: 보완 필요 | F38: SH-FM-178 | G38: SH-FM-178 | H38: 김주태 | I38: 발송용_최종_20261008/메시지_김주태.txt | J38: 46331 | K38: 46303 | L38: 발송(회신 대기) | P38: 항목·기준 작성 파일 수령 → 같은 Rev.00 재개정(recheck → 승인·배포) → 매핑표 '보유'로 갱신 | Q38: 미완료 | S38: =IF(L38="회신 완료","",J38-TODAY()) | T38: =IF(L38="회신 완료","완료",IF(J38<TODAY(),"지연",IF(J38-TODAY()<=1,"임박(D-1 이내)",IF(J38-TODAY()<=3,"임박(D-3 이내)","여유"))))
A39: 57 | B39: 검사시험 | C39: 2-5 | D39: 검사구이력카드 | E39: 보완 필요 | F39: SH-FM-179 | G39: SH-FM-179 | H39: 김주태 | I39: 발송용_최종_20261008/메시지_김주태.txt | J39: 46331 | K39: 46303 | L39: 발송(회신 대기) | P39: 항목·기준 작성 파일 수령 → 같은 Rev.00 재개정(recheck → 승인·배포) → 매핑표 '보유'로 갱신 | Q39: 미완료 | S39: =IF(L39="회신 완료","",J39-TODAY()) | T39: =IF(L39="회신 완료","완료",IF(J39<TODAY(),"지연",IF(J39-TODAY()<=1,"임박(D-1 이내)",IF(J39-TODAY()<=3,"임박(D-3 이내)","여유"))))
A40: 58 | B40: 검사시험 | C40: 2-5 | D40: 검사구정기점검 계획대실적표 | E40: 보완 필요 | F40: SH-FM-180 | G40: SH-FM-180 | H40: 김주태 | I40: 발송용_최종_20261008/메시지_김주태.txt | J40: 46331 | K40: 46303 | L40: 발송(회신 대기) | P40: 항목·기준 작성 파일 수령 → 같은 Rev.00 재개정(recheck → 승인·배포) → 매핑표 '보유'로 갱신 | Q40: 미완료 | S40: =IF(L40="회신 완료","",J40-TODAY()) | T40: =IF(L40="회신 완료","완료",IF(J40<TODAY(),"지연",IF(J40-TODAY()<=1,"임박(D-1 이내)",IF(J40-TODAY()<=3,"임박(D-3 이내)","여유"))))
A41: 59 | B41: 검사시험 | C41: 2-5 | D41: 검사구점검체크시트 | E41: 보완 필요 | F41: SH-FM-181 | G41: SH-FM-181 | H41: 김주태 | I41: 발송용_최종_20261008/메시지_김주태.txt | J41: 46331 | K41: 46303 | L41: 발송(회신 대기) | P41: 항목·기준 작성 파일 수령 → 같은 Rev.00 재개정(recheck → 승인·배포) → 매핑표 '보유'로 갱신 | Q41: 미완료 | S41: =IF(L41="회신 완료","",J41-TODAY()) | T41: =IF(L41="회신 완료","완료",IF(J41<TODAY(),"지연",IF(J41-TODAY()<=1,"임박(D-1 이내)",IF(J41-TODAY()<=3,"임박(D-3 이내)","여유"))))
A42: 60 | B42: 검사시험 | C42: 2-5 | D42: 검사구보관 lay-out | E42: 보완 필요 | F42: SH-FM-182 | G42: SH-FM-182 | H42: 김주태 | I42: 발송용_최종_20261008/메시지_김주태.txt | J42: 46331 | K42: 46303 | L42: 발송(회신 대기) | P42: 항목·기준 작성 파일 수령 → 같은 Rev.00 재개정(recheck → 승인·배포) → 매핑표 '보유'로 갱신 | Q42: 미완료 | S42: =IF(L42="회신 완료","",J42-TODAY()) | T42: =IF(L42="회신 완료","완료",IF(J42<TODAY(),"지연",IF(J42-TODAY()<=1,"임박(D-1 이내)",IF(J42-TODAY()<=3,"임박(D-3 이내)","여유"))))
A43: 61 | B43: 검사시험 | C43: 2-5 | D43: 검사구 식별표 | E43: 보완 필요 | F43: SH-FM-183 | G43: SH-FM-183 | H43: 김주태 | I43: 발송용_최종_20261008/메시지_김주태.txt | J43: 46331 | K43: 46303 | L43: 발송(회신 대기) | P43: 항목·기준 작성 파일 수령 → 같은 Rev.00 재개정(recheck → 승인·배포) → 매핑표 '보유'로 갱신 | Q43: 미완료 | S43: =IF(L43="회신 완료","",J43-TODAY()) | T43: =IF(L43="회신 완료","완료",IF(J43<TODAY(),"지연",IF(J43-TODAY()<=1,"임박(D-1 이내)",IF(J43-TODAY()<=3,"임박(D-3 이내)","여유"))))
A44: 210 | B44: 품질경영체제 | C44: 6-8 | D44: 품질실적보고서 (전부서KPI목표대비실적) | E44: 보완 필요 | F44: SH-FM-332 | G44: SH-FM-332 | H44: 박철호 | I44: 발송용_담당자변경_20261027/메시지_박철호_20261027.txt | J44: 46331 | K44: 46322 | L44: 발송(회신 대기) | P44: 항목·기준 작성 파일 수령 → 같은 Rev.00 재개정(recheck → 승인·배포) → 매핑표 '보유'로 갱신 | Q44: 미완료 | R44: 담당자 변경 재안내 발송 2026-10-27 | S44: =IF(L44="회신 완료","",J44-TODAY()) | T44: =IF(L44="회신 완료","완료",IF(J44<TODAY(),"지연",IF(J44-TODAY()<=1,"임박(D-1 이내)",IF(J44-TODAY()<=3,"임박(D-3 이내)","여유"))))
A45: 211 | B45: 품질경영체제 | C45: 6-8 | D45: 고객/공정/외주불량 실적PPM | E45: 보완 필요 | F45: SH-FM-333 | G45: SH-FM-333 | H45: 박철호 | I45: 발송용_담당자변경_20261027/메시지_박철호_20261027.txt | J45: 46331 | K45: 46322 | L45: 발송(회신 대기) | P45: 항목·기준 작성 파일 수령 → 같은 Rev.00 재개정(recheck → 승인·배포) → 매핑표 '보유'로 갱신 | Q45: 미완료 | R45: 담당자 변경 재안내 발송 2026-10-27 | S45: =IF(L45="회신 완료","",J45-TODAY()) | T45: =IF(L45="회신 완료","완료",IF(J45<TODAY(),"지연",IF(J45-TODAY()<=1,"임박(D-1 이내)",IF(J45-TODAY()<=3,"임박(D-3 이내)","여유"))))
A46: 212 | B46: 품질경영체제 | C46: 6-8 | D46: 고객/공정/외주불량 개선대책서 | E46: 보완 필요 | F46: SH-FM-334 | G46: SH-FM-334 | H46: 박철호 | I46: 발송용_담당자변경_20261027/메시지_박철호_20261027.txt | J46: 46331 | K46: 46322 | L46: 발송(회신 대기) | P46: 항목·기준 작성 파일 수령 → 같은 Rev.00 재개정(recheck → 승인·배포) → 매핑표 '보유'로 갱신 | Q46: 미완료 | R46: 담당자 변경 재안내 발송 2026-10-27 | S46: =IF(L46="회신 완료","",J46-TODAY()) | T46: =IF(L46="회신 완료","완료",IF(J46<TODAY(),"지연",IF(J46-TODAY()<=1,"임박(D-1 이내)",IF(J46-TODAY()<=3,"임박(D-3 이내)","여유"))))
A47: 213 | B47: 품질경영체제 | C47: 6-8 | D47: 고객불량 유효성검증 MASTER LIST | E47: 보완 필요 | F47: SH-FM-335 | G47: SH-FM-335 | H47: 박철호 | I47: 발송용_담당자변경_20261027/메시지_박철호_20261027.txt | J47: 46331 | K47: 46322 | L47: 발송(회신 대기) | P47: 항목·기준 작성 파일 수령 → 같은 Rev.00 재개정(recheck → 승인·배포) → 매핑표 '보유'로 갱신 | Q47: 미완료 | R47: 담당자 변경 재안내 발송 2026-10-27 | S47: =IF(L47="회신 완료","",J47-TODAY()) | T47: =IF(L47="회신 완료","완료",IF(J47<TODAY(),"지연",IF(J47-TODAY()<=1,"임박(D-1 이내)",IF(J47-TODAY()<=3,"임박(D-3 이내)","여유"))))
A48: 214 | B48: 품질경영체제 | C48: 6-8 | D48: D+3개월 유효성검증 | E48: 보완 필요 | F48: SH-FM-336 | G48: SH-FM-336 | H48: 이광재 | I48: 발송용_담당자정정_20261028/메시지_이광재_20261028_정정.txt | J48: 46331 | L48: 미발송 | P48: 항목·기준 작성 파일 수령 → 같은 Rev.00 재개정(recheck → 승인·배포) → 매핑표 '보유'로 갱신 | Q48: 미완료 | R48: 담당자 정정본4 기준 이광재 확정(2026-10-28, 인쇄물 전달 당시: 박철호). 정정 메시지 발송 후 발송일·상태 갱신 | S48: =IF(L48="회신 완료","",J48-TODAY()) | T48: =IF(L48="회신 완료","완료",IF(J48<TODAY(),"지연",IF(J48-TODAY()<=1,"임박(D-1 이내)",IF(J48-TODAY()<=3,"임박(D-3 이내)","여유"))))
A49: 233 | B49: 품질경영체제 | C49: 6-12 | D49: 용접교육장설치 | E49: 판단 보류 | F49: SH-FM-355 | G49: SH-FM-355 | H49: 안종명 | I49: 발송용_최종_20261008/메시지_안종명.txt | J49: 46331 | K49: 46303 | L49: 발송(회신 대기) | P49: 현물 증빙(사진·위치) 확인 → 매핑표에 현물 보유 반영 검토 | Q49: 미완료 | S49: =IF(L49="회신 완료","",J49-TODAY()) | T49: =IF(L49="회신 완료","완료",IF(J49<TODAY(),"지연",IF(J49-TODAY()<=1,"임박(D-1 이내)",IF(J49-TODAY()<=3,"임박(D-3 이내)","여유"))))
A50: 234 | B50: 품질경영체제 | C50: 6-12 | D50: 자격인증내 실기평가보고서첨부 | E50: 보완 필요 | F50: SH-FM-356 | G50: SH-FM-356 | H50: 안종명 | I50: 발송용_최종_20261008/메시지_안종명.txt | J50: 46331 | K50: 46303 | L50: 발송(회신 대기) | P50: 항목·기준 작성 파일 수령 → 같은 Rev.00 재개정(recheck → 승인·배포) → 매핑표 '보유'로 갱신 | Q50: 미완료 | S50: =IF(L50="회신 완료","",J50-TODAY()) | T50: =IF(L50="회신 완료","완료",IF(J50<TODAY(),"지연",IF(J50-TODAY()<=1,"임박(D-1 이내)",IF(J50-TODAY()<=3,"임박(D-3 이내)","여유"))))
A51: 14 | B51: 생산조건관리 | C51: 1-3 | D51: 부적합처리기준 현지어번역본 | E51: 판단 보류 | F51: SH-FM-136 | G51: SH-FM-162 | H51: 이광재 | I51: 발송용_담당자변경_20261027/메시지_이광재_20261027.txt | J51: 46331 | K51: 46322 | L51: 발송(회신 대기) | P51: 통합 유지 확인 → 증빙 매핑표 갱신 / 분리 필요 시 통합 해제(FM Master·결정 CSV) | Q51: 미완료 | R51: 담당자 변경 재안내 발송 2026-10-27 | S51: =IF(L51="회신 완료","",J51-TODAY()) | T51: =IF(L51="회신 완료","완료",IF(J51<TODAY(),"지연",IF(J51-TODAY()<=1,"임박(D-1 이내)",IF(J51-TODAY()<=3,"임박(D-3 이내)","여유"))))
A52: 15 | B52: 생산조건관리 | C52: 1-3 | D52: 외관검사기준 현지어번역본 | E52: 판단 보류 | F52: SH-FM-137 | G52: SH-FM-168 | H52: 이광재 | I52: 발송용_담당자변경_20261027/메시지_이광재_20261027.txt | J52: 46331 | K52: 46322 | L52: 발송(회신 대기) | P52: 통합 유지 확인 → 증빙 매핑표 갱신 / 분리 필요 시 통합 해제(FM Master·결정 CSV) | Q52: 미완료 | R52: 담당자 변경 재안내 발송 2026-10-27 | S52: =IF(L52="회신 완료","",J52-TODAY()) | T52: =IF(L52="회신 완료","완료",IF(J52<TODAY(),"지연",IF(J52-TODAY()<=1,"임박(D-1 이내)",IF(J52-TODAY()<=3,"임박(D-3 이내)","여유"))))
A53: 41 | B53: 검사시험 | C53: 2-2 | D53: 외주품 검사협정서 | E53: 판단 보류 | F53: SH-FM-163 | G53: SH-FM-056 | H53: 이광재 | I53: 발송용_담당자변경_20261027/메시지_이광재_20261027.txt | J53: 46331 | K53: 46322 | L53: 발송(회신 대기) | P53: 원본 양식·승인 증빙 확보 → 대표 번호 릴리스 여부 결정 | Q53: 미완료 | R53: 담당자 변경 재안내 발송 2026-10-27 | S53: =IF(L53="회신 완료","",J53-TODAY()) | T53: =IF(L53="회신 완료","완료",IF(J53<TODAY(),"지연",IF(J53-TODAY()<=1,"임박(D-1 이내)",IF(J53-TODAY()<=3,"임박(D-3 이내)","여유"))))
A54: 185 | B54: 품질경영체제 | C54: 6-3 | D54: 정기검사실적 | E54: 판단 보류 | F54: SH-FM-307 | G54: SH-FM-034 | H54: 이광재 | I54: 발송용_담당자변경_20261027/메시지_이광재_20261027.txt | J54: 46331 | K54: 46322 | L54: 발송(회신 대기) | P54: 원본 양식·승인 증빙 확보 → 대표 번호 릴리스 여부 결정 | Q54: 미완료 | R54: 담당자 변경 재안내 발송 2026-10-27 | S54: =IF(L54="회신 완료","",J54-TODAY()) | T54: =IF(L54="회신 완료","완료",IF(J54<TODAY(),"지연",IF(J54-TODAY()<=1,"임박(D-1 이내)",IF(J54-TODAY()<=3,"임박(D-3 이내)","여유"))))
A55: 47 | B55: 검사시험 | C55: 2-4 | D55: 정기검사계획대실적(치수/용접) | E55: 보완 필요 | F55: SH-FM-169 | G55: SH-FM-169 | H55: 이광재 | I55: 발송용_담당자변경_20261027/메시지_이광재_20261027.txt | J55: 46331 | K55: 46322 | L55: 발송(회신 대기) | P55: 항목·기준 작성 파일 수령 → 같은 Rev.00 재개정(recheck → 승인·배포) → 매핑표 '보유'로 갱신 | Q55: 미완료 | R55: 담당자 변경 재안내 발송 2026-10-27 | S55: =IF(L55="회신 완료","",J55-TODAY()) | T55: =IF(L55="회신 완료","완료",IF(J55<TODAY(),"지연",IF(J55-TODAY()<=1,"임박(D-1 이내)",IF(J55-TODAY()<=3,"임박(D-3 이내)","여유"))))
A56: 48 | B56: 검사시험 | C56: 2-4 | D56: 정기검사성적서(치수/용접) | E56: 보완 필요 | F56: SH-FM-170 | G56: SH-FM-170 | H56: 이광재 | I56: 발송용_담당자변경_20261027/메시지_이광재_20261027.txt | J56: 46331 | K56: 46322 | L56: 발송(회신 대기) | P56: 항목·기준 작성 파일 수령 → 같은 Rev.00 재개정(recheck → 승인·배포) → 매핑표 '보유'로 갱신 | Q56: 미완료 | R56: 담당자 변경 재안내 발송 2026-10-27 | S56: =IF(L56="회신 완료","",J56-TODAY()) | T56: =IF(L56="회신 완료","완료",IF(J56<TODAY(),"지연",IF(J56-TODAY()<=1,"임박(D-1 이내)",IF(J56-TODAY()<=3,"임박(D-3 이내)","여유"))))
A57: 65 | B57: 검사시험 | C57: 2-7 | D57: 자주검사기준서 | E57: 보완 필요 | F57: SH-FM-187 | G57: SH-FM-187 | H57: 이광재 | I57: 발송용_담당자변경_20261027/메시지_이광재_20261027.txt | J57: 46331 | K57: 46322 | L57: 발송(회신 대기) | P57: 항목·기준 작성 파일 수령 → 같은 Rev.00 재개정(recheck → 승인·배포) → 매핑표 '보유'로 갱신 | Q57: 미완료 | R57: 담당자 변경 재안내 발송 2026-10-27 | S57: =IF(L57="회신 완료","",J57-TODAY()) | T57: =IF(L57="회신 완료","완료",IF(J57<TODAY(),"지연",IF(J57-TODAY()<=1,"임박(D-1 이내)",IF(J57-TODAY()<=3,"임박(D-3 이내)","여유"))))
A58: 66 | B58: 검사시험 | C58: 2-7 | D58: 자주검사체크시트 | E58: 보완 필요 | F58: SH-FM-188 | G58: SH-FM-188 | H58: 이광재 | I58: 발송용_담당자변경_20261027/메시지_이광재_20261027.txt | J58: 46331 | K58: 46322 | L58: 발송(회신 대기) | P58: 항목·기준 작성 파일 수령 → 같은 Rev.00 재개정(recheck → 승인·배포) → 매핑표 '보유'로 갱신 | Q58: 미완료 | R58: 담당자 변경 재안내 발송 2026-10-27 | S58: =IF(L58="회신 완료","",J58-TODAY()) | T58: =IF(L58="회신 완료","완료",IF(J58<TODAY(),"지연",IF(J58-TODAY()<=1,"임박(D-1 이내)",IF(J58-TODAY()<=3,"임박(D-3 이내)","여유"))))
A59: 67 | B59: 검사시험 | C59: 2-7 | D59: 용접spatter 관리기준 | E59: 보완 필요 | F59: SH-FM-189 | G59: SH-FM-189 | H59: 이광재 | I59: 발송용_담당자변경_20261027/메시지_이광재_20261027.txt | J59: 46331 | K59: 46322 | L59: 발송(회신 대기) | P59: 항목·기준 작성 파일 수령 → 같은 Rev.00 재개정(recheck → 승인·배포) → 매핑표 '보유'로 갱신 | Q59: 미완료 | R59: 담당자 변경 재안내 발송 2026-10-27 | S59: =IF(L59="회신 완료","",J59-TODAY()) | T59: =IF(L59="회신 완료","완료",IF(J59<TODAY(),"지연",IF(J59-TODAY()<=1,"임박(D-1 이내)",IF(J59-TODAY()<=3,"임박(D-3 이내)","여유"))))
A60: 69 | B60: 검사시험 | C60: 2-7 | D60: 자주검사체크시트 | E60: 보완 필요 | F60: SH-FM-191 | G60: SH-FM-188 | H60: 이광재 | I60: 발송용_담당자변경_20261027/메시지_이광재_20261027.txt | J60: 46331 | K60: 46322 | L60: 발송(회신 대기) | P60: 항목·기준 작성 파일 수령 → 같은 Rev.00 재개정(recheck → 승인·배포) → 매핑표 '보유'로 갱신 | Q60: 미완료 | R60: 담당자 변경 재안내 발송 2026-10-27 | S60: =IF(L60="회신 완료","",J60-TODAY()) | T60: =IF(L60="회신 완료","완료",IF(J60<TODAY(),"지연",IF(J60-TODAY()<=1,"임박(D-1 이내)",IF(J60-TODAY()<=3,"임박(D-3 이내)","여유"))))
...

Sheet 사용 안내
A1: 회신 현황 체크리스트 사용 안내 (2026-10-08)
A3: ■ 개요
A4: 대상: 판단 보류 29 + 미비 17 + 보완 필요 189 = 235건 + 보유 확인 5건 = 240행. 담당자 11명(이은주·박철호 공동 1건 포함).
A5: 발송용 메시지: 99_산출물/발송용_최종_20261008/ (담당자 1명당 1통, 지성규·이광재·이은주는 보유 확인 포함). 근거 자료는 99_산출물의 근거 정리 문서를 참고합니다.
A6: 회신 기한: 2026-11-05 (사용자 지정 2026-10-27, 기존 2026-10-15 에서 변경. 보유 확인에도 같은 날짜 적용). 담당자가 바뀐 6명의 재안내(발송용_담당자변경_20261027)는 발송 후 상세 시트의 발송일·상태를 갱신하세요.
A8: ■ 시트 구성
A9: 1. 담당자별 현황: 담당자 1명당 1행. 요청 건수(유형별), 회신 진행(미발송·발송·일부 회신·재요청·회신 완료·회신율·미회신·지연·조치 완료), 최근 발송일, 가장 이른 미회신 기한, 다음 조치, 판단 보류·미비·보유 확인의 SQ NO를 한 줄에 보여줍니다. 직접 입력하지 않고 '상세' 입력에 따라 자동 집계됩니다(보완 필요 SQ NO는 상세에서 확인).
A10: 2. 유형별 현황: 판단 보류·미비·보완 필요·보유 확인별 총 건수와 회신 진행 집계(자동).
A11: 3. 상세: 240행 건별 기록. 여기에만 입력합니다(아래 입력 순서 참고).
A12: 4. 사용 안내: 이 시트.
A14: ■ 입력 순서 (상세 시트)
A15: 1. 메시지를 보낸 뒤 '발송일'을 입력하고 '회신 상태'를 '발송(회신 대기)'로 바꿉니다. 담당자 열 필터로 해당 담당자 행을 한꺼번에 선택하면 편합니다.
... A48: 11/16~11/20은 ISO 14001 갱신심사(NQA) 주간이라 SQ 마일스톤을 두지 않았습니다. 확정된 날짜는 회신 11/05·SQ 심사 12/10(사용자 지정), 나머지는 담당자 협의 후 확정합니다.
