Workbook

Sheet 0_대시보드
A1: SQ mark 심사 준비 현황 대시보드 (경영보고용)
A2: 고객사: 한온시스템(Hanon Systems) | 기준: IATF16949/ISO9001 | 작성일: 2026-09-17(Rev.2, QP/WI 본문 대조 재판정 반영) | 데이터 갱신 안내: "전체_필요서류리스트"/부서별 탭의 "준비상태" 드롭다운을 갱신하면 이 표가 자동으로 다시 계산됩니다.
A4: 1. 전체 진행 현황
A5: 총 필요서류 | B5: 완료 | C5: 진행중 | D5: 미착수 | E5: 해당없음 | F5: 전체 완료율
A6: =COUNT(전체_필요서류리스트!$A$4:$A$1000) -> 240 | B6: =COUNTIF(전체_필요서류리스트!$O$4:$O$1000,"완료") -> 0 | C6: =COUNTIF(전체_필요서류리스트!$O$4:$O$1000,"진행중") -> 0 | D6: =COUNT(전체_필요서류리스트!$A$4:$A$1000)-B6-C6-E6 -> 240 | E6: =COUNTIF(전체_필요서류리스트!$O$4:$O$1000,"해당없음") -> 0 | F6: =B6/A6 -> 0
A8: 2. 우선순위별 진행 현황
A9: 우선순위 | B9: 총 건수 | C9: 완료 | D9: 진행중 | E9: 미착수 | F9: 완료율
A10: 높음 (A) | B10: =COUNTIF(전체_필요서류리스트!$E$4:$E$1000,"높음") -> 36 | C10: =COUNTIFS(전체_필요서류리스트!$E$4:$E$1000,"높음",전체_필요서류리스트!$O$4:$O$1000,"완료") -> 0 | D10: =COUNTIFS(전체_필요서류리스트!$E$4:$E$1000,"높음",전체_필요서류리스트!$O$4:$O$1000,"진행중") -> 0 | E10: =B10-C10-D10 -> 36 | F10: =IF(B10=0,0,C10/B10) -> 0
A11: 보통 (B) | B11: =COUNTIF(전체_필요서류리스트!$E$4:$E$1000,"보통") -> 162 | C11: =COUNTIFS(전체_필요서류리스트!$E$4:$E$1000,"보통",전체_필요서류리스트!$O$4:$O$1000,"완료") -> 0 | D11: =COUNTIFS(전체_필요서류리스트!$E$4:$E$1000,"보통",전체_필요서류리스트!$O$4:$O$1000,"진행중") -> 0 | E11: =B11-C11-D11 -> 162 | F11: =IF(B11=0,0,C11/B11) -> 0
A12: 낮음 (C) | B12: =COUNTIF(전체_필요서류리스트!$E$4:$E$1000,"낮음") -> 42 | C12: =COUNTIFS(전체_필요서류리스트!$E$4:$E$1000,"낮음",전체_필요서류리스트!$O$4:$O$1000,"완료") -> 0 | D12: =COUNTIFS(전체_필요서류리스트!$E$4:$E$1000,"낮음",전체_필요서류리스트!$O$4:$O$1000,"진행중") -> 0 | E12: =B12-C12-D12 -> 42 | F12: =IF(B12=0,0,C12/B12) -> 0
A14: 3. 담당부서별 진행 현황
A15: 담당부서 | B15: 총 건수 | C15: 완료 | D15: 진행중 | E15: 미착수 | F15: 완료율
A16: 생산팀 | B16: =COUNTIF(전체_필요서류리스트!$J$4:$J$1000,"생산팀") -> 91 | C16: =COUNTIFS(전체_필요서류리스트!$J$4:$J$1000,"생산팀",전체_필요서류리스트!$O$4:$O$1000,"완료") -> 0 | D16: =COUNTIFS(전체_필요서류리스트!$J$4:$J$1000,"생산팀",전체_필요서류리스트!$O$4:$O$1000,"진행중") -> 0 | E16: =B16-C16-D16 -> 91 | F16: =IF(B16=0,0,C16/B16) -> 0
A17: 품질팀 | B17: =COUNTIF(전체_필요서류리스트!$J$4:$J$1000,"품질팀") -> 88 | C17: =COUNTIFS(전체_필요서류리스트!$J$4:$J$1000,"품질팀",전체_필요서류리스트!$O$4:$O$1000,"완료") -> 0 | D17: =COUNTIFS(전체_필요서류리스트!$J$4:$J$1000,"품질팀",전체_필요서류리스트!$O$4:$O$1000,"진행중") -> 0 | E17: =B17-C17-D17 -> 88 | F17: =IF(B17=0,0,C17/B17) -> 0
A18: 구매자재팀 | B18: =COUNTIF(전체_필요서류리스트!$J$4:$J$1000,"구매자재팀") -> 32 | C18: =COUNTIFS(전체_필요서류리스트!$J$4:$J$1000,"구매자재팀",전체_필요서류리스트!$O$4:$O$1000,"완료") -> 0 | D18: =COUNTIFS(전체_필요서류리스트!$J$4:$J$1000,"구매자재팀",전체_필요서류리스트!$O$4:$O$1000,"진행중") -> 0 | E18: =B18-C18-D18 -> 32 | F18: =IF(B18=0,0,C18/B18) -> 0
A19: 생산기술 | B19: =COUNTIF(전체_필요서류리스트!$J$4:$J$1000,"생산기술") -> 19 | C19: =COUNTIFS(전체_필요서류리스트!$J$4:$J$1000,"생산기술",전체_필요서류리스트!$O$4:$O$1000,"완료") -> 0 | D19: =COUNTIFS(전체_필요서류리스트!$J$4:$J$1000,"생산기술",전체_필요서류리스트!$O$4:$O$1000,"진행중") -> 0 | E19: =B19-C19-D19 -> 19 | F19: =IF(B19=0,0,C19/B19) -> 0
A20: 개발팀 | B20: =COUNTIF(전체_필요서류리스트!$J$4:$J$1000,"개발팀") -> 2 | C20: =COUNTIFS(전체_필요서류리스트!$J$4:$J$1000,"개발팀",전체_필요서류리스트!$O$4:$O$1000,"완료") -> 0 | D20: =COUNTIFS(전체_필요서류리스트!$J$4:$J$1000,"개발팀",전체_필요서류리스트!$O$4:$O$1000,"진행중") -> 0 | E20: =B20-C20-D20 -> 2 | F20: =IF(B20=0,0,C20/B20) -> 0
A21: (부서 미정) | B21: =COUNTIF(전체_필요서류리스트!$J$4:$J$1000,"(부서 미정)") -> 8 | C21: =COUNTIFS(전체_필요서류리스트!$J$4:$J$1000,"(부서 미정)",전체_필요서류리스트!$O$4:$O$1000,"완료") -> 0 | D21: =COUNTIFS(전체_필요서류리스트!$J$4:$J$1000,"(부서 미정)",전체_필요서류리스트!$O$4:$O$1000,"진행중") -> 0 | E21: =B21-C21-D21 -> 8 | F21: =IF(B21=0,0,C21/B21) -> 0
A23: 4. 월별 목표완료 일정 및 진행 현황
A24: 목표월 | B24: 배정 건수 | C24: 완료 | D24: 진행중 | E24: 미착수 | F24: 완료율
A25: 2026-09 | B25: =COUNTIF(전체_필요서류리스트!$N$4:$N$1000,"2026-09") -> 48 | C25: =COUNTIFS(전체_필요서류리스트!$N$4:$N$1000,"2026-09",전체_필요서류리스트!$O$4:$O$1000,"완료") -> 0 | D25: =COUNTIFS(전체_필요서류리스트!$N$4:$N$1000,"2026-09",전체_필요서류리스트!$O$4:$O$1000,"진행중") -> 0 | E25: =B25-C25-D25 -> 48 | F25: =IF(B25=0,0,C25/B25) -> 0
A26: 2026-10 | B26: =COUNTIF(전체_필요서류리스트!$N$4:$N$1000,"2026-10") -> 64 | C26: =COUNTIFS(전체_필요서류리스트!$N$4:$N$1000,"2026-10",전체_필요서류리스트!$O$4:$O$1000,"완료") -> 0 | D26: =COUNTIFS(전체_필요서류리스트!$N$4:$N$1000,"2026-10",전체_필요서류리스트!$O$4:$O$1000,"진행중") -> 0 | E26: =B26-C26-D26 -> 64 | F26: =IF(B26=0,0,C26/B26) -> 0
A27: 2026-11 | B27: =COUNTIF(전체_필요서류리스트!$N$4:$N$1000,"2026-11") -> 64 | C27: =COUNTIFS(전체_필요서류리스트!$N$4:$N$1000,"2026-11",전체_필요서류리스트!$O$4:$O$1000,"완료") -> 0 | D27: =COUNTIFS(전체_필요서류리스트!$N$4:$N$1000,"2026-11",전체_필요서류리스트!$O$4:$O$1000,"진행중") -> 0 | E27: =B27-C27-D27 -> 64 | F27: =IF(B27=0,0,C27/B27) -> 0
A28: 2026-12 | B28: =COUNTIF(전체_필요서류리스트!$N$4:$N$1000,"2026-12") -> 64 | C28: =COUNTIFS(전체_필요서류리스트!$N$4:$N$1000,"2026-12",전체_필요서류리스트!$O$4:$O$1000,"완료") -> 0 | D28: =COUNTIFS(전체_필요서류리스트!$N$4:$N$1000,"2026-12",전체_필요서류리스트!$O$4:$O$1000,"진행중") -> 0 | E28: =B28-C28-D28 -> 64 | F28: =IF(B28=0,0,C28/B28) -> 0
G48: 준비상태 | H48: 건수
G49: 완료 | H49: =B6 -> 0
G50: 진행중 | H50: =C6 -> 0
G51: 미착수 | H51: =D6 -> 240
G52: 해당없음 | H52: =E6 -> 0
A54: ※ 본 대시보드는 "전체_필요서류리스트" 시트의 데이터를 실시간으로 집계합니다. 각 부서 탭(D_생산팀 등)에서 "준비상태"를 미착수→진행중→완료로 갱신하면 파일을 열 때 자동으로 반영됩니다.

Sheet 요약
A1: SQ mark 심사 추진 계획 - 필요서류 정리 요약(종합)
A2: 고객사: 한온시스템(Hanon Systems) | 기준: IATF16949/ISO9001 | 작성일: 2026-09-17(Rev.2, QP/WI 본문 대조 재판정 반영) | 원본: SQ_진척율 보고 자료 한온시스템 260907.xlsx
A3: DISCLAIMER: "작성구분"/"관련 기존 문서"는 QMS_REV00 품질경영시스템 통합문서(SH-QP-001~025, SH-WI-001~030) 실제 본문과 대조한 재판정 결과입니다(2026-09-17, Rev.2). 녹색=본문상 근거 확인된 기존 연계, 노란색="기존 절차 연계 (제안 — 검토 필요)"로 표시된 항목(본문 근거가 약하거나 새로 발견된 연계 후보 — 관련 기존 문서 칸의 [재검토]/[신규 발견]/[참고] 문구 확인), 빨간색=신규 작성 필요. "FM문서번호(안)"/"목표완료월"은 규칙 기반 1차 추정치입니다. 실제 활용 가능 여부, 양식 신규 제정 여부, 일정은 반드시 담당부서·품질책임자 검토 후 확정하세요.
A5: 구분별 필요서류 현황
A6: NO | B6: 구분 | C6: 필요서류 건수 | D6: 기존 절차 연계(건) | E6: 기존 절차 연계-제안/검토필요(건) | F6: 신규 작성 필요(건) | G6: 준비상태-완료(건) | H6: 준비상태-미완료(건)
A7: 1 | B7: 1. 생산조건관리 | C7: =COUNT('C1_생산조건관리'!$A$4:$A$1000) -> 29 | D7: =COUNTIF('C1_생산조건관리'!$J$4:$J$1000,"기존 절차 연계") -> 13 | E7: =COUNTIF('C1_생산조건관리'!$J$4:$J$1000,"기존 절차 연계 (제안 — 검토 필요)") -> 9 | F7: =COUNTIF('C1_생산조건관리'!$J$4:$J$1000,"신규 작성 필요") -> 7 | G7: =COUNTIF('C1_생산조건관리'!$M$4:$M$1000,"완료") -> 0 | H7: =COUNT('C1_생산조건관리'!$A$4:$A$1000)-G7 -> 29
A8: 2 | B8: 2. 검사시험 | C8: =COUNT('C2_검사시험'!$A$4:$A$1000) -> 55 | D8: =COUNTIF('C2_검사시험'!$J$4:$J$1000,"기존 절차 연계") -> 29 | E8: =COUNTIF('C2_검사시험'!$J$4:$J$1000,"기존 절차 연계 (제안 — 검토 필요)") -> 7 | F8: =COUNTIF('C2_검사시험'!$J$4:$J$1000,"신규 작성 필요") -> 19 | G8: =COUNTIF('C2_검사시험'!$M$4:$M$1000,"완료") -> 0 | H8: =COUNT('C2_검사시험'!$A$4:$A$1000)-G8 -> 55
A9: 3 | B9: 3. 설비관리 | C9: =COUNT('C3_설비관리'!$A$4:$A$1000) -> 28 | D9: =COUNTIF('C3_설비관리'!$J$4:$J$1000,"기존 절차 연계") -> 4 | E9: =COUNTIF('C3_설비관리'!$J$4:$J$1000,"기존 절차 연계 (제안 — 검토 필요)") -> 3 | F9: =COUNTIF('C3_설비관리'!$J$4:$J$1000,"신규 작성 필요") -> 21 | G9: =COUNTIF('C3_설비관리'!$M$4:$M$1000,"완료") -> 0 | H9: =COUNT('C3_설비관리'!$A$4:$A$1000)-G9 -> 28
A10: 4 | B10: 4. 금형관리 | C10: =COUNT('C4_금형관리'!$A$4:$A$1000) -> 19 | D10: =COUNTIF('C4_금형관리'!$J$4:$J$1000,"기존 절차 연계") -> 14 | E10: =COUNTIF('C4_금형관리'!$J$4:$J$1000,"기존 절차 연계 (제안 — 검토 필요)") -> 5 | F10: =COUNTIF('C4_금형관리'!$J$4:$J$1000,"신규 작성 필요") -> 0 | G10: =COUNTIF('C4_금형관리'!$M$4:$M$1000,"완료") -> 0 | H10: =COUNT('C4_금형관리'!$A$4:$A$1000)-G10 -> 19
A11: 5 | B11: 5. 자재관리 | C11: =COUNT('C5_자재관리'!$A$4:$A$1000) -> 33 | D11: =COUNTIF('C5_자재관리'!$J$4:$J$1000,"기존 절차 연계") -> 15 | E11: =COUNTIF('C5_자재관리'!$J$4:$J$1000,"기존 절차 연계 (제안 — 검토 필요)") -> 3 | F11: =COUNTIF('C5_자재관리'!$J$4:$J$1000,"신규 작성 필요") -> 15 | G11: =COUNTIF('C5_자재관리'!$M$4:$M$1000,"완료") -> 0 | H11: =COUNT('C5_자재관리'!$A$4:$A$1000)-G11 -> 33
A12: 6 | B12: 6. 품질경영체제 | C12: =COUNT('C6_품질경영체제'!$A$4:$A$1000) -> 76 | D12: =COUNTIF('C6_품질경영체제'!$J$4:$J$1000,"기존 절차 연계") -> 20 | E12: =COUNTIF('C6_품질경영체제'!$J$4:$J$1000,"기존 절차 연계 (제안 — 검토 필요)") -> 14 | F12: =COUNTIF('C6_품질경영체제'!$J$4:$J$1000,"신규 작성 필요") -> 42 | G12: =COUNTIF('C6_품질경영체제'!$M$4:$M$1000,"완료") -> 0 | H12: =COUNT('C6_품질경영체제'!$A$4:$A$1000)-G12 -> 76
B13: 합계 | C13: =SUM(C7:C12) -> 240 | D13: =SUM(D7:D12) -> 95 | E13: =SUM(E7:E12) -> 41 | F13: =SUM(F7:F12) -> 104 | G13: =SUM(G7:G12) -> 0 | H13: =SUM(H7:H12) -> 240
A15: 담당부서별 필요서류 건수 및 우선순위 분포
A16: 담당부서 | B16: 필요서류 건수 | C16: 우선순위 높음(A) | D16: 우선순위 보통(B) | E16: 우선순위 낮음(C)
A17: 생산팀 | B17: =COUNT(D_생산팀!$A$4:$A$1000) -> 91 | C17: =COUNTIF(D_생산팀!$D$4:$D$1000,"높음") -> 8 | D17: =COUNTIF(D_생산팀!$D$4:$D$1000,"보통") -> 58 | E17: =COUNTIF(D_생산팀!$D$4:$D$1000,"낮음") -> 25
A18: 품질팀 | B18: =COUNT(D_품질팀!$A$4:$A$1000) -> 88 | C18: =COUNTIF(D_품질팀!$D$4:$D$1000,"높음") -> 13 | D18: =COUNTIF(D_품질팀!$D$4:$D$1000,"보통") -> 61 | E18: =COUNTIF(D_품질팀!$D$4:$D$1000,"낮음") -> 14
A19: 구매자재팀 | B19: =COUNT(D_구매자재팀!$A$4:$A$1000) -> 32 | C19: =COUNTIF(D_구매자재팀!$D$4:$D$1000,"높음") -> 8 | D19: =COUNTIF(D_구매자재팀!$D$4:$D$1000,"보통") -> 24 | E19: =COUNTIF(D_구매자재팀!$D$4:$D$1000,"낮음") -> 0
A20: 생산기술 | B20: =COUNT(D_생산기술!$A$4:$A$1000) -> 19 | C20: =COUNTIF(D_생산기술!$D$4:$D$1000,"높음") -> 4 | D20: =COUNTIF(D_생산기술!$D$4:$D$1000,"보통") -> 15 | E20: =COUNTIF(D_생산기술!$D$4:$D$1000,"낮음") -> 0
A21: 개발팀 | B21: =COUNT(D_개발팀!$A$4:$A$1000) -> 2 | C21: =COUNTIF(D_개발팀!$D$4:$D$1000,"높음") -> 0 | D21: =COUNTIF(D_개발팀!$D$4:$D$1000,"보통") -> 0 | E21: =COUNTIF(D_개발팀!$D$4:$D$1000,"낮음") -> 2
A22: (부서 미정) | B22: =COUNT('D_부서 미정'!$A$4:$A$1000) -> 8 | C22: =COUNTIF('D_부서 미정'!$D$4:$D$1000,"높음") -> 3 | D22: =COUNTIF('D_부서 미정'!$D$4:$D$1000,"보통") -> 4 | E22: =COUNTIF('D_부서 미정'!$D$4:$D$1000,"낮음") -> 1
A24: 월별 목표완료 배정 건수 (전체_필요서류리스트 기준)
A25: 목표월 | B25: 배정 건수
A26: 2026-09 | B26: =COUNTIF(전체_필요서류리스트!$N$4:$N$1000,A26) -> 48
A27: 2026-10 | B27: =COUNTIF(전체_필요서류리스트!$N$4:$N$1000,A27) -> 64
A28: 2026-11 | B28: =COUNTIF(전체_필요서류리스트!$N$4:$N$1000,A28) -> 64
A29: 2026-12 | B29: =COUNTIF(전체_필요서류리스트!$N$4:$N$1000,A29) -> 64

Sheet 전체_필요서류리스트
A1: SQ mark 심사 - 필요서류 전체 리스트 (구분별 통합, 우선순위/FM번호/일정 포함)
A2: 작성일: 2026-09-17(Rev.2) | 총 240건 | 준비상태는 드롭다운으로 선택
A3: DISCLAIMER: "작성구분"/"관련 기존 문서"는 QMS_REV00 품질경영시스템 통합문서(SH-QP-001~025, SH-WI-001~030) 실제 본문과 대조한 재판정 결과입니다(2026-09-17, Rev.2). 녹색=기존 절차 연계(확정), 빨간색=신규 작성 필요. ※2026-09-22: 재판정(본문대조) 결과 검토가 필요했던 41건(과거 노란색 표시)은 품질경영담당(박철호)이 담당부서 정식 회신 없이 일괄 검토·확정했습니다 — 대안 후보/신규 발견 연계를 채택해 "기존 절차 연계"로 전환(녹색), "관련 기존 문서"·"비고" 칸에 확정 근거(ratio)와 확정 일자를 기재했습니다. 이 중 4건(외관검사기준 현지어번역본, 완성품보관장소선정, 금형관리대장, 3정5행관리 기준서)은 "비고" 칸에 ⚠ 표시 — 유사도는 높으나 문서 성격이 다를 가능성이 있어 현장 실제 서식과의 대조 확인이 별도로 필요합니다. "FM문서번호"는 이번 확정으로 240건 전체가 확정 상태입니다. 다만 41건은 애초 번호가 옛 추정/신규작성 기준으로 채번되어 있어 확정된 연계절차와 번호가 어긋나 있던 것을 2026-09-22 발견, 확정된 연계절차 코드 기준("SH-FM-<연계절차코드>-<순번>")으로 재채번했습니다(해당 행 "비고"에 구번호→신번호 기록). 이 재채번은 카테고리별(C1~C6)·부서별(D_생산팀 등) 탭, "FM양식번호_초안" 시트, 공식 문서관리대장에도 동일하게 반영했습니다. "목표완료월"은 규칙 기반 1차 추정치입니다. 실제 활용 가능 여부, 양식 신규 제정 여부, 일정은 반드시 담당부서·품질책임자 검토 후 확정하세요. "배점"은 문서 단위가 아니라 "번호"(요구사항) 단위 배점입니다 — 한 요구사항에 필요서류가 여러 건이면 첫 행에만 배점을 표기하고 나머지 행은 공란입니다(전체 42개 요구사항 배점 합계 1,000점; 행별로 단순 합산하지 마세요). ※2026-09-30: 통합문서(QM-001 계열)에 회사 내부에서 "SH-" 접두사를 부여해 편집한 개정본(시행일 2026-09-23)이 확인되어, 앞으로 전 문서번호 체계를 "SH-" 접두사로 통일하기로 확정했습니다(SH-QM-001, SH-QP-001~025, SH-WI-001~030, SH-FM-XXX). 본 파일의 FM문서번호·관련 기존 문서 표기도 전부 SH- 접두사 기준으로 갱신했습니다.
A4: NO | B4: 구분 | C4: 번호 | D4: 배점(요구사항당) | E4: 우선순위 | F4: 요구사항(세부 추진 항목) | G4: 필요서류(준비서류) | H4: FM문서번호 | I4: 현장 연계 | J4: 담당부서 | K4: 담당자 | L4: 작성구분(자동추정) | M4: 관련 기존 문서(참고) | N4: 목표완료월(제안) | O4: 준비상태 | P4: 비고 | Q4: 확인결과 | R4: 확정 연계문서/FM번호 | S4: 확인자 | T4: 확인일자
A5: 1 | B5: 1. 생산조건관리 | C5: 1-1 | D5: 20 | E5: 보통 | F5: 표준류(관리계획서, 작업표준서, 설비일상점검표 등)와 실제공정 일치성 확인[관리 분담 등] | G5: P-FMEA | H5: SH-FM-QP010-01 | J5: 품질팀 | K5: 이광재 | L5: 기존 절차 연계 | M5: SH-QP-010(APQP 및 PPAP 관리 절차서); SH-WI-004(설비 일상점검 및 이상대응 표준) [참고: 본문상 명확한 근거 약함(ratio=0.28), 담당부서 확인 권장] | N5: 2026-11 | P5: ※재판정(본문대조): 본문상 명확한 근거 약함 — 담당부서 확인 권장(기존 분류 유지)
A6: 2 | B6: 1. 생산조건관리 | C6: 1-1 | E6: 보통 | F6: 고객과 협의된 검사협정서/검사기준서 기준과 실제 업무절차 일치성 | G6: 관리계획서 | H6: SH-FM-WI022-01 | J6: 품질팀 | K6: 이광재 | L6: 기존 절차 연계 | M6: SH-WI-022(변경 초기유동 및 강화검사 작업표준) [확정 2026-09-22: 기존 추정 SH-QP-010(ratio=0.34) 대비 대안 채택(ratio=0.69) — 품질경영담당 일괄판단, 부서 정식회신 생략] | N6: 2026-11 | P6: ※재판정(본문대조) 확정(2026-09-22, 품질경영담당 일괄판단 — 부서 정식회신 없이 처리): 관련 기존 문서란 참고 | FM번호 재부여(2026-09-22, 확정 연계절차 기준): SH-FM-QP010-02 → SH-FM-WI022-01 | Q6: 대안 채택 | R6: SH-WI-022(변경 초기유동 및 강화검사 작업표준) | S6: 박철호(품질경영 담당, 일괄확정) | T6: 2026-09-22
A7: 3 | B7: 1. 생산조건관리 | C7: 1-1 | E7: 보통 | F7: 공정 FMEA작성 및 주요 품질 문서 내용과 연계상태 확인 | G7: 작업표준서 | H7: SH-FM-QP010-03 | I7: 관리본 배포 | J7: 생산팀 | K7: 지성규 | L7: 기존 절차 연계 | M7: SH-QP-010(APQP 및 PPAP 관리 절차서) [참고: 본문상 명확한 근거 약함(ratio=0.11), 담당부서 확인 권장] | N7: 2026-12 | P7: ※재판정(본문대조): 본문상 명확한 근거 약함 — 담당부서 확인 권장(기존 분류 유지)
A8: 4 | B8: 1. 생산조건관리 | C8: 1-1 | E8: 보통 | F8: 주요 표준류(작업표준서 등) 현장내 게시 상태 | G8: 설비일상점검표 | H8: SH-FM-WI004-01 | I8: 관리본 배포 | J8: 생산팀 | K8: 지성규 | L8: 기존 절차 연계 | M8: SH-WI-004(설비 일상점검 및 이상대응 표준) [본문 확인 ratio=0.73] | N8: 2026-12
A9: 5 | B9: 1. 생산조건관리 | C9: 1-1 | E9: 보통 | F9: 관리계획서 및 현장내 표준류 중요공정/안전 보안공정 식별표시관리 | G9: 고객승인 검사협정 / ISIR 서류 | H9: SH-FM-QP010-04 | J9: 품질팀 | K9: 이광재 | L9: 기존 절차 연계 | M9: SH-QP-010(APQP 및 PPAP 관리 절차서); SH-QP-025(고객별 요구사항(CSR) 관리 절차서) [참고: 본문상 명확한 근거 약함(ratio=0.23), 담당부서 확인 권장] | N9: 2026-11 | P9: ※재판정(본문대조): 본문상 명확한 근거 약함 — 담당부서 확인 권장(기존 분류 유지)
A10: 6 | B10: 1. 생산조건관리 | C10: 1-2 | D10: 20 | E10: 보통 | F10: 설비 가동중단 발생시 설비점검 절차 수립 및 준수상태 | G10: 설비재가동업무 프로세스 | H10: SH-FM-QP025-01 | I10: 관리본 배포 | J10: 생산팀 | K10: 지성규 | L10: 기존 절차 연계 | M10: SH-QP-025(고객별 요구사항(CSR) 관리 절차서) [확정 2026-09-22: 기존 추정 SH-WI-016(ratio=0.20) 대비 대안 채택(ratio=0.56) — 품질경영담당 일괄판단, 부서 정식회신 생략] | N10: 2026-12 | P10: ※재판정(본문대조) 확정(2026-09-22, 품질경영담당 일괄판단 — 부서 정식회신 없이 처리): 관련 기존 문서란 참고 | FM번호 재부여(2026-09-22, 확정 연계절차 기준): SH-FM-WI016-01 → SH-FM-QP025-01 | Q10: 대안 채택 | R10: SH-QP-025(고객별 요구사항(CSR) 관리 절차서) | S10: 박철호(품질경영 담당, 일괄확정) | T10: 2026-09-22
A11: 7 | B11: 1. 생산조건관리 | C11: 1-2 | E11: 보통 | F11: ※ 계획 : 가동중단 시간별/사유별 점검절차 수립 및 이행 | G11: (계획/비계획정지 기준 명확화) | H11: SH-FM-WI020-01 | J11: (부서 미정) | L11: 기존 절차 연계 | M11: SH-WI-020(비상상황 생산복구 표준); SH-WI-025(품질이상 정지·보고·재가동 표준) [참고: 본문상 명확한 근거 약함(ratio=0.28), 담당부서 확인 권장] | N11: 2026-12 | P11: ※재판정(본문대조): 본문상 명확한 근거 약함 — 담당부서 확인 권장(기존 분류 유지)
A12: 8 | B12: 1. 생산조건관리 | C12: 1-2 | E12: 보통 | F12: 비계획 : 이상발생 가동중단 발생시 설비 점검 지침, 생산중인 제품에 대한 품질보증 업무절차 수립 및 이행 | G12: 설비가동중단 LIST (설비이력카드 연계) | H12: SH-FM-WI016-02 | I12: 관리본 배포 | J12: 생산팀 | L12: 기존 절차 연계 | M12: SH-WI-016(예방보전 및 설비점검 표준); SH-WI-020(비상상황 생산복구 표준) [참고: 본문상 명확한 근거 약함(ratio=0.09), 담당부서 확인 권장] | N12: 2026-12 | P12: ※재판정(본문대조): 본문상 명확한 근거 약함 — 담당부서 확인 권장(기존 분류 유지)
A13: 9 | B13: 1. 생산조건관리 | C13: 1-2 | E13: 보통 | F13: 재가동후 초도생산품에 대한 중요품질특성부 품질검증 결과 기록관리여부 | G13: 재가동 초품 검사 체크시트 | H13: SH-FM-WI020-02 | I13: 관리본 배포 | J13: 품질팀 | K13: 이광재 | L13: 기존 절차 연계 | M13: SH-WI-020(비상상황 생산복구 작업표준) [확정 2026-09-22: 기존 추정 SH-QP-003(ratio=0.05) 대비 대안 채택(ratio=0.79) — 품질경영담당 일괄판단, 부서 정식회신 생략] | N13: 2026-11 | P13: ※재판정(본문대조) 확정(2026-09-22, 품질경영담당 일괄판단 — 부서 정식회신 없이 처리): 관련 기존 문서란 참고 | FM번호 재부여(2026-09-22, 확정 연계절차 기준): SH-FM-QP003-01 → SH-FM-WI020-02 | Q13: 대안 채택 | R13: SH-WI-020(비상상황 생산복구 작업표준) | S13: 박철호(품질경영 담당, 일괄확정) | T13: 2026-09-22
A14: 10 | B14: 1. 생산조건관리 | C14: 1-2 | E14: 보통 | F14: 비계획 가동중단 발생시 전/후 생산제품에 대한 LOT 구분 관리방안 수립 및 식별관리 실시 | G14: 재가동 초도생산품 LOT식별관리 기준서 | H14: SH-FM-QP018-01 | J14: 생산팀 | K14: 지성규 | L14: 기존 절차 연계 | M14: SH-QP-018(식별 및 추적성 관리 절차서); SH-WI-005(제품 식별·LOT 추적 및 출하 표준) [참고: 본문상 명확한 근거 약함(ratio=0.14), 담당부서 확인 권장] | N14: 2026-12 | P14: ※재판정(본문대조): 본문상 명확한 근거 약함 — 담당부서 확인 권장(기존 분류 유지)
A15: 11 | B15: 1. 생산조건관리 | C15: 1-3 | D15: 10 | E15: 낮음 | F15: 작업표준서, 설비일상점검 기준표, 작업일보 등 외국인 배치공정 표준류 현지어 번역 게시상태 | G15: 작업표준서 현지어번역본 | H15: SH-FM-WI004-02 | I15: 관리본 배포 | J15: 생산팀 | K15: 지성규 | L15: 기존 절차 연계 | M15: SH-WI-004(설비 일상점검 및 이상대응 표준) [본문 확인 ratio=0.43] | N15: 2026-12
A16: 12 | B16: 1. 생산조건관리 | C16: 1-3 | E16: 낮음 | F16: : 부적합 처리절차 및 중요 품질문제 개선 사례등 품질의식 강화목적 표준류 번역 게시 (추가 관리시 우수) | G16: 설비일상점검표 현지어 번역본 | H16: SH-FM-WI004-03 | I16: 관리본 배포 | J16: 생산팀 | L16: 기존 절차 연계 | M16: SH-WI-004(설비 일상점검 및 이상대응 표준) [본문 확인 ratio=0.64] | N16: 2026-12
A17: 13 | B17: 1. 생산조건관리 | C17: 1-3 | E17: 낮음 | F17: ※ 해당공정 외국인작업자 주요 표준류 교육 및 내용 숙지 시 현지어 번역게시 불필요(현장확인 필요) | G17: 작업일보 현지어 번역본 | H17: SH-FM-PRD-N01 | I17: 관리본 배포 | J17: 생산팀 | L17: 신규 작성 필요 | N17: 2026-10
A18: 14 | B18: 1. 생산조건관리 | C18: 1-3 | E18: 낮음 | G18: 부적합처리기준 현지어번역본 | H18: SH-FM-QP014-01 | I18: 관리본 배포 | J18: 품질팀 | K18: 이광재 | L18: 기존 절차 연계 | M18: SH-QP-014(부적합품 및 재작업 관리 절차서) [확정 2026-09-22: 신규 발견 연계 채택(ratio=0.72) — 품질경영담당 일괄판단, 부서 정식회신 생략] | N18: 2026-10 | P18: ※재판정(본문대조) 확정(2026-09-22, 품질경영담당 일괄판단 — 부서 정식회신 없이 처리): 관련 기존 문서란 참고 | FM번호 재부여(2026-09-22, 확정 연계절차 기준): SH-FM-PRD-N02 → SH-FM-QP014-01 | Q18: 대안 채택 | R18: SH-QP-014(부적합품 및 재작업 관리 절차서) | S18: 박철호(품질경영 담당, 일괄확정) | T18: 2026-09-22
A19: 15 | B19: 1. 생산조건관리 | C19: 1-3 | E19: 낮음 | G19: 외관검사기준 현지어번역본 | H19: SH-FM-WI030-01 | I19: 관리본 배포 | J19: 품질팀 | L19: 기존 절차 연계 | M19: SH-WI-030(고객감사·인증심사 현장대응 표준) [확정 2026-09-22: 신규 발견 연계 채택(ratio=1.00) — 품질경영담당 일괄판단, 부서 정식회신 생략] | N19: 2026-10 | P19: ※재판정(본문대조) 확정(2026-09-22, 품질경영담당 일괄판단 — 부서 정식회신 없이 처리): 관련 기존 문서란 참고 ⚠현장 실제 서식과 반드시 대조 확인 필요(철호님 직접 확인 권장) | FM번호 재부여(2026-09-22, 확정 연계절차 기준): SH-FM-PRD-N03 → SH-FM-WI030-01 | Q19: 대안 채택 | R19: SH-WI-030(고객감사·인증심사 현장대응 표준) | S19: 박철호(품질경영 담당, 일괄확정) | T19: 2026-09-22
A20: 16 | B20: 1. 생산조건관리 | C20: 1-4 | D20: 20 | E20: 보통 | F20: 품질관리 취약 시간대 관리기준 수립 및 관리상태 | G20: 품질취약시간관리기준서 | H20: SH-FM-PRD-N04 | J20: 생산팀 | K20: 지성규 | L20: 신규 작성 필요 | N20: 2026-10
A21: 17 | B21: 1. 생산조건관리 | C21: 1-4 | E21: 보통 | F21: 주간/야간 작업전 일상점검, 자주검사 및 순회검사 관리기준 수립 및 관리상태 | G21: 비상연락망 | H21: SH-FM-QP020-01 | J21: 생산팀 | L21: 기존 절차 연계 | M21: SH-QP-020(비상계획 및 공급연속성 절차서) [본문 확인 ratio=0.48] | N21: 2026-12
A22: 18 | B22: 1. 생산조건관리 | C22: 1-4 | E22: 보통 | F22: 주간/야간 교대 시 공정 Issue 사항 전달 여부 | G22: 주야간업무 인수인계서 | H22: SH-FM-WI015-01 | I22: 관리본 배포 | J22: 생산팀 | L22: 기존 절차 연계 | M22: SH-WI-015(작업자 표준작업 및 교대인수인계 표준) [본문 확인 ratio=0.83] | N22: 2026-12
A23: 19 | B23: 1. 생산조건관리 | C23: 1-4 | E23: 보통 | F23: ※ 초/종품 검사는 필수, 중품은 선택사항으로 자율적 기준 수립필요, 중품검사 미진행도 가능, | G23: 야간설비일상점검표 | H23: SH-FM-WI004-06 | I23: 관리본 배포 | J23: 생산팀 | L23: 기존 절차 연계 | M23: SH-WI-004(설비 일상점검 및 이상대응 표준) [확정 2026-09-22: 기존 추정 SH-WI-001(ratio=0.17) 대비 대안 채택(ratio=0.73) — 품질경영담당 일괄판단, 부서 정식회신 생략] | N23: 2026-12 | P23: ※재판정(본문대조) 확정(2026-09-22, 품질경영담당 일괄판단 — 부서 정식회신 없이 처리): 관련 기존 문서란 참고 | FM번호 재부여(2026-09-22, 확정 연계절차 기준): SH-FM-WI001-01 → SH-FM-WI004-06 | Q23: 대안 채택 | R23: SH-WI-004(설비 일상점검 및 이상대응 표준) | S23: 박철호(품질경영 담당, 일괄확정) | T23: 2026-09-22
A24: 20 | B24: 1. 생산조건관리 | C24: 1-4 | E24: 보통 | F24: 단, 생산LOT가 장기적일경우 최소 1회/shift검사 진행 필요 | G24: 야간생산품 식별격리절차 | H24: SH-FM-WI003-01 | J24: 품질팀 | K24: 이광재 | L24: 기존 절차 연계 | M24: SH-WI-003(부적합품 식별·격리 및 재작업 표준) [참고: 본문상 명확한 근거 약함(ratio=0.24), 담당부서 확인 권장] | N24: 2026-11 | P24: ※재판정(본문대조): 본문상 명확한 근거 약함 — 담당부서 확인 권장(기존 분류 유지)
A25: 21 | B25: 1. 생산조건관리 | C25: 1-4 | E25: 보통 | F25: ※ 인원 부족으로 야간 검사요원 미 투입 시 야간 생산품 검증 프로세스 수립 | G25: 야간생산품 검사일지 | H25: SH-FM-PRD-N05 | J25: 품질팀 | L25: 신규 작성 필요 | N25: 2026-09
A26: 22 | B26: 1. 생산조건관리 | C26: 1-5 | D26: 70 | E26: 높음 | F26: ▣ CO2 용접 ▷ 주요조건 (전류.전압.속도.가스유량) 기준수립 및 현장 관리 상태 비교검증 실시. - 전류.전압.가스 표준조건 대비 게이지 현재값 일상 체크 및 기록관리 - 전류.전압 게이지 현재값 실측 검증 (측정주기 자체설정. 단 주기설정 근거보관 필요) - 로봇 용접 프로그램 백업 관리 (궤적.티칭각도 등) ▣ 스폿 용접 ▷ 주요조건(가압력.전류.통전시간) 기준수립 및 표준 대비, 현장 관리 상태 비교검증 실시. - 가압력,전류.통전시간등 표준조건 대비 게이지 현재값 일상 체크 및 기록관리 - 가압력 점검 (가압력계) - (측정주기 자체설정. 단 주기설정 근거보관 필요) - 전류. 통전시간 점검 (웰드체카) - (측정주기 자체설정. 단 주기설정 근거보관 필요) | G26: 작업표준서 OR 작업조건표 | H26: SH-FM-QP003-02 | I26: 관리본 배포 | J26: 생산팀 | K26: 지성규 | L26: 기존 절차 연계 | M26: SH-QP-003(기록관리 절차서); SH-WI-011(공정조건 설정 및 변경관리 표준) [참고: 본문상 명확한 근거 약함(ratio=0.15), 담당부서 확인 권장] | N26: 2026-11 | P26: ※재판정(본문대조): 본문상 명확한 근거 약함 — 담당부서 확인 권장(기존 분류 유지)
A27: 23 | B27: 1. 생산조건관리 | C27: 1-5 | E27: 높음 | G27: 작업일보 | H27: SH-FM-PRD-N06 | I27: 관리본 배포 | J27: 생산팀 | L27: 신규 작성 필요 | N27: 2026-09
A28: 24 | B28: 1. 생산조건관리 | C28: 1-5 | E28: 높음 | G28: (작업일보내작업조건필히기록) | H28: SH-FM-WI001-01 | J28: (부서 미정) | L28: 기존 절차 연계 | M28: SH-WI-001(생산 작업준비 및 초품확인 표준) [확정 2026-09-22: 신규 발견 연계 채택(ratio=0.72) — 품질경영담당 일괄판단, 부서 정식회신 생략] | N28: 2026-09 | P28: ※재판정(본문대조) 확정(2026-09-22, 품질경영담당 일괄판단 — 부서 정식회신 없이 처리): 관련 기존 문서란 참고 | FM번호 재부여(2026-09-22, 확정 연계절차 기준): SH-FM-PRD-N07 → SH-FM-WI001-01 | Q28: 대안 채택 | R28: SH-WI-001(생산 작업준비 및 초품확인 표준) | S28: 박철호(품질경영 담당, 일괄확정) | T28: 2026-09-22
A29: 25 | B29: 1. 생산조건관리 | C29: 1-5 | E29: 높음 | G29: 로봇용접프로그램백업관리기준서 | H29: SH-FM-QP003-05 | I29: 관리본 배포 | J29: 생산기술 | K29: 황지환 | L29: 기존 절차 연계 | M29: SH-QP-003(기록관리 절차서) [확정 2026-09-22: 신규 발견 연계 채택(ratio=0.59) — 품질경영담당 일괄판단, 부서 정식회신 생략] | N29: 2026-09 | P29: ※재판정(본문대조) 확정(2026-09-22, 품질경영담당 일괄판단 — 부서 정식회신 없이 처리): 관련 기존 문서란 참고 | FM번호 재부여(2026-09-22, 확정 연계절차 기준): SH-FM-PRD-N08 → SH-FM-QP003-05 | Q29: 대안 채택 | R29: SH-QP-003(기록관리 절차서) | S29: 박철호(품질경영 담당, 일괄확정) | T29: 2026-09-22
A30: 26 | B30: 1. 생산조건관리 | C30: 1-5 | E30: 높음 | G30: 로봇용접프로그램백업관리실적 | H30: SH-FM-QP003-06 | I30: 관리본 배포 | J30: 생산기술 | L30: 기존 절차 연계 | M30: SH-QP-003(기록관리 절차서) [확정 2026-09-22: 신규 발견 연계 채택(ratio=0.82) — 품질경영담당 일괄판단, 부서 정식회신 생략] | N30: 2026-09 | P30: ※재판정(본문대조) 확정(2026-09-22, 품질경영담당 일괄판단 — 부서 정식회신 없이 처리): 관련 기존 문서란 참고 | FM번호 재부여(2026-09-22, 확정 연계절차 기준): SH-FM-PRD-N09 → SH-FM-QP003-06 | Q30: 대안 채택 | R30: SH-QP-003(기록관리 절차서) | S30: 박철호(품질경영 담당, 일괄확정) | T30: 2026-09-22
A31: 27 | B31: 1. 생산조건관리 | C31: 1-5 | E31: 높음 | G31: 용접조건 검증체크시트 | H31: SH-FM-PRD-N10 | J31: 생산기술 | L31: 신규 작성 필요 | N31: 2026-09
A32: 28 | B32: 1. 생산조건관리 | C32: 1-5 | E32: 높음 | G32: 스폿용접전류/가압력 관리기준서 | H32: SH-FM-PRD-N11 | J32: (부서 미정) | L32: 신규 작성 필요 | N32: 2026-09
A33: 29 | B33: 1. 생산조건관리 | C33: 1-5 | E33: 높음 | G33: 스폿용접전류/가압력 관리실적(1회/월) | H33: SH-FM-PRD-N12 | J33: 생산기술 | K33: 황지환 | L33: 신규 작성 필요 | N33: 2026-09
A34: 30 | B34: 2. 검사시험 | C34: 2-1 | D34: 40 | E34: 높음 | F34: 검사협정서/기준서 체결상태 | G34: 원자재 검사협정서 OR 검사기준서 | H34: SH-FM-QP013-01 | J34: 구매자재팀 | K34: 이은주 박철호 | L34: 기존 절차 연계 | M34: SH-QP-013(검사 및 시험관리 절차서) [본문 확인 ratio=0.46] | N34: 2026-10
A35: 31 | B35: 2. 검사시험 | C35: 2-1 | E35: 높음 | F35: (사급품은 1차 협력사가 체결한 검사협정서 사본 접수 및 동일 시료/주기로 검사 실시 필요) | G35: 원자재 입고 LIST | H35: SH-FM-WI009-01 | J35: 구매자재팀 | L35: 기존 절차 연계 | M35: SH-WI-009(자재 입고·보관·불출 관리 표준) [본문 확인 ratio=0.42] | N35: 2026-10
A36: 32 | B36: 2. 검사시험 | C36: 2-1 | E36: 높음 | F36: → 검사협정 체결이 어려울 시 검사기준서 수립으로 대체 (예: 대기업 공급 원재료,도금업종 등) | G36: 원자재수입검사 기준서 | H36: SH-FM-QP013-02 | I36: 관리본 배포 | J36: 구매자재팀 | L36: 기존 절차 연계 | M36: SH-QP-013(검사 및 시험관리 절차서) [본문 확인 ratio=0.68] | N36: 2026-11
A37: 33 | B37: 2. 검사시험 | C37: 2-1 | E37: 높음 | F37: 외주품 입고 시 외주사 출하성적서 접수 및 수입검사 실측값 비교검증 여부 | G37: 원자재수입검사 일지 | H37: SH-FM-QP013-10 | J37: 구매자재팀 | L37: 기존 절차 연계 | M37: SH-QP-013(검사 및 시험관리 절차서) [확정 2026-09-22: 신규 발견 연계 채택(ratio=0.91) — 품질경영담당 일괄판단, 부서 정식회신 생략] | N37: 2026-09 | P37: ※재판정(본문대조) 확정(2026-09-22, 품질경영담당 일괄판단 — 부서 정식회신 없이 처리): 관련 기존 문서란 참고 | FM번호 재부여(2026-09-22, 확정 연계절차 기준): SH-FM-INS-N01 → SH-FM-QP013-10 | Q37: 대안 채택 | R37: SH-QP-013(검사 및 시험관리 절차서) | S37: 박철호(품질경영 담당, 일괄확정) | T37: 2026-09-22
A38: 34 | B38: 2. 검사시험 | C38: 2-1 | E38: 높음 | F38: 원재료 M/SHEET 접수 시 물성 및 화학조성비 합/부 판단기준 명확화 수립 | G38: 원자재 M/SHEET (입고LOT별 접수) | H38: SH-FM-WI029-02 | J38: 구매자재팀 | L38: 기존 절차 연계 | M38: SH-WI-029(공급자 변경품 및 초도품 확인표준) [확정 2026-09-22: 신규 발견 연계 채택(ratio=0.64) — 품질경영담당 일괄판단, 부서 정식회신 생략] | N38: 2026-09 | P38: ※재판정(본문대조) 확정(2026-09-22, 품질경영담당 일괄판단 — 부서 정식회신 없이 처리): 관련 기존 문서란 참고 | FM번호 재부여(2026-09-22, 확정 연계절차 기준): SH-FM-INS-N02 → SH-FM-WI029-02 | Q38: 대안 채택 | R38: SH-WI-029(공급자 변경품 및 초도품 확인표준) | S38: 박철호(품질경영 담당, 일괄확정) | T38: 2026-09-22
A39: 35 | B39: 2. 검사시험 | C39: 2-1 | E39: 높음 | F39: 입고 LOT와 출하검사 성적서내 LOT 일치성 확보여부(원소재의 경우 M/SHEET내 검사시료 LOT 일치성) | G39: 원자재 규격별 물성및 화학조성비 기준서 | H39: SH-FM-WI027-01 | I39: 관리본 배포 | J39: 구매자재팀 | L39: 기존 절차 연계 | M39: SH-WI-027(검사성적서 및 품질기록 작성 표준) [참고: 본문상 명확한 근거 약함(ratio=0.22), 담당부서 확인 권장] | N39: 2026-11 | P39: ※재판정(본문대조): 본문상 명확한 근거 약함 — 담당부서 확인 권장(기존 분류 유지)
A40: 36 | B40: 2. 검사시험 | C40: 2-1 | E40: 높음 | F40: 검사협정서/기준서에 준한 일상검사/정기검사 실시상태 | G40: 원자재 중금속검사 성적서 | H40: SH-FM-WI027-02 | J40: 구매자재팀 | L40: 기존 절차 연계 | M40: SH-WI-027(검사성적서 및 품질기록 작성표준) [본문 확인 ratio=0.80] | N40: 2026-11
...

Sheet 신규작성_실행리스트
A1: SQ mark 심사 - 신규 작성 필요 문서 실행 리스트
A2: 작성일: 2026-09-17(Rev.2) | 기존 절차/표준이 없어 절차 검토부터 필요한 104건 | 우선순위 A(배점40+) > B(20~39) > C(19이하)
A3: DISCLAIMER: "작성구분"/"관련 기존 문서"는 QMS_REV00 품질경영시스템 통합문서(SH-QP-001~025, SH-WI-001~030) 실제 본문과 대조한 재판정 결과입니다(2026-09-17, Rev.2). 녹색=본문상 근거 확인된 기존 연계, 노란색="기존 절차 연계 (제안 — 검토 필요)"로 표시된 항목(본문 근거가 약하거나 새로 발견된 연계 후보 — 관련 기존 문서 칸의 [재검토]/[신규 발견]/[참고] 문구 확인), 빨간색=신규 작성 필요. "FM문서번호(안)"/"목표완료월"은 규칙 기반 1차 추정치입니다. 실제 활용 가능 여부, 양식 신규 제정 여부, 일정은 반드시 담당부서·품질책임자 검토 후 확정하세요.
A4: NO | B4: 우선순위 | C4: 구분 | D4: 번호 | E4: FM문서번호(안) | F4: 요구사항(세부 추진 항목) | G4: 필요서류(준비서류) | H4: 담당부서 | I4: 담당자 | J4: 목표완료월(제안) | K4: 준비상태 | L4: 비고
A5: 1 | B5: 높음 | C5: 1. 생산조건관리 | D5: 1-5 | E5: SH-FM-PRD-N06 | G5: 작업일보 | H5: 생산팀 | J5: 2026-09
A6: 2 | B6: 높음 | C6: 1. 생산조건관리 | D6: 1-5 | E6: SH-FM-PRD-N10 | G6: 용접조건 검증체크시트 | H6: 생산기술 | J6: 2026-09
A7: 3 | B7: 높음 | C7: 1. 생산조건관리 | D7: 1-5 | E7: SH-FM-PRD-N11 | G7: 스폿용접전류/가압력 관리기준서 | H7: (부서 미정) | J7: 2026-09
A8: 4 | B8: 높음 | C8: 1. 생산조건관리 | D8: 1-5 | E8: SH-FM-PRD-N12 | G8: 스폿용접전류/가압력 관리실적(1회/월) | H8: 생산기술 | I8: 황지환 | J8: 2026-09
A9: 5 | B9: 높음 | C9: 2. 검사시험 | D9: 2-1 | E9: SH-FM-INS-N03 | F9: (원소재) 도금처리된 원소재 판넬 : 도금 부착력 검사 (180˚밴딩후 크랙, 박리여부), 도금두께(3point), | G9: 원자재식별표 | H9: 구매자재팀 | J9: 2026-09
A10: 6 | B10: 높음 | C10: 2. 검사시험 | D10: 2-7 | E10: SH-FM-INS-N12 | F10: 용접제품 표면관리기준 설정 (스패터, Chip, 버어, 이물질 ) 및 점검 이력 관리 | G10: 용접스패터관리 점검체크시트 | H10: 품질팀 | I10: 이광재 | J10: 2026-09
A11: 7 | B11: 높음 | C11: 2. 검사시험 | D11: 2-8 | E11: SH-FM-INS-N13 | G11: 완성품검사체크시트 | H11: 품질팀 | I11: 김명용 | J11: 2026-09
A12: 8 | B12: 높음 | C12: 2. 검사시험 | D12: 2-8 | E12: SH-FM-INS-N14 | G12: 완성품검사식별표 | H12: 품질팀 | I12: 김명용 | J12: 2026-09
A13: 9 | B13: 높음 | C13: 2. 검사시험 | D13: 2-9 | E13: SH-FM-INS-N18 | F13: 아크 용접 : 용접비드, 위치 (길이, 폭, 이동량) 및 용입량 - CO2용접: 절단검사(정기검사). (용접 구간별 길이,비드 폭 형상 한도견본 비교검사) * 용입량 검사 : 용접로봇별, 용접JIG별 검사 (검사 주기 : 1회/년, 단, 4M 변경 시 용입량 검사 진행할 것(용접조건 변경, 설비변경, 지그 수정/변경, 로봇 티칭 이후 외) ※ 검사 시료 및 주기는 고객과 협의된 검사협정/기준서 따를것 ▷ 저항 용접 : 분리력 - 스폿용접: 반파괴, 전파괴 분리시험 / 드라이브 체크 ▷ (초,종품 실시) 인장강도 만족할것(실물 및 시편) / 볼트너트: 망치 타격시험 - 프로젝션용접: 볼트 너트 ▷ 회전 토르크 검사 (초, 종 검사) 예) 용접비드 이탈 및 분리력 검사 → 검사결과 사진, 스캔저장 → 검사이력 D/B 관리(엑셀등) | G13: 용입검사 계획대실적 | H13: 품질팀 | I13: 이광재 | J13: 2026-09
A14: 10 | B14: 높음 | C14: 2. 검사시험 | D14: 2-9 | E14: SH-FM-INS-N19 | G14: 용접로보트별 용접POINT 관리표준 | H14: 생산팀 | I14: 한상돈 | J14: 2026-09
A15: 11 | B15: 높음 | C15: 2. 검사시험 | D15: 2-9 | E15: SH-FM-INS-N20 | G15: 용접로보트별 용접POINT 관리표준 | H15: 품질팀 | I15: 이광재 | J15: 2026-09
A16: 12 | B16: 높음 | C16: 2. 검사시험 | D16: 2-9 | E16: SH-FM-INS-N21 | G16: 용접반파괴/파괴검사기준 | H16: 생산팀 | I16: 한상돈 | J16: 2026-09
A17: 13 | B17: 높음 | C17: 2. 검사시험 | D17: 2-9 | E17: SH-FM-INS-N22 | G17: 용접검사체크시트 | H17: 생산팀 | I17: 한상돈 | J17: 2026-09
A18: 14 | B18: 높음 | C18: 2. 검사시험 | D18: 2-9 | E18: SH-FM-INS-N23 | G18: 용접반파괴 검사대제작 | H18: 생산팀 | I18: 한상돈 | J18: 2026-09
A19: 15 | B19: 높음 | C19: 2. 검사시험 | D19: 2-8 | E19: SH-FM-INS-N17 | G19: (QMS SYSTEM 운영시 컴퓨터설치운영) | H19: (부서 미정) | J19: 2026-10
A20: 16 | B20: 보통 | C20: 1. 생산조건관리 | D20: 1-4 | E20: SH-FM-PRD-N05 | F20: ※ 인원 부족으로 야간 검사요원 미 투입 시 야간 생산품 검증 프로세스 수립 | G20: 야간생산품 검사일지 | H20: 품질팀 | J20: 2026-09
A21: 17 | B21: 보통 | C21: 2. 검사시험 | D21: 2-2 | E21: SH-FM-INS-N04 | F21: 수입검사 실시 전 외주품/원재료 입고처리 안되도록 업무 프로세스 수립 | G21: 외주품입고식별표 | H21: 구매자재팀 | I21: 이은주 | J21: 2026-09
A22: 18 | B22: 보통 | C22: 2. 검사시험 | D22: 2-2 | E22: SH-FM-INS-N05 | G22: 외주품 부적합처리기준서 | H22: 품질팀 | I22: 김명용 | J22: 2026-09
A23: 19 | B23: 보통 | C23: 2. 검사시험 | D23: 2-2 | E23: SH-FM-INS-N06 | G23: 외주품 검사협정서 | H23: 품질팀 | I23: 이광재 | J23: 2026-09
A24: 20 | B24: 보통 | C24: 2. 검사시험 | D24: 2-3 | E24: SH-FM-INS-N07 | F24: 외주품/완제품 외관 합/부 판별용 한도견본 운영 | G24: 한도견본 관리대장(외주품/완성품) | H24: 품질팀 | I24: 김명용 | J24: 2026-09
A25: 21 | B25: 보통 | C25: 2. 검사시험 | D25: 2-4 | E25: SH-FM-INS-N09 | F25: 정기 시험 성적서 신뢰도 확보 | G25: 정기검사계획대실적(치수/용접) | H25: 품질팀 | I25: 이광재 | J25: 2026-09
A26: 22 | B26: 보통 | C26: 2. 검사시험 | D26: 2-4 | E26: SH-FM-INS-N10 | F26: 환경규제(중금속) 정기시험 실시상태 : 검사협정 체결기준 시험결과 증빙관리 상태 | G26: 중금속 정기검사 계획대실적 | H26: 구매자재팀 | I26: 이은주 | J26: 2026-09
A27: 23 | B27: 보통 | C27: 2. 검사시험 | D27: 2-4 | E27: SH-FM-INS-N11 | F27: (시험장비 보유시 자체 성적서 인정, 미보유시 1차사 또는 공인기관 의뢰 가능) | G27: 중금속 성적서 | H27: 구매자재팀 | I27: 이은주 | J27: 2026-09
A28: 24 | B28: 보통 | C28: 3. 설비관리 | D28: 3-1 | E28: SH-FM-EQP-N01 | F28: 설비 셋팅값 임의조작 방지를 위한 시건장치/KEY-LOCK 반영상태 | G28: 설비 오셋팅방지 KEY-LOCK | H28: 생산팀 | I28: 한상돈 | J28: 2026-09
A29: 25 | B29: 보통 | C29: 3. 설비관리 | D29: 3-3 | E29: SH-FM-EQP-N11 | F29: '- 유압설비: 유압. 유량. 소음. 누유 등 이상유무 확인 | G29: 스폿로봇 원점확인장치 | H29: 생산팀 | I29: 김운주 | J29: 2026-09
A30: 26 | B30: 보통 | C30: 3. 설비관리 | D30: 3-3 | E30: SH-FM-EQP-N12 | F30: 유틸리티: 에어압력. 냉각수(온도: 10∼30℃). 압력: 가스 유량 | G30: 용접전극드레싱/교환 F/P장비설치 | H30: 생산팀 | I30: 김운주 | J30: 2026-09
A31: 27 | B31: 보통 | C31: 3. 설비관리 | D31: 3-5 | E31: SH-FM-EQP-N17 | F31: 기준준수 및 이행상태 | G31: 스폿로봇 원점확인장치 | H31: 생산팀 | I31: 황지환 | J31: 2026-09
A32: 28 | B32: 보통 | C32: 5. 자재관리 | D32: 5-1 | E32: SH-FM-MAT-N01 | F32: 수입검사 완료품 식별 프로세스 수립 (합격도장 등) - 보안/안전 부품 별도 식별 표시 : LOT타각, 식별마크 등 | G32: 작업일보 | H32: 생산팀 | I32: 지성규 | J32: 2026-09
A33: 29 | B33: 보통 | C33: 5. 자재관리 | D33: 5-1 | E33: SH-FM-MAT-N02 | F33: 선입선출 준수여부 - 중요부품 샘플링 점검, 인라인투입제품, 투입대기제품, 자재창고 적재 제품 생산일 점검 | G33: 작업일보 | H33: 생산팀 | I33: 지성규 | J33: 2026-09
A34: 30 | B34: 보통 | C34: 5. 자재관리 | D34: 5-1 | E34: SH-FM-MAT-N03 | F34: 부품 LOT 표기 여부 (표준류 지정시) - 각인, 스티커, 타각 등 | G34: 부품식별표 | H34: 생산팀 | I34: 지성규 | J34: 2026-09
A35: 31 | B35: 보통 | C35: 6. 품질경영체제 | D35: 6-1 | E35: SH-FM-QMS-N02 | F35: : 생산라인 투입전 핸드폰 보관을 위한 별도 보관대 설치 및 활용상태 점검 (생산중 핸드폰 사용에 따른 사고 방지) | G35: 안전보호구 지급기준 | H35: 생산팀 | I35: 지성규 | J35: 2026-09
... A41: 37 | B41: 보통 | C41: 6. 품질경영체제 | D41: 6-3 | E41: SH-FM-QMS-N15 | F41: '-도면 일치성 점검 담당자 지정하여 정기적 도면대비 검사협정/기준서 일치성 점검 및 점검이력 관리 | G41: 도면/검사협정서/초도품보증서고객승인본 | H41: 품질팀 | I41: 이광재 | J41: 2026-09
A42: 38 | B42: 보통 | C42: 6. 품질경영체제 | D42: 6-3 | E42: SH-FM-QMS-N16 | G42: 정기검사실적 | H42: 품질팀 | I42: 이광재 | J42: 2026-09
A43: 39 | B43: 보통 | C43: 6. 품질경영체제 | D43: 6-5 | E43: SH-FM-QMS-N21 | F43: 공정별 작업자/검사자 배치기준 수립 및 자격인증 평가 실시여부 [품질 표준류내 검사지정 항목별 담당자] | G43: 자격인증관리 기준서 | H43: 품질팀 | I43: 이광재 | J43: 2026-09
A44: 40 | B44: 보통 | C44: 1. 생산조건관리 | D44: 1-4 | E44: SH-FM-PRD-N04 | F44: 품질관리 취약 시간대 관리기준 수립 및 관리상태 | G44: 품질취약시간관리기준서 | H44: 생산팀 | I44: 지성규 | J44: 2026-10
A45: 41 | B45: 보통 | C45: 2. 검사시험 | D45: 2-3 | E45: SH-FM-INS-N08 | F45: 검사기 신뢰도 확인을 위한 양/불 마스터 설정기준 및 관리상태 | G45: 한도견본 샘플보관대 및 샘플 | H45: 생산팀 | I45: 지성규 | J45: 2026-10
...

Sheet FM양식번호_초안
A1: SQ mark 심사 - 신규 양식(FM) 문서번호 부여 초안
A2: 작성일: 2026-09-17(Rev.2) | 총 240건 | 체계: SH-FM-<근거 QP/WI 번호>-<순번> / 근거 문서가 없으면 SH-FM-<SQ구분코드>-N<순번> | 문서관리대장(SH-FM-002-01 표기 방식) 준용
A3: DISCLAIMER: "작성구분"/"관련 기존 문서"는 QMS_REV00 품질경영시스템 통합문서(SH-QP-001~025, SH-WI-001~030) 실제 본문과 대조한 재판정 결과입니다(2026-09-17, Rev.2). 녹색=본문상 근거 확인된 기존 연계, 노란색="기존 절차 연계 (제안 — 검토 필요)"로 표시된 항목(본문 근거가 약하거나 새로 발견된 연계 후보 — 관련 기존 문서 칸의 [재검토]/[신규 발견]/[참고] 문구 확인), 빨간색=신규 작성 필요. "FM문서번호(안)"/"목표완료월"은 규칙 기반 1차 추정치입니다. 실제 활용 가능 여부, 양식 신규 제정 여부, 일정은 반드시 담당부서·품질책임자 검토 후 확정하세요.
A4: NO | B4: 문서구분 | C4: 문서번호(FM안) | D4: 문서명(필요서류) | E4: 근거 상위문서(QM/QP/WI) | F4: SQ 심사구분 | G4: 주관부서 | H4: 목표 제정월 | I4: 제정상태 | J4: 비고
A5: 1 | B5: FM | C5: SH-FM-EQP-N01 | D5: 설비 오셋팅방지 KEY-LOCK | E5: (신규 절차 필요) | F5: 3. 설비관리 | G5: 생산팀 | H5: 2026-09 | I5: 제정 예정
A6: 2 | B6: FM | C6: SH-FM-EQP-N02 | D6: 설비정기점검 계획대실적표 | E6: (신규 절차 필요) | F6: 3. 설비관리 | G6: 생산기술 | H6: 2026-10 | I6: 제정 예정 | J6: 0
A7: 3 | B7: FM | C7: SH-FM-EQP-N03 | D7: 설비정기점검 실적 | E7: (신규 절차 필요) | F7: 3. 설비관리 | G7: 생산기술 | H7: 2026-10 | I7: 제정 예정
A8: 4 | B8: FM | C8: SH-FM-EQP-N04 | D8: 설비관리대장 | E8: (신규 절차 필요) | F8: 3. 설비관리 | G8: 생산기술 | H8: 2026-10 | I8: 제정 예정
A9: 5 | B9: FM | C9: SH-FM-EQP-N05 | D9: 설비이력카드 | E9: (신규 절차 필요) | F9: 3. 설비관리 | G9: 생산기술 | H9: 2026-10 | I9: 제정 예정
A10: 6 | B10: FM | C10: SH-FM-QP015-01 | D10: 설비압력게이지 검증 계획대실적표 | E10: SH-QP-015 | F10: 3. 설비관리 | G10: 생산기술 | H10: 2026-10 | I10: 제정 예정 | J10: ※재판정(본문대조): 기존 절차 연계 가능성 신규 발견 — 검토 후 확정 필요
A11: 7 | B11: FM | C11: SH-FM-EQP-N07 | D11: 설비예비품 입출고 관리일지 | E11: (신규 절차 필요) | F11: 3. 설비관리 | G11: 생산기술 | H11: 2026-11 | I11: 제정 예정
A12: 8 | B12: FM | C12: SH-FM-EQP-N08 | D12: 작동유관리기준서 | E12: (신규 절차 필요) | F12: 3. 설비관리 | G12: 생산기술 | H12: 2026-11 | I12: 제정 예정
A13: 9 | B13: FM | C13: SH-FM-EQP-N09 | D13: 작동유샘플보관대제작설치 | E13: (신규 절차 필요) | F13: 3. 설비관리 | G13: 생산기술 | H13: 2026-11 | I13: 제정 예정
A14: 10 | B14: FM | C14: SH-FM-EQP-N10 | D14: CO2용접원점확인장치 | E14: (신규 절차 필요) | F14: 3. 설비관리 | G14: (부서 미정) | H14: 2026-10 | I14: 제정 예정
A15: 11 | B15: FM | C15: SH-FM-EQP-N11 | D15: 스폿로봇 원점확인장치 | E15: (신규 절차 필요) | F15: 3. 설비관리 | G15: 생산팀 | H15: 2026-09 | I15: 제정 예정
A16: 12 | B16: FM | C16: SH-FM-EQP-N12 | D16: 용접전극드레싱/교환 F/P장비설치 | E16: (신규 절차 필요) | F16: 3. 설비관리 | G16: 생산팀 | H16: 2026-09 | I16: 제정 예정
A17: 13 | B17: FM | C17: SH-FM-EQP-N13 | D17: 설비정기점검 관리기준서 | E17: (신규 절차 필요) | F17: 3. 설비관리 | G17: 생산기술 | H17: 2026-11 | I17: 제정 예정
A18: 14 | B18: FM | C18: SH-FM-EQP-N14 | D18: 설비정기점검계획대실적표 | E18: (신규 절차 필요) | F18: 3. 설비관리 | G18: 생산기술 | H18: 2026-11 | I18: 제정 예정
A19: 15 | B19: FM | C19: SH-FM-EQP-N15 | D19: 설비정기점검 실적 | E19: (신규 절차 필요) | F19: 3. 설비관리 | G19: 생산기술 | H19: 2026-12 | I19: 제정 예정
A20: 16 | B20: FM | C20: SH-FM-EQP-N16 | D20: CO2용접원점확인장치 | E20: (신규 절차 필요) | F20: 3. 설비관리 | G20: (부서 미정) | H20: 2026-11 | I20: 제정 예정
A21: 17 | B21: FM | C21: SH-FM-EQP-N17 | D21: 스폿로봇 원점확인장치 | E21: (신규 절차 필요) | F21: 3. 설비관리 | G21: 생산팀 | H21: 2026-09 | I21: 제정 예정
A22: 18 | B22: FM | C22: SH-FM-EQP-N18 | D22: 가스잔량 F/P장치 | E22: (신규 절차 필요) | F22: 3. 설비관리 | G22: (부서 미정) | H22: 2026-11 | I22: 제정 예정
... A26: 22 | B26: FM | C26: SH-FM-EQP-N22 | D26: JIG PIN 위치도 및 상세사진 위치도 | E26: (신규 절차 필요) | F26: 3. 설비관리 | G26: 생산팀 | H26: 2026-10 | I26: 제정 예정
A27: 23 | B27: FM | C27: SH-FM-QP013-10 | D27: 원자재수입검사 일지 | E27: SH-QP-013 | F27: 2. 검사시험 | G27: 구매자재팀 | H27: 2026-09 | I27: 제정 예정 | J27: ※재판정(본문대조): 기존 절차 연계 가능성 신규 발견 — 검토 후 확정 필요
A28: 24 | B28: FM | C28: SH-FM-WI029-02 | D28: 원자재 M/SHEET (입고LOT별 접수) | E28: SH-WI-029 | F28: 2. 검사시험 | G28: 구매자재팀 | H28: 2026-09 | I28: 제정 예정 | J28: ※재판정(본문대조): 기존 절차 연계 가능성 신규 발견 — 검토 후 확정 필요
A29: 25 | B29: FM | C29: SH-FM-INS-N03 | D29: 원자재식별표 | E29: (신규 절차 필요) | F29: 2. 검사시험 | G29: 구매자재팀 | H29: 2026-09 | I29: 제정 예정
A30: 26 | B30: FM | C30: SH-FM-INS-N04 | D30: 외주품입고식별표 | E30: (신규 절차 필요) | F30: 2. 검사시험 | G30: 구매자재팀 | H30: 2026-09 | I30: 제정 예정
A31: 27 | B31: FM | C31: SH-FM-INS-N05 | D31: 외주품 부적합처리기준서 | E31: (신규 절차 필요) | F31: 2. 검사시험 | G31: 품질팀 | H31: 2026-09 | I31: 제정 예정
A32: 28 | B32: FM | C32: SH-FM-INS-N06 | D32: 외주품 검사협정서 | E32: (신규 절차 필요) | F32: 2. 검사시험 | G32: 품질팀 | H32: 2026-09 | I32: 제정 예정
A33: 29 | B33: FM | C33: SH-FM-INS-N07 | D33: 한도견본 관리대장(외주품/완성품) | E33: (신규 절차 필요) | F33: 2. 검사시험 | G33: 품질팀 | H33: 2026-09 | I33: 제정 예정
A34: 30 | B34: FM | C34: SH-FM-INS-N08 | D34: 한도견본 샘플보관대 및 샘플 | E34: (신규 절차 필요) | F34: 2. 검사시험 | G34: 생산팀 | H34: 2026-10 | I34: 제정 예정
A35: 31 | B35: FM | C35: SH-FM-INS-N09 | D35: 정기검사계획대실적(치수/용접) | E35: (신규 절차 필요) | F35: 2. 검사시험 | G35: 품질팀 | H35: 2026-09 | I35: 제정 예정
A36: 32 | B36: FM | C36: SH-FM-INS-N10 | D36: 중금속 정기검사 계획대실적 | E36: (신규 절차 필요) | F36: 2. 검사시험 | G36: 구매자재팀 | H36: 2026-09 | I36: 제정 예정
A37: 33 | B37: FM | C37: SH-FM-INS-N11 | D37: 중금속 성적서 | E37: (신규 절차 필요) | F37: 2. 검사시험 | G37: 구매자재팀 | H37: 2026-09 | I37: 제정 예정
A38: 34 | B38: FM | C38: SH-FM-INS-N12 | D38: 용접스패터관리 점검체크시트 | E38: (신규 절차 필요) | F38: 2. 검사시험 | G38: 품질팀 | H38: 2026-09 | I38: 제정 예정
A39: 35 | B39: FM | C39: SH-FM-INS-N13 | D39: 완성품검사체크시트 | E39: (신규 절차 필요) | F39: 2. 검사시험 | G39: 품질팀 | H39: 2026-09 | I39: 제정 예정
A40: 36 | B40: FM | C40: SH-FM-INS-N14 | D40: 완성품검사식별표 | E40: (신규 절차 필요) | F40: 2. 검사시험 | G40: 품질팀 | H40: 2026-09 | I40: 제정 예정
A41: 37 | B41: FM | C41: SH-FM-WI006-10 | D41: 완성품보관장소선정 | E41: SH-WI-006 | F41: 2. 검사시험 | G41: 품질팀 | H41: 2026-09 | I41: 제정 예정 | J41: ※재판정(본문대조): 기존 절차 연계 가능성 신규 발견 — 검토 후 확정 필요
A42: 38 | B42: FM | C42: SH-FM-QP012-01 | D42: 완성검사관리대제작 | E42: SH-QP-012 | F42: 2. 검사시험 | G42: 품질팀 | H42: 2026-09 | I42: 제정 예정 | J42: ※재판정(본문대조): 기존 절차 연계 가능성 신규 발견 — 검토 후 확정 필요
A43: 39 | B43: FM | C43: SH-FM-INS-N17 | D43: (QMS SYSTEM 운영시 컴퓨터설치운영) | E43: (신규 절차 필요) | F43: 2. 검사시험 | G43: (부서 미정) | H43: 2026-10 | I43: 제정 예정
...

Sheet C1_생산조건관리
A1: SQ mark 심사 - 1. 생산조건관리 필요서류 체크리스트
A2: 고객사: 한온시스템 | 작성일: 2026-09-17(Rev.2) | 해당 구분 필요서류: 29건
A3: DISCLAIMER: "작성구분"/"관련 기존 문서"는 QMS_REV00 품질경영시스템 통합문서(SH-QP-001~025, SH-WI-001~030) 실제 본문과 대조한 재판정 결과입니다(2026-09-17, Rev.2). 녹색=본문상 근거 확인된 기존 연계, 노란색="기존 절차 연계 (제안 — 검토 필요)"로 표시된 항목(본문 근거가 약하거나 새로 발견된 연계 후보 — 관련 기존 문서 칸의 [재검토]/[신규 발견]/[참고] 문구 확인), 빨간색=신규 작성 필요. "FM문서번호(안)"/"목표완료월"은 규칙 기반 1차 추정치입니다. 실제 활용 가능 여부, 양식 신규 제정 여부, 일정은 반드시 담당부서·품질책임자 검토 후 확정하세요.
A4: NO | B4: 번호 | C4: 우선순위 | D4: 요구사항(세부 추진 항목) | E4: 필요서류(준비서류) | F4: FM문서번호(안) | G4: 현장 연계 | H4: 담당부서 | I4: 담당자 | J4: 작성구분(자동추정) | K4: 관련 기존 문서(참고) | L4: 목표완료월(제안) | M4: 준비상태 | N4: 비고
A5: 1 | B5: 1-5 | C5: 높음 | E5: 작업일보 | F5: SH-FM-PRD-N06 | G5: 관리본 배포 | H5: 생산팀 | J5: 신규 작성 필요 | L5: 2026-09
A6: 2 | B6: 1-5 | C6: 높음 | E6: (작업일보내작업조건필히기록) | F6: SH-FM-WI001-01 | H6: (부서 미정) | J6: 기존 절차 연계 | K6: SH-WI-001(생산 작업준비 및 초품확인 표준) [확정 2026-09-22: 신규 발견 연계 채택(ratio=0.72) — 품질경영담당 일괄판단, 부서 정식회신 생략] | L6: 2026-09 | N6: ※재판정(본문대조): 기존 절차 연계 가능성 신규 발견 — 검토 후 확정 필요
A7: 3 | B7: 1-5 | C7: 높음 | E7: 로봇용접프로그램백업관리기준서 | F7: SH-FM-QP003-05 | G7: 관리본 배포 | H7: 생산기술 | I7: 황지환 | J7: 기존 절차 연계 | K7: SH-QP-003(기록관리 절차서) [확정 2026-09-22: 신규 발견 연계 채택(ratio=0.59) — 품질경영담당 일괄판단, 부서 정식회신 생략] | L7: 2026-09 | N7: ※재판정(본문대조): 기존 절차 연계 가능성 신규 발견 — 검토 후 확정 필요
A8: 4 | B8: 1-5 | C8: 높음 | E8: 로봇용접프로그램백업관리실적 | F8: SH-FM-QP003-06 | G8: 관리본 배포 | H8: 생산기술 | J8: 기존 절차 연계 | K8: SH-QP-003(기록관리 절차서) [확정 2026-09-22: 신규 발견 연계 채택(ratio=0.82) — 품질경영담당 일괄판단, 부서 정식회신 생략] | L8: 2026-09 | N8: ※재판정(본문대조): 기존 절차 연계 가능성 신규 발견 — 검토 후 확정 필요
A9: 5 | B9: 1-5 | C9: 높음 | E9: 용접조건 검증체크시트 | F9: SH-FM-PRD-N10 | H9: 생산기술 | J9: 신규 작성 필요 | L9: 2026-09
A10: 6 | B10: 1-5 | C10: 높음 | E10: 스폿용접전류/가압력 관리기준서 | F10: SH-FM-PRD-N11 | H10: (부서 미정) | J10: 신규 작성 필요 | L10: 2026-09
A11: 7 | B11: 1-5 | C11: 높음 | E11: 스폿용접전류/가압력 관리실적(1회/월) | F11: SH-FM-PRD-N12 | H11: 생산기술 | I11: 황지환 | J11: 신규 작성 필요 | L11: 2026-09
A12: 8 | B12: 1-5 | C12: 높음 | D12: ▣ CO2 용접 ▷ 주요조건 (전류.전압.속도.가스유량) 기준수립 및 현장 관리 상태 비교검증 실시. - 전류.전압.가스 표준조건 대비 게이지 현재값 일상 체크 및 기록관리 - 전류.전압 게이지 현재값 실측 검증 (측정주기 자체설정. 단 주기설정 근거보관 필요) - 로봇 용접 프로그램 백업 관리 (궤적.티칭각도 등) ▣ 스폿 용접 ▷ 주요조건(가압력.전류.통전시간) 기준수립 및 표준 대비, 현장 관리 상태 비교검증 실시. - 가압력,전류.통전시간등 표준조건 대비 게이지 현재값 일상 체크 및 기록관리 - 가압력 점검 (가압력계) - (측정주기 자체설정. 단 주기설정 근거보관 필요) - 전류. 통전시간 점검 (웰드체카) - (측정주기 자체설정. 단 주기설정 근거보관 필요) | E12: 작업표준서 OR 작업조건표 | F12: SH-FM-QP003-02 | G12: 관리본 배포 | H12: 생산팀 | I12: 지성규 | J12: 기존 절차 연계 | K12: SH-QP-003(기록관리 절차서); SH-WI-011(공정조건 설정 및 변경관리 표준) [참고: 본문상 명확한 근거 약함(ratio=0.15), 담당부서 확인 권장] | L12: 2026-11 | N12: ※재판정(본문대조): 본문상 명확한 근거 약함 — 담당부서 확인 권장(기존 분류 유지)
A13: 9 | B13: 1-4 | C13: 보통 | D13: ※ 인원 부족으로 야간 검사요원 미 투입 시 야간 생산품 검증 프로세스 수립 | E13: 야간생산품 검사일지 | F13: SH-FM-PRD-N05 | H13: 품질팀 | J13: 신규 작성 필요 | L13: 2026-09
A14: 10 | B14: 1-4 | C14: 보통 | D14: 품질관리 취약 시간대 관리기준 수립 및 관리상태 | E14: 품질취약시간관리기준서 | F14: SH-FM-PRD-N04 | H14: 생산팀 | I14: 지성규 | J14: 신규 작성 필요 | L14: 2026-10
A15: 11 | B15: 1-1 | C15: 보통 | D15: 표준류(관리계획서, 작업표준서, 설비일상점검표 등)와 실제공정 일치성 확인[관리 분담 등] | E15: P-FMEA | F15: SH-FM-QP010-01 | H15: 품질팀 | I15: 이광재 | J15: 기존 절차 연계 | K15: SH-QP-010(APQP 및 PPAP 관리 절차서); SH-WI-004(설비 일상점검 및 이상대응 표준) [참고: 본문상 명확한 근거 약함(ratio=0.28), 담당부서 확인 권장] | L15: 2026-11 | N15: ※재판정(본문대조): 본문상 명확한 근거 약함 — 담당부서 확인 권장(기존 분류 유지)
A16: 12 | B16: 1-1 | C16: 보통 | D16: 고객과 협의된 검사협정서/검사기준서 기준과 실제 업무절차 일치성 | E16: 관리계획서 | F16: SH-FM-WI022-01 | H16: 품질팀 | I16: 이광재 | J16: 기존 절차 연계 | K16: SH-WI-022(변경 초기유동 및 강화검사 작업표준) [확정 2026-09-22: 기존 추정 SH-QP-010(ratio=0.34) 대비 대안 채택(ratio=0.69) — 품질경영담당 일괄판단, 부서 정식회신 생략] | L16: 2026-11 | N16: ※재판정(본문대조): 기존 근거서류 재검토 필요 — 관련문서 참고, 담당부서/품질팀 확인 후 확정
A17: 13 | B17: 1-1 | C17: 보통 | D17: 관리계획서 및 현장내 표준류 중요공정/안전 보안공정 식별표시관리 | E17: 고객승인 검사협정 / ISIR 서류 | F17: SH-FM-QP010-04 | H17: 품질팀 | I17: 이광재 | J17: 기존 절차 연계 | K17: SH-QP-010(APQP 및 PPAP 관리 절차서); SH-QP-025(고객별 요구사항(CSR) 관리 절차서) [참고: 본문상 명확한 근거 약함(ratio=0.23), 담당부서 확인 권장] | L17: 2026-11 | N17: ※재판정(본문대조): 본문상 명확한 근거 약함 — 담당부서 확인 권장(기존 분류 유지)
A18: 14 | B18: 1-2 | C18: 보통 | D18: 재가동후 초도생산품에 대한 중요품질특성부 품질검증 결과 기록관리여부 | E18: 재가동 초품 검사 체크시트 | F18: SH-FM-WI020-02 | G18: 관리본 배포 | H18: 품질팀 | I18: 이광재 | J18: 기존 절차 연계 | K18: SH-WI-020(비상상황 생산복구 작업표준) [확정 2026-09-22: 기존 추정 SH-QP-003(ratio=0.05) 대비 대안 채택(ratio=0.79) — 품질경영담당 일괄판단, 부서 정식회신 생략] | L18: 2026-11 | N18: ※재판정(본문대조): 기존 근거서류 재검토 필요 — 관련문서 참고, 담당부서/품질팀 확인 후 확정
A19: 15 | B19: 1-4 | C19: 보통 | D19: 단, 생산LOT가 장기적일경우 최소 1회/shift검사 진행 필요 | E19: 야간생산품 식별격리절차 | F19: SH-FM-WI003-01 | H19: 품질팀 | I19: 이광재 | J19: 기존 절차 연계 | K19: SH-WI-003(부적합품 식별·격리 및 재작업 표준) [참고: 본문상 명확한 근거 약함(ratio=0.24), 담당부서 확인 권장] | L19: 2026-11 | N19: ※재판정(본문대조): 본문상 명확한 근거 약함 — 담당부서 확인 권장(기존 분류 유지)
A20: 16 | B20: 1-1 | C20: 보통 | D20: 공정 FMEA작성 및 주요 품질 문서 내용과 연계상태 확인 | E20: 작업표준서 | F20: SH-FM-QP010-03 | G20: 관리본 배포 | H20: 생산팀 | I20: 지성규 | J20: 기존 절차 연계 | K20: SH-QP-010(APQP 및 PPAP 관리 절차서) [참고: 본문상 명확한 근거 약함(ratio=0.11), 담당부서 확인 권장] | L20: 2026-12 | N20: ※재판정(본문대조): 본문상 명확한 근거 약함 — 담당부서 확인 권장(기존 분류 유지)
A21: 17 | B21: 1-1 | C21: 보통 | D21: 주요 표준류(작업표준서 등) 현장내 게시 상태 | E21: 설비일상점검표 | F21: SH-FM-WI004-01 | G21: 관리본 배포 | H21: 생산팀 | I21: 지성규 | J21: 기존 절차 연계 | K21: SH-WI-004(설비 일상점검 및 이상대응 표준) [본문 확인 ratio=0.73] | L21: 2026-12
A22: 18 | B22: 1-2 | C22: 보통 | D22: 설비 가동중단 발생시 설비점검 절차 수립 및 준수상태 | E22: 설비재가동업무 프로세스 | F22: SH-FM-QP025-01 | G22: 관리본 배포 | H22: 생산팀 | I22: 지성규 | J22: 기존 절차 연계 | K22: SH-QP-025(고객별 요구사항(CSR) 관리 절차서) [확정 2026-09-22: 기존 추정 SH-WI-016(ratio=0.20) 대비 대안 채택(ratio=0.56) — 품질경영담당 일괄판단, 부서 정식회신 생략] | L22: 2026-12 | N22: ※재판정(본문대조): 기존 근거서류 재검토 필요 — 관련문서 참고, 담당부서/품질팀 확인 후 확정
A23: 19 | B23: 1-2 | C23: 보통 | D23: ※ 계획 : 가동중단 시간별/사유별 점검절차 수립 및 이행 | E23: (계획/비계획정지 기준 명확화) | F23: SH-FM-WI020-01 | H23: (부서 미정) | J23: 기존 절차 연계 | K23: SH-WI-020(비상상황 생산복구 표준); SH-WI-025(품질이상 정지·보고·재가동 표준) [참고: 본문상 명확한 근거 약함(ratio=0.28), 담당부서 확인 권장] | L23: 2026-12 | N23: ※재판정(본문대조): 본문상 명확한 근거 약함 — 담당부서 확인 권장(기존 분류 유지)
A24: 20 | B24: 1-2 | C24: 보통 | D24: 비계획 : 이상발생 가동중단 발생시 설비 점검 지침, 생산중인 제품에 대한 품질보증 업무절차 수립 및 이행 | E24: 설비가동중단 LIST (설비이력카드 연계) | F24: SH-FM-WI016-02 | G24: 관리본 배포 | H24: 생산팀 | J24: 기존 절차 연계 | K24: SH-WI-016(예방보전 및 설비점검 표준); SH-WI-020(비상상황 생산복구 표준) [참고: 본문상 명확한 근거 약함(ratio=0.09), 담당부서 확인 권장] | L24: 2026-12 | N24: ※재판정(본문대조): 본문상 명확한 근거 약함 — 담당부서 확인 권장(기존 분류 유지)
A25: 21 | B25: 1-2 | C25: 보통 | D25: 비계획 가동중단 발생시 전/후 생산제품에 대한 LOT 구분 관리방안 수립 및 식별관리 실시 | E25: 재가동 초도생산품 LOT식별관리 기준서 | F25: SH-FM-QP018-01 | H25: 생산팀 | I25: 지성규 | J25: 기존 절차 연계 | K25: SH-QP-018(식별 및 추적성 관리 절차서); SH-WI-005(제품 식별·LOT 추적 및 출하 표준) [참고: 본문상 명확한 근거 약함(ratio=0.14), 담당부서 확인 권장] | L25: 2026-12 | N25: ※재판정(본문대조): 본문상 명확한 근거 약함 — 담당부서 확인 권장(기존 분류 유지)
A26: 22 | B26: 1-4 | C26: 보통 | D26: 주간/야간 작업전 일상점검, 자주검사 및 순회검사 관리기준 수립 및 관리상태 | E26: 비상연락망 | F26: SH-FM-QP020-01 | H26: 생산팀 | J26: 기존 절차 연계 | K26: SH-QP-020(비상계획 및 공급연속성 절차서) [본문 확인 ratio=0.48] | L26: 2026-12
A27: 23 | B27: 1-4 | C27: 보통 | D27: 주간/야간 교대 시 공정 Issue 사항 전달 여부 | E27: 주야간업무 인수인계서 | F27: SH-FM-WI015-01 | G27: 관리본 배포 | H27: 생산팀 | J27: 기존 절차 연계 | K27: SH-WI-015(작업자 표준작업 및 교대인수인계 표준) [본문 확인 ratio=0.83] | L27: 2026-12
A28: 24 | B28: 1-4 | C28: 보통 | D28: ※ 초/종품 검사는 필수, 중품은 선택사항으로 자율적 기준 수립필요, 중품검사 미진행도 가능, | E28: 야간설비일상점검표 | F28: SH-FM-WI004-06 | G28: 관리본 배포 | H28: 생산팀 | J28: 기존 절차 연계 | K28: SH-WI-004(설비 일상점검 및 이상대응 표준) [확정 2026-09-22: 기존 추정 SH-WI-001(ratio=0.17) 대비 대안 채택(ratio=0.73) — 품질경영담당 일괄판단, 부서 정식회신 생략] | L28: 2026-12 | N28: ※재판정(본문대조): 기존 근거서류 재검토 필요 — 관련문서 참고, 담당부서/품질팀 확인 후 확정
A29: 25 | B29: 1-3 | C29: 낮음 | D29: ※ 해당공정 외국인작업자 주요 표준류 교육 및 내용 숙지 시 현지어 번역게시 불필요(현장확인 필요) | E29: 작업일보 현지어 번역본 | F29: SH-FM-PRD-N01 | G29: 관리본 배포 | H29: 생산팀 | J29: 신규 작성 필요 | L29: 2026-10
A30: 26 | B30: 1-3 | C30: 낮음 | E30: 부적합처리기준 현지어번역본 | F30: SH-FM-QP014-01 | G30: 관리본 배포 | H30: 품질팀 | I30: 이광재 | J30: 기존 절차 연계 | K30: SH-QP-014(부적합품 및 재작업 관리 절차서) [확정 2026-09-22: 신규 발견 연계 채택(ratio=0.72) — 품질경영담당 일괄판단, 부서 정식회신 생략] | L30: 2026-10 | N30: ※재판정(본문대조): 기존 절차 연계 가능성 신규 발견 — 검토 후 확정 필요
A31: 27 | B31: 1-3 | C31: 낮음 | E31: 외관검사기준 현지어번역본 | F31: SH-FM-WI030-01 | G31: 관리본 배포 | H31: 품질팀 | J31: 기존 절차 연계 | K31: SH-WI-030(고객감사·인증심사 현장대응 표준) [확정 2026-09-22: 신규 발견 연계 채택(ratio=1.00) — 품질경영담당 일괄판단, 부서 정식회신 생략] | L31: 2026-10 | N31: ※재판정(본문대조): 기존 절차 연계 가능성 신규 발견 — 검토 후 확정 필요
A32: 28 | B32: 1-3 | C32: 낮음 | D32: 작업표준서, 설비일상점검 기준표, 작업일보 등 외국인 배치공정 표준류 현지어 번역 게시상태 | E32: 작업표준서 현지어번역본 | F32: SH-FM-WI004-02 | G32: 관리본 배포 | H32: 생산팀 | I32: 지성규 | J32: 기존 절차 연계 | K32: SH-WI-004(설비 일상점검 및 이상대응 표준) [본문 확인 ratio=0.43] | L32: 2026-12
A33: 29 | B33: 1-3 | C33: 낮음 | D33: : 부적합 처리절차 및 중요 품질문제 개선 사례등 품질의식 강화목적 표준류 번역 게시 (추가 관리시 우수) | E33: 설비일상점검표 현지어 번역본 | F33: SH-FM-WI004-03 | G33: 관리본 배포 | H33: 생산팀 | J33: 기존 절차 연계 | K33: SH-WI-004(설비 일상점검 및 이상대응 표준) [본문 확인 ratio=0.64] | L33: 2026-12

Sheet C2_검사시험
A1: SQ mark 심사 - 2. 검사시험 필요서류 체크리스트
A2: 고객사: 한온시스템 | 작성일: 2026-09-17(Rev.2) | 해당 구분 필요서류: 55건
A3: DISCLAIMER: "작성구분"/"관련 기존 문서"는 QMS_REV00 품질경영시스템 통합문서(SH-QP-001~025, SH-WI-001~030) 실제 본문과 대조한 재판정 결과입니다(2026-09-17, Rev.2). 녹색=본문상 근거 확인된 기존 연계, 노란색="기존 절차 연계 (제안 — 검토 필요)"로 표시된 항목(본문 근거가 약하거나 새로 발견된 연계 후보 — 관련 기존 문서 칸의 [재검토]/[신규 발견]/[참고] 문구 확인), 빨간색=신규 작성 필요. "FM문서번호(안)"/"목표완료월"은 규칙 기반 1차 추정치입니다. 실제 활용 가능 여부, 양식 신규 제정 여부, 일정은 반드시 담당부서·품질책임자 검토 후 확정하세요.
A4: NO | B4: 번호 | C4: 우선순위 | D4: 요구사항(세부 추진 항목) | E4: 필요서류(준비서류) | F4: FM문서번호(안) | G4: 현장 연계 | H4: 담당부서 | I4: 담당자 | J4: 작성구분(자동추정) | K4: 관련 기존 문서(참고) | L4: 목표완료월(제안) | M4: 준비상태 | N4: 비고
A5: 1 | B5: 2-1 | C5: 높음 | D5: 외주품 입고 시 외주사 출하성적서 접수 및 수입검사 실측값 비교검증 여부 | E5: 원자재수입검사 일지 | F5: SH-FM-QP013-10 | H5: 구매자재팀 | J5: 기존 절차 연계 | K5: SH-QP-013(검사 및 시험관리 절차서) [확정 2026-09-22: 신규 발견 연계 채택(ratio=0.91) — 품질경영담당 일괄판단, 부서 정식회신 생략] | L5: 2026-09 | N5: ※재판정(본문대조): 기존 절차 연계 가능성 신규 발견 — 검토 후 확정 필요
A6: 2 | B6: 2-1 | C6: 높음 | D6: 원재료 M/SHEET 접수 시 물성 및 화학조성비 합/부 판단기준 명확화 수립 | E6: 원자재 M/SHEET (입고LOT별 접수) | F6: SH-FM-WI029-02 | H6: 구매자재팀 | J6: 기존 절차 연계 | K6: SH-WI-029(공급자 변경품 및 초도품 확인표준) [확정 2026-09-22: 신규 발견 연계 채택(ratio=0.64) — 품질경영담당 일괄판단, 부서 정식회신 생략] | L6: 2026-09 | N6: ※재판정(본문대조): 기존 절차 연계 가능성 신규 발견 — 검토 후 확정 필요
A7: 3 | B7: 2-1 | C7: 높음 | D7: (원소재) 도금처리된 원소재 판넬 : 도금 부착력 검사 (180˚밴딩후 크랙, 박리여부), 도금두께(3point), | E7: 원자재식별표 | F7: SH-FM-INS-N03 | G7: 관리본 배포 | H7: 구매자재팀 | J7: 신규 작성 필요 | L7: 2026-09
A8: 4 | B8: 2-7 | C8: 높음 | D8: 용접제품 표면관리기준 설정 (스패터, Chip, 버어, 이물질 ) 및 점검 이력 관리 | E8: 용접스패터관리 점검체크시트 | F8: SH-FM-INS-N12 | G8: 관리본 배포 | H8: 품질팀 | I8: 이광재 | J8: 신규 작성 필요 | L8: 2026-09
A9: 5 | B9: 2-8 | C9: 높음 | E9: 완성품검사체크시트 | F9: SH-FM-INS-N13 | G9: 관리본 배포 | H9: 품질팀 | I9: 김명용 | J9: 신규 작성 필요 | L9: 2026-09
A10: 6 | B10: 2-8 | C10: 높음 | E10: 완성품검사식별표 | F10: SH-FM-INS-N14 | G10: 관리본 배포 | H10: 품질팀 | I10: 김명용 | J10: 신규 작성 필요 | L10: 2026-09
A11: 7 | B11: 2-8 | C11: 높음 | E11: 완성품보관장소선정 | F11: SH-FM-WI006-10 | G11: 관리본 배포 | H11: 품질팀 | I11: 김명용 | J11: 기존 절차 연계 | K11: SH-WI-006(계측기 사용 및 일상점검 표준) [확정 2026-09-22: 신규 발견 연계 채택(ratio=1.00) — 품질경영담당 일괄판단, 부서 정식회신 생략] | L11: 2026-09 | N11: ※재판정(본문대조): 기존 절차 연계 가능성 신규 발견 — 검토 후 확정 필요
A12: 8 | B12: 2-8 | C12: 높음 | E12: 완성검사관리대제작 | F12: SH-FM-QP012-01 | G12: 관리본 배포 | H12: 품질팀 | I12: 김명용 | J12: 기존 절차 연계 | K12: SH-QP-012(생산 및 공정관리 절차서) [확정 2026-09-22: 신규 발견 연계 채택(ratio=0.63) — 품질경영담당 일괄판단, 부서 정식회신 생략] | L12: 2026-09 | N12: ※재판정(본문대조): 기존 절차 연계 가능성 신규 발견 — 검토 후 확정 필요
A13: 9 | B13: 2-9 | C13: 높음 | D13: 아크 용접 : 용접비드, 위치 (길이, 폭, 이동량) 및 용입량 - CO2용접: 절단검사(정기검사). (용접 구간별 길이,비드 폭 형상 한도견본 비교검사) * 용입량 검사 : 용접로봇별, 용접JIG별 검사 (검사 주기 : 1회/년, 단, 4M 변경 시 용입량 검사 진행할 것(용접조건 변경, 설비변경, 지그 수정/변경, 로봇 티칭 이후 외) ※ 검사 시료 및 주기는 고객과 협의된 검사협정/기준서 따를것 ▷ 저항 용접 : 분리력 - 스폿용접: 반파괴, 전파괴 분리시험 / 드라이브 체크 ▷ (초,종품 실시) 인장강도 만족할것(실물 및 시편) / 볼트너트: 망치 타격시험 - 프로젝션용접: 볼트 너트 ▷ 회전 토르크 검사 (초, 종 검사) 예) 용접비드 이탈 및 분리력 검사 → 검사결과 사진, 스캔저장 → 검사이력 D/B 관리(엑셀등) | E13: 용입검사 계획대실적 | F13: SH-FM-INS-N18 | H13: 품질팀 | I13: 이광재 | J13: 신규 작성 필요 | L13: 2026-09
A14: 10 | B14: 2-9 | C14: 높음 | E14: 용접로보트별 용접POINT 관리표준 | F14: SH-FM-INS-N19 | H14: 생산팀 | I14: 한상돈 | J14: 신규 작성 필요 | L14: 2026-09
A15: 11 | B15: 2-9 | C15: 높음 | E15: 용접로보트별 용접POINT 관리표준 | F15: SH-FM-INS-N20 | H15: 품질팀 | I15: 이광재 | J15: 신규 작성 필요 | L15: 2026-09
A16: 12 | B16: 2-9 | C16: 높음 | E16: 용접반파괴/파괴검사기준 | F16: SH-FM-INS-N21 | H16: 생산팀 | I16: 한상돈 | J16: 신규 작성 필요 | L16: 2026-09
A17: 13 | B17: 2-9 | C17: 높음 | E17: 용접검사체크시트 | F17: SH-FM-INS-N22 | H17: 생산팀 | I17: 한상돈 | J17: 신규 작성 필요 | L17: 2026-09
A18: 14 | B18: 2-9 | C18: 높음 | E18: 용접반파괴 검사대제작 | F18: SH-FM-INS-N23 | H18: 생산팀 | I18: 한상돈 | J18: 신규 작성 필요 | L18: 2026-09
A19: 15 | B19: 2-9 | C19: 높음 | E19: (용접반파괴테스트 보관대제작-한도견본&현품) | F19: SH-FM-WI001-03 | H19: 생산팀 | I19: 한상돈 | J19: 기존 절차 연계 | K19: SH-WI-001(생산 작업준비 및 초품확인 표준) [확정 2026-09-22: 신규 발견 연계 채택(ratio=1.00) — 품질경영담당 일괄판단, 부서 정식회신 생략] | L19: 2026-09 | N19: ※재판정(본문대조): 기존 절차 연계 가능성 신규 발견 — 검토 후 확정 필요
A20: 16 | B20: 2-1 | C20: 높음 | D20: 검사협정서/기준서 체결상태 | E20: 원자재 검사협정서 OR 검사기준서 | F20: SH-FM-QP013-01 | H20: 구매자재팀 | I20: 이은주 박철호 | J20: 기존 절차 연계 | K20: SH-QP-013(검사 및 시험관리 절차서) [본문 확인 ratio=0.46] | L20: 2026-10
A21: 17 | B21: 2-1 | C21: 높음 | D21: (사급품은 1차 협력사가 체결한 검사협정서 사본 접수 및 동일 시료/주기로 검사 실시 필요) | E21: 원자재 입고 LIST | F21: SH-FM-WI009-01 | H21: 구매자재팀 | J21: 기존 절차 연계 | K21: SH-WI-009(자재 입고·보관·불출 관리 표준) [본문 확인 ratio=0.42] | L21: 2026-10
A22: 18 | B22: 2-8 | C22: 높음 | E22: (QMS SYSTEM 운영시 컴퓨터설치운영) | F22: SH-FM-INS-N17 | H22: (부서 미정) | J22: 신규 작성 필요 | L22: 2026-10
A23: 19 | B23: 2-1 | C23: 높음 | D23: → 검사협정 체결이 어려울 시 검사기준서 수립으로 대체 (예: 대기업 공급 원재료,도금업종 등) | E23: 원자재수입검사 기준서 | F23: SH-FM-QP013-02 | G23: 관리본 배포 | H23: 구매자재팀 | J23: 기존 절차 연계 | K23: SH-QP-013(검사 및 시험관리 절차서) [본문 확인 ratio=0.68] | L23: 2026-11
A24: 20 | B24: 2-1 | C24: 높음 | D24: 입고 LOT와 출하검사 성적서내 LOT 일치성 확보여부(원소재의 경우 M/SHEET내 검사시료 LOT 일치성) | E24: 원자재 규격별 물성및 화학조성비 기준서 | F24: SH-FM-WI027-01 | G24: 관리본 배포 | H24: 구매자재팀 | J24: 기존 절차 연계 | K24: SH-WI-027(검사성적서 및 품질기록 작성 표준) [참고: 본문상 명확한 근거 약함(ratio=0.22), 담당부서 확인 권장] | L24: 2026-11 | N24: ※재판정(본문대조): 본문상 명확한 근거 약함 — 담당부서 확인 권장(기존 분류 유지)
A25: 21 | B25: 2-1 | C25: 높음 | D25: 검사협정서/기준서에 준한 일상검사/정기검사 실시상태 | E25: 원자재 중금속검사 성적서 | F25: SH-FM-WI027-02 | H25: 구매자재팀 | J25: 기존 절차 연계 | K25: SH-WI-027(검사성적서 및 품질기록 작성표준) [본문 확인 ratio=0.80] | L25: 2026-11
A26: 22 | B26: 2-7 | C26: 높음 | D26: 초/종품 외관, 치수 및 장착상태 (용접지그 수정/변경시 치수 및 용접물간 갭 최대 1mm 이하관리 - 샘플실측) | E26: 자주검사기준서 | F26: SH-FM-QP013-07 | G26: 관리본 배포 | H26: 품질팀 | I26: 이광재 | J26: 기존 절차 연계 | K26: SH-QP-013(검사 및 시험관리 절차서); SH-WI-002(공정검사 및 특수특성 관리 표준) [참고: 본문상 명확한 근거 약함(ratio=0.32), 담당부서 확인 권장] | L26: 2026-11 | N26: ※재판정(본문대조): 본문상 명확한 근거 약함 — 담당부서 확인 권장(기존 분류 유지)
A27: 23 | B27: 2-7 | C27: 높음 | D27: 예) 카울크로스바 파이프-SUB 용접물 간 갭 | E27: 자주검사체크시트 | F27: SH-FM-WI002-02 | G27: 관리본 배포 | H27: 품질팀 | I27: 이광재 | J27: 기존 절차 연계 | K27: SH-WI-002(공정검사 및 특수특성 관리 표준) [참고: 본문상 명확한 근거 약함(ratio=0.00), 담당부서 확인 권장] | L27: 2026-11 | N27: ※재판정(본문대조): 본문상 명확한 근거 약함 — 담당부서 확인 권장(기존 분류 유지)
A28: 24 | B28: 2-7 | C28: 높음 | D28: 자주검사 기록, 불량품 시정조치 내역 및 이력관리 상태 | E28: 용접spatter 관리기준 | F28: SH-FM-QP016-01 | G28: 관리본 배포 | H28: 품질팀 | I28: 이광재 | J28: 기존 절차 연계 | K28: SH-QP-016(시정조치 및 문제해결 절차서); SH-WI-002(공정검사 및 특수특성 관리 표준) [참고: 본문상 명확한 근거 약함(ratio=0.09), 담당부서 확인 권장] | L28: 2026-11 | N28: ※재판정(본문대조): 본문상 명확한 근거 약함 — 담당부서 확인 권장(기존 분류 유지)
A29: 25 | B29: 2-7 | C29: 높음 | D29: QC순회검사: 작업자 자주검사 실시상태 확인 및 주요 포인트 추가 검사 후 확인 서명 | E29: 자주검사체크시트 | F29: SH-FM-WI002-03 | H29: 품질팀 | I29: 이광재 | J29: 기존 절차 연계 | K29: SH-WI-002(공정검사 및 특수특성 관리 표준) [참고: 본문상 명확한 근거 약함(ratio=0.13), 담당부서 확인 권장] | L29: 2026-11 | N29: ※재판정(본문대조): 본문상 명확한 근거 약함 — 담당부서 확인 권장(기존 분류 유지)
A30: 26 | B30: 2-7 | C30: 높음 | D30: → 용접관련 기술표준 (MS181 ▷ 13 (용융용접) / MS 181 ▷ 06 (SEAM용접) / | E30: 품질순회검사체크시트(중요항목치수추가) | F30: SH-FM-WI002-04 | H30: 품질팀 | I30: 이광재 | J30: 기존 절차 연계 | K30: SH-WI-002(공정검사 및 특수특성 관리 표준) [참고: 본문상 명확한 근거 약함(ratio=0.04), 담당부서 확인 권장] | L30: 2026-11 | N30: ※재판정(본문대조): 본문상 명확한 근거 약함 — 담당부서 확인 권장(기존 분류 유지)
A31: 27 | B31: 2-7 | C31: 높음 | D31: MS181 ▷ 15 (점용접) 참조 | E31: 자주검사대 설치(초중종현품보관) | F31: SH-FM-WI002-05 | H31: 생산팀 | I31: 지성규 | J31: 기존 절차 연계 | K31: SH-WI-002(공정검사 및 특수특성 관리 표준) [참고: 본문상 명확한 근거 약함(ratio=0.00), 담당부서 확인 권장] | L31: 2026-11 | N31: ※재판정(본문대조): 본문상 명확한 근거 약함 — 담당부서 확인 권장(기존 분류 유지)
A32: 28 | B32: 2-8 | C32: 높음 | D32: 외관, 치수, 취약부 절단면 검사, 상대 물 조립 성 검증 등 (샘플 실측 요망) | E32: 완성품검사기준서 | F32: SH-FM-QP013-08 | G32: 관리본 배포 | H32: 품질팀 | I32: 김명용 | J32: 기존 절차 연계 | K32: SH-QP-013(검사 및 시험관리 절차서) [본문 확인 ratio=0.36] | L32: 2026-11
A33: 29 | B33: 2-2 | C33: 보통 | D33: 수입검사 실시 전 외주품/원재료 입고처리 안되도록 업무 프로세스 수립 | E33: 외주품입고식별표 | F33: SH-FM-INS-N04 | G33: 관리본 배포 | H33: 구매자재팀 | I33: 이은주 | J33: 신규 작성 필요 | L33: 2026-09
A34: 30 | B34: 2-2 | C34: 보통 | E34: 외주품 부적합처리기준서 | F34: SH-FM-INS-N05 | G34: 관리본 배포 | H34: 품질팀 | I34: 김명용 | J34: 신규 작성 필요 | L34: 2026-09
A35: 31 | B35: 2-2 | C35: 보통 | E35: 외주품 검사협정서 | F35: SH-FM-INS-N06 | H35: 품질팀 | I35: 이광재 | J35: 신규 작성 필요 | L35: 2026-09
A36: 32 | B36: 2-3 | C36: 보통 | D36: 외주품/완제품 외관 합/부 판별용 한도견본 운영 | E36: 한도견본 관리대장(외주품/완성품) | F36: SH-FM-INS-N07 | H36: 품질팀 | I36: 김명용 | J36: 신규 작성 필요 | L36: 2026-09
A37: 33 | B37: 2-4 | C37: 보통 | D37: 정기 시험 성적서 신뢰도 확보 | E37: 정기검사계획대실적(치수/용접) | F37: SH-FM-INS-N09 | H37: 품질팀 | I37: 이광재 | J37: 신규 작성 필요 | L37: 2026-09
A38: 34 | B38: 2-4 | C38: 보통 | D38: 환경규제(중금속) 정기시험 실시상태 : 검사협정 체결기준 시험결과 증빙관리 상태 | E38: 중금속 정기검사 계획대실적 | F38: SH-FM-INS-N10 | H38: 구매자재팀 | I38: 이은주 | J38: 신규 작성 필요 | L38: 2026-09
A39: 35 | B39: 2-4 | C39: 보통 | D39: (시험장비 보유시 자체 성적서 인정, 미보유시 1차사 또는 공인기관 의뢰 가능) | E39: 중금속 성적서 | F39: SH-FM-INS-N11 | H39: 구매자재팀 | I39: 이은주 | J39: 신규 작성 필요 | L39: 2026-09
A40: 36 | B40: 2-3 | C40: 보통 | D40: 검사기 신뢰도 확인을 위한 양/불 마스터 설정기준 및 관리상태 | E40: 한도견본 샘플보관대 및 샘플 | F40: SH-FM-INS-N08 | G40: 관리본 배포 | H40: 생산팀 | I40: 지성규 | J40: 신규 작성 필요 | L40: 2026-10
...

Sheet C3_설비관리
A1: SQ mark 심사 - 3. 설비관리 필요서류 체크리스트
A2: 고객사: 한온시스템 | 작성일: 2026-09-17(Rev.2) | 해당 구분 필요서류: 28건
A3: DISCLAIMER: "작성구분"/"관련 기존 문서"는 QMS_REV00 품질경영시스템 통합문서(SH-QP-001~025, SH-WI-001~030) 실제 본문과 대조한 재판정 결과입니다(2026-09-17, Rev.2). 녹색=본문상 근거 확인된 기존 연계, 노란색="기존 절차 연계 (제안 — 검토 필요)"로 표시된 항목(본문 근거가 약하거나 새로 발견된 연계 후보 — 관련 기존 문서 칸의 [재검토]/[신규 발견]/[참고] 문구 확인), 빨간색=신규 작성 필요. "FM문서번호(안)"/"목표완료월"은 규칙 기반 1차 추정치입니다. 실제 활용 가능 여부, 양식 신규 제정 여부, 일정은 반드시 담당부서·품질책임자 검토 후 확정하세요.
A4: NO | B4: 번호 | C4: 우선순위 | D4: 요구사항(세부 추진 항목) | E4: 필요서류(준비서류) | F4: FM문서번호(안) | G4: 현장 연계 | H4: 담당부서 | I4: 담당자 | J4: 작성구분(자동추정) | K4: 관련 기존 문서(참고) | L4: 목표완료월(제안) | M4: 준비상태 | N4: 비고
A5: 1 | B5: 3-1 | C5: 보통 | D5: 설비 셋팅값 임의조작 방지를 위한 시건장치/KEY-LOCK 반영상태 | E5: 설비 오셋팅방지 KEY-LOCK | F5: SH-FM-EQP-N01 | H5: 생산팀 | I5: 한상돈 | J5: 신규 작성 필요 | L5: 2026-09
A6: 2 | B6: 3-3 | C6: 보통 | D6: '- 유압설비: 유압. 유량. 소음. 누유 등 이상유무 확인 | E6: 스폿로봇 원점확인장치 | F6: SH-FM-EQP-N11 | H6: 생산팀 | I6: 김운주 | J6: 신규 작성 필요 | L6: 2026-09
A7: 3 | B7: 3-3 | C7: 보통 | D7: 유틸리티: 에어압력. 냉각수(온도: 10∼30℃). 압력: 가스 유량 | E7: 용접전극드레싱/교환 F/P장비설치 | F7: SH-FM-EQP-N12 | H7: 생산팀 | I7: 김운주 | J7: 신규 작성 필요 | L7: 2026-09
A8: 4 | B8: 3-5 | C8: 보통 | D8: 기준준수 및 이행상태 | E8: 스폿로봇 원점확인장치 | F8: SH-FM-EQP-N17 | H8: 생산팀 | I8: 황지환 | J8: 신규 작성 필요 | L8: 2026-09
A9: 5 | B9: 3-2 | C9: 보통 | D9: 주요 핵심설비 정기점검 계획수립 및 점검상태(외주업체 정도점검 성적서 포함, 최소 1회/년) | E9: 설비정기점검 계획대실적표 | F9: SH-FM-EQP-N02 | H9: 생산기술 | I9: 황지환 | J9: 신규 작성 필요 | L9: 2026-10 | N9: 0
A10: 6 | B10: 3-2 | C10: 보통 | D10: (외주업체 또는 자체 정도점검 가능 설비/인력이 확보된경우 인정) | E10: 설비정기점검 실적 | F10: SH-FM-EQP-N03 | H10: 생산기술 | I10: 황지환 | J10: 신규 작성 필요 | L10: 2026-10
A11: 7 | B11: 3-2 | C11: 보통 | D11: 설비내 소모성 부자재류 점검/교체주기 설정 및 준수여부 | E11: 설비관리대장 | F11: SH-FM-EQP-N04 | H11: 생산기술 | I11: 황지환 | J11: 신규 작성 필요 | L11: 2026-10
A12: 8 | B12: 3-2 | C12: 보통 | D12: [필요시 소모성 부자재 교체주기 설정근거 제시 필요, T/O 이력 등] | E12: 설비이력카드 | F12: SH-FM-EQP-N05 | G12: 설비고장수리반영 | H12: 생산기술 | I12: 황지환 | J12: 신규 작성 필요 | L12: 2026-10
A13: 9 | B13: 3-2 | C13: 보통 | D13: 1) 설비내 주요 압력계 정기점검 정도보증 또른 검교정된 마스터게이지 비교 검증활동 실시 | E13: 설비압력게이지 검증 계획대실적표 | F13: SH-FM-QP015-01 | H13: 생산기술 | I13: 황지환 | J13: 기존 절차 연계 | K13: SH-QP-015(변경관리 절차서) [확정 2026-09-22: 신규 발견 연계 채택(ratio=0.67) — 품질경영담당 일괄판단, 부서 정식회신 생략] | L13: 2026-10 | N13: ※재판정(본문대조): 기존 절차 연계 가능성 신규 발견 — 검토 후 확정 필요
A14: 10 | B14: 3-3 | C14: 보통 | D14: 용접기: 팁 교환. 노즐청소. 와이어 공급기. 케이블. 전류 전압. 전극 드레싱 및 교환 | E14: CO2용접원점확인장치 | F14: SH-FM-EQP-N10 | H14: (부서 미정) | I14: 김운주 | J14: 신규 작성 필요 | L14: 2026-10
A15: 11 | B15: 3-6 | C15: 보통 | D15: JIG 기준 핀 외경치수 측정 (관리범위 이탈방지) - 주기 : 1회/분기 이상 ※ 자체 측정주기 설정시 설정근거 마련 안전율 80% - 지그 기준면 마모/유격 및 토치 로보트 원점 검사 관리기준 수립 및 준수 상태 - 클렘프 고정상태. 센서 류 고정 작동상태.배선정리 피복점검 | E15: JIG정기점검 관리기준서 | F15: SH-FM-EQP-N19 | H15: 생산팀 | I15: 지성규 | J15: 신규 작성 필요 | L15: 2026-10
A16: 12 | B16: 3-6 | C16: 보통 | E16: JIG정기점검계획대실적표 | F16: SH-FM-EQP-N20 | H16: 생산팀 | I16: 지성규 | J16: 신규 작성 필요 | L16: 2026-10
A17: 13 | B17: 3-6 | C17: 보통 | E17: JIG 기준핀정기점검 실적 | F17: SH-FM-EQP-N21 | H17: 생산팀 | I17: 지성규 | J17: 신규 작성 필요 | L17: 2026-10
A18: 14 | B18: 3-6 | C18: 보통 | E18: JIG PIN 위치도 및 상세사진 위치도 | F18: SH-FM-EQP-N22 | H18: 생산팀 | I18: 지성규 | J18: 신규 작성 필요 | L18: 2026-10
A19: 15 | B19: 3-1 | C19: 보통 | D19: 설비별 설비일상 점검부위 및 점검방법 도식화 관리상태 | E19: 설비일상점검기준서 | F19: SH-FM-WI004-04 | H19: 생산팀 | I19: 한상돈 | J19: 기존 절차 연계 | K19: SH-WI-004(설비 일상점검 및 이상대응 표준) [본문 확인 ratio=0.62] | L19: 2026-11
A20: 16 | B20: 3-1 | C20: 보통 | D20: 설비내 부착 게이지류 상/하한 식별 및 측정 실측값 일상점검표 기록관리 | E20: 설비일상점검표(각부위별사진도식화) | F20: SH-FM-WI004-07 | G20: 게이지값기록 | H20: 생산팀 | I20: 한상돈 | J20: 기존 절차 연계 | K20: SH-WI-004(설비 일상점검 및 이상대응 표준) [확정 2026-09-22: 기존 추정 SH-QP-003(ratio=0.04) 대비 대안 채택(ratio=0.68) — 품질경영담당 일괄판단, 부서 정식회신 생략] | L20: 2026-11 | N20: ※재판정(본문대조): 기존 근거서류 재검토 필요 — 관련문서 참고, 담당부서/품질팀 확인 후 확정
A21: 17 | B21: 3-2 | C21: 보통 | D21: 설비 작동유는 사용시간을 고려한 교체주기설정 예)설비오일 2,000Hr시 전량교체 (필터포함)(※정밀프레스추가) | E21: 설비예비품 입출고 관리일지 | F21: SH-FM-EQP-N07 | H21: 생산기술 | I21: 황지환 | J21: 신규 작성 필요 | L21: 2026-11
A22: 18 | B22: 3-2 | C22: 보통 | D22: 프레스설비 1회/년 설비제조협력사에 정기정도 점검 진행 | E22: 작동유관리기준서 | F22: SH-FM-EQP-N08 | H22: 생산기술 | I22: 황지환 | J22: 신규 작성 필요 | L22: 2026-11
A23: 19 | B23: 3-2 | C23: 보통 | D23: (일상검사시 Air 압력 검사: 바란스, 클러치, 브레이크 AIR) (※정밀프레스 추가) | E23: 작동유샘플보관대제작설치 | F23: SH-FM-EQP-N09 | H23: 생산기술 | I23: 황지환 | J23: 신규 작성 필요 | L23: 2026-11
A24: 20 | B24: 3-4 | C24: 보통 | D24: CO2용접기: 전류.전압 검 교정.케이블 조임상태. 메인 전원 입력 변동 차. 와이어 공급상태 - 스폿 용접기: 전류. 통전시간 오차확인. 가압력 확인. 전극.전원연결 조임 상태.냉각수 온도 압력, 부품누락. - 로봇: 쇼크센서 작동상태, 콘트롤러 배터리 전압, 콘트롤러 냉각핀 작동상태, 케이블 연결상태 | E24: 설비정기점검 관리기준서 | F24: SH-FM-EQP-N13 | H24: 생산기술 | I24: 황지환 | J24: 신규 작성 필요 | L24: 2026-11
A25: 21 | B25: 3-4 | C25: 보통 | E25: 설비정기점검계획대실적표 | F25: SH-FM-EQP-N14 | H25: 생산기술 | I25: 황지환 | J25: 신규 작성 필요 | L25: 2026-11
A26: 22 | B26: 3-5 | C26: 보통 | D26: 전극, 가스, 냉각수 관리 F/PROOF 구축시 관리기준 및 준수상태, F/PROOF 미구축시 관리기준 수립여부, | E26: CO2용접원점확인장치 | F26: SH-FM-EQP-N16 | H26: (부서 미정) | I26: 황지환 | J26: 신규 작성 필요 | L26: 2026-11
A27: 23 | B27: 3-5 | C27: 보통 | D27: (드레싱 및 교체 주기 관리, 용접타점 관리, 타점 도달시 경보장치) | E27: 가스잔량 F/P장치 | F27: SH-FM-EQP-N18 | H27: (부서 미정) | I27: 황지환 | J27: 신규 작성 필요 | L27: 2026-11
A28: 24 | B28: 3-1 | C28: 보통 | D28: 설비내 F/P설비 경고등/알람 정상작동 및 설비내 셋팅값/관리공차 표준과 일치여부 | E28: 설비게이지 상하한식별관리 | F28: SH-FM-QP018-02 | H28: 생산기술 | I28: 한상돈 | J28: 기존 절차 연계 | K28: SH-QP-018(식별 및 추적성 관리 절차서) [참고: 본문상 명확한 근거 약함(ratio=0.00), 담당부서 확인 권장] | L28: 2026-12 | N28: ※재판정(본문대조): 본문상 명확한 근거 약함 — 담당부서 확인 권장(기존 분류 유지)
A29: 25 | B29: 3-2 | C29: 보통 | D29: 설비 부착 센서 및 게이지류에 대한 정도 보증 방안 수립 및 이행 상태 | E29: 설비수리보고서 | F29: SH-FM-WI015-02 | H29: 생산기술 | I29: 황지환 | J29: 기존 절차 연계 | K29: SH-WI-015(작업자 표준작업 및 교대인수인계 표준) [확정 2026-09-22: 기존 추정 SH-WI-018(ratio=0.00) 대비 대안 채택(ratio=0.55) — 품질경영담당 일괄판단, 부서 정식회신 생략] | L29: 2026-12 | N29: ※재판정(본문대조): 기존 근거서류 재검토 필요 — 관련문서 참고, 담당부서/품질팀 확인 후 확정
A30: 26 | B30: 3-2 | C30: 보통 | D30: 2) 금형내 노즐온도 센서 등 중요 센서류 고장여부 정기점검시 정도보증 활동 필요 | E30: 설비압력게이지 점검실적 | F30: SH-FM-WI008-01 | G30: B/C,C/B,O/R | H30: 생산기술 | I30: 황지환 | J30: 기존 절차 연계 | K30: SH-WI-008(금형·치공구 교환 및 관리 표준) [참고: 본문상 명확한 근거 약함(ratio=0.00), 담당부서 확인 권장] | L30: 2026-12 | N30: ※재판정(본문대조): 본문상 명확한 근거 약함 — 담당부서 확인 권장(기존 분류 유지)
A31: 27 | B31: 3-2 | C31: 보통 | D31: ※ 설비 일상점검 항목을 제외한 세부 점검 필요부만 정기점검 계획 수립 및 점검 필요 | E31: 설비예비품관리대장 | F31: SH-FM-WI004-05 | H31: 생산기술 | I31: 황지환 | J31: 기존 절차 연계 | K31: SH-WI-004(설비 일상점검 및 이상대응 표준) [참고: 본문상 명확한 근거 약함(ratio=0.25), 담당부서 확인 권장] | L31: 2026-12 | N31: ※재판정(본문대조): 본문상 명확한 근거 약함 — 담당부서 확인 권장(기존 분류 유지)
A32: 28 | B32: 3-4 | C32: 보통 | E32: 설비정기점검 실적 | F32: SH-FM-EQP-N15 | H32: 생산기술 | I32: 황지환 | J32: 신규 작성 필요 | L32: 2026-12

Sheet C4_금형관리
A1: SQ mark 심사 - 4. 금형관리 필요서류 체크리스트
A2: 고객사: 한온시스템 | 작성일: 2026-09-17(Rev.2) | 해당 구분 필요서류: 19건
A3: DISCLAIMER: "작성구분"/"관련 기존 문서"는 QMS_REV00 품질경영시스템 통합문서(SH-QP-001~025, SH-WI-001~030) 실제 본문과 대조한 재판정 결과입니다(2026-09-17, Rev.2). 녹색=본문상 근거 확인된 기존 연계, 노란색="기존 절차 연계 (제안 — 검토 필요)"로 표시된 항목(본문 근거가 약하거나 새로 발견된 연계 후보 — 관련 기존 문서 칸의 [재검토]/[신규 발견]/[참고] 문구 확인), 빨간색=신규 작성 필요. "FM문서번호(안)"/"목표완료월"은 규칙 기반 1차 추정치입니다. 실제 활용 가능 여부, 양식 신규 제정 여부, 일정은 반드시 담당부서·품질책임자 검토 후 확정하세요.
