Workbook

Sheet 00_작성안내
A1: 현장양식목록 및 작성계획
A2: (주)신화에이치앤티 | SH-FM-122 | Rev.00 | 문서상태: 승인완료 | 제정일: 2026-09-29
A4: 관리 목적
A5: 현장 양식의 문서번호·담당자·작성주기·보관기준을 관리합니다.
A6: 시트 안내
A7: 01 양식목록 / 02 작성계획 / 03 번호대조 / 04 문서관리·파일연결
A8: 작성 방법
A9: 실제 담당자·운영시작일·기록별 보존기간을 입력하고 확인상태를 갱신합니다.
A10: 운영 기준
A11: 연계 QM·QP·WI는 Rev.03 기준입니다. 개별 FM은 확인된 자체 개정번호로 관리합니다.
A12: 문서 보관
A13: 품질부서 QMS 문서관리 폴더에 보관합니다. 유효기간 중 보관하며 폐지·대체 후 5년, 고객·법규의 장기 보존 요구를 우선 적용합니다.
... A17: 문서번호·양식명·개정 또는 담당·주기가 바뀌면 목록과 관련 양식을 함께 갱신합니다.
A19: 총 기록 항목 | B19: =COUNTA('01_현장양식목록'!C7:C50) | C19: 신규 번호 배정 | D19: =COUNTIF('01_현장양식목록'!F7:F50,"신규 번호 배정") | E19: 운영 시작 | F19: =COUNTIF('02_작성계획'!J7:J50,"운영 시작")
A21: 문서 결재
A22: 작성 | C22: 검토 | E22: 승인
A23: 문서관리 담당자 | C23: 품질책임자 | E23: 사내 승인권자
A24: 성명: __________________ | C24: 성명: 김흥수 | E24: 성명: __________________
A25: 서명: __________________ | C25: 서명: __________________ | E25: 서명: __________________
A26: 일자: __________________ | C26: 일자: __________________ | E26: 일자: __________________

Sheet 01_현장양식목록
A1: 현장 사용 양식 목록
A2: 현장 사용 양식의 문서번호·명칭·개정 관리
A4: (주)신화에이치앤티 | SH-FM-122 Rev.00 | 품질책임자 김흥수
A6: NO | B6: 양식번호 | C6: 양식명·기록명 | D6: 연계 QP | E6: 연계 WI | F6: 번호 확인상태 | G6: 적용 개정계획 | H6: 작성 시 남길 내용 | I6: 근거 위치
A7: 1 | B7: SH-FM-033 | C7: 생산조건 및 초품확인표 | D7: SH-QP-012/013/015 | E7: SH-WI-001 | F7: Rev.03 번호·명칭 대조 | G7: Rev.00 적용 예정 | H7: 품번·설비·LOT·조건·측정값·판정 | I7: Rev.03 관련기록 및 FM Master 06_Rev03_대조결과
A8: 2 | B8: SH-FM-034 | C8: 공정검사 기록표 | D8: SH-QP-012/013/023 | E8: SH-WI-002 | F8: Rev.03 번호·명칭 대조 | G8: Rev.00 적용 예정 | H8: 실측값·특수특성·판정·이상조치 | I8: Rev.03 관련기록 및 FM Master 06_Rev03_대조결과
A9: 3 | B9: SH-FM-071 | C9: 부적합품 관련 관리기록 | D9: SH-QP-014/016 | E9: SH-WI-003/014/018/025 | F9: 통합문서 명시 | G9: Rev.00 적용 예정 | H9: 의심 LOT·수량·격리·처리·재검사 | I9: SH-QP-014 및 SH-WI-003
A10: 4 | B10: SH-FM-101 | C10: 설비 일상점검 및 고장이력 | D10: SH-QP-007/012/020 | E10: SH-WI-004/016 | F10: 신규 번호 배정 | G10: Rev.00 | H10: 설비번호·점검결과·조치·복구확인 | I10: SH-WI-004/016 연계표 / 이번 작성계획 신규 배정
A11: 5 | B11: SH-FM-102 | C11: 생산·검사·출하 LOT 이력 | D11: SH-QP-018/019/013 | E11: SH-WI-005 | F11: 신규 번호 배정 | G11: Rev.00 | H11: 원자재→공정→완제품→출하 연결 | I11: SH-QP-018 및 SH-WI-005 / 이번 작성계획 신규 배정
A12: 6 | B12: SH-FM-059 | C12: 구매품추적관리대장 | D12: SH-QP-018 | E12: SH-WI-005/009/024 | F12: Rev.03 번호·명칭 대조 | G12: Rev.00 적용 예정 | H12: 공급자·입고 LOT·불출·사용 LOT | I12: Rev.03 관련기록 및 FM Master 06_Rev03_대조결과
A13: 7 | B13: SH-FM-023 | C13: 계측기대장 및 교정기록 | D13: SH-QP-008/013 | E13: SH-WI-006 | F13: 기존 번호 연결 | G13: Rev.00 | H13: 계측기번호·유효기간·교정결과 | I13: SH-WI-006 연계표 / FM Master: 계측기관리대장
A14: 8 | B14: SH-FM-024 | C14: MSA 및 Gauge R&R 기록 | D14: SH-QP-008/023 | E14: SH-WI-007 | F14: 기존 번호 연결 | G14: Rev.00 | H14: 측정시스템·평가결과·개선조치 | I14: SH-WI-007 연계표 / FM Master: MSA관리
A15: 9 | B15: SH-FM-103 | C15: 금형·치공구 관리이력 | D15: SH-QP-007/012/015 | E15: SH-WI-008 | F15: 신규 번호 배정 | G15: Rev.00 | H15: 식별번호·수명·교환·초품확인 | I15: SH-WI-008 연계표 / 이번 작성계획 신규 배정
A16: 10 | B16: SH-FM-104 | C16: 자재 입고·보관·불출 기록 | D16: SH-QP-011/013/018/019 | E16: SH-WI-009 | F16: 신규 번호 배정 | G16: Rev.00 | H16: 입출고·LOT·수량·선입선출 | I16: SH-WI-009 연계표 / 이번 작성계획 신규 배정
A17: 11 | B17: SH-FM-105 | C17: 포장·라벨 및 출하검증 기록 | D17: SH-QP-019/013/018/025 | E17: SH-WI-010 | F17: 신규 번호 배정 | G17: Rev.00 | H17: 품번·라벨·수량·포장·출하승인 | I17: SH-WI-010 연계표 / 이번 작성계획 신규 배정
A18: 12 | B18: SH-FM-106 | C18: 공정조건 설정 및 확인기록 | D18: SH-QP-012/015/023 | E18: SH-WI-011 | F18: 신규 번호 배정 | G18: Rev.00 | H18: 승인조건·실제조건·변경승인 | I18: SH-WI-011 본문 / 이번 작성계획 신규 배정
... A50: 44 | B50: SH-FM-094 | C50: 지속적개선 과제관리표 | D50: SH-QP-024 | E50: 해당 없음 | F50: Rev.03 번호·명칭 대조 | G50: Rev.00 적용 예정 | H50: 과제·담당·기한·효과·유지확인 | I50: Rev.03 관련기록 및 FM Master 06_Rev03_대조결과

Sheet 02_작성계획
A1: 현장 양식 작성계획
A2: 담당자·작성주기·보관기준 관리
A4: (주)신화에이치앤티 | SH-FM-122 Rev.00 | 품질책임자 김흥수
A6: NO | B6: 양식번호 | C6: 양식명·기록명 | D6: 작성부서(안) | E6: 담당 역할(안) | F6: 작성주기·시점(안) | G6: 보관위치(안) | H6: 실제 담당자 | I6: 운영시작일 | J6: 확인상태 | K6: 결재 방식(안) | L6: 기록 보존기간·기준
A7: 1 | B7: ='01_현장양식목록'!B7 | C7: ='01_현장양식목록'!C7 | D7: 생산부서 | E7: 작업자·초품검사원 | F7: 생산 시작·교대·셋업·품번전환 후 | G7: 생산부서 기록철 | J7: 미확인 | K7: 작성·확인 | L7: 미확정 — 기록별 기준 확인
A8: 2 | B8: ='01_현장양식목록'!B8 | C8: ='01_현장양식목록'!C8 | D8: 품질부서 | E8: 공정검사원 | F8: Control Plan에 정한 검사주기 | G8: 품질부서 기록철 | J8: 미확인 | K8: 작성·확인 | L8: 미확정 — 기록별 기준 확인
A9: 3 | B9: ='01_현장양식목록'!B9 | C9: ='01_현장양식목록'!C9 | D9: 품질부서 | E9: 부적합품 관리담당 | F9: 부적합 발생·처리 시 | G9: 품질부서 기록철 | J9: 미확인 | K9: 작성·검토·승인 | L9: 미확정 — 기록별 기준 확인
A10: 4 | B10: ='01_현장양식목록'!B10 | C10: ='01_현장양식목록'!C10 | D10: 설비관리 담당부서 | E10: 설비담당·작업자 | F10: 작업 전 점검 / 고장 발생 시 | G10: 설비관리 담당부서 기록철 | J10: 미확인 | K10: 작성·확인 | L10: 미확정 — 기록별 기준 확인
A11: 5 | B11: ='01_현장양식목록'!B11 | C11: ='01_현장양식목록'!C11 | D11: 생산관리부서 | E11: 생산·출하 기록담당 | F11: 생산 LOT·검사·출하마다 | G11: 생산관리부서 기록철 | J11: 미확인 | K11: 작성·확인 | L11: 미확정 — 기록별 기준 확인
A12: 6 | B12: ='01_현장양식목록'!B12 | C12: ='01_현장양식목록'!C12 | D12: 자재구매부서 | E12: 자재담당 | F12: 구매품 입고·불출 시 | G12: 자재구매부서 기록철 | J12: 미확인 | K12: 작성·확인 | L12: 미확정 — 기록별 기준 확인
A13: 7 | B13: ='01_현장양식목록'!B13 | C13: ='01_현장양식목록'!C13 | D13: 품질부서 | E13: 계측기 관리담당 | F13: 등록·사용 전 확인·교정 시 | G13: 품질부서 기록철 | J13: 미확인 | K13: 작성·확인 | L13: 미확정 — 기록별 기준 확인
A14: 8 | B14: ='01_현장양식목록'!B14 | C14: ='01_현장양식목록'!C14 | D14: 품질부서 | E14: MSA 담당 | F14: 측정시스템 도입·변경 및 계획 시 | G14: 품질부서 기록철 | J14: 미확인 | K14: 작성·검토·승인 | L14: 미확정 — 기록별 기준 확인
A15: 9 | B15: ='01_현장양식목록'!B15 | C15: ='01_현장양식목록'!C15 | D15: 설비관리 담당부서 | E15: 금형·치공구 담당 | F15: 등록·교환·수리·점검 시 | G15: 설비관리 담당부서 기록철 | J15: 미확인 | K15: 작성·확인 | L15: 미확정 — 기록별 기준 확인
A16: 10 | B16: ='01_현장양식목록'!B16 | C16: ='01_현장양식목록'!C16 | D16: 자재구매부서 | E16: 자재담당 | F16: 입고·불출 시 / 재고점검 계획 시 | G16: 자재구매부서 기록철 | J16: 미확인 | K16: 작성·확인 | L16: 미확정 — 기록별 기준 확인
A17: 11 | B17: ='01_현장양식목록'!B17 | C17: ='01_현장양식목록'!C17 | D17: 생산관리부서 | E17: 출하담당·검사원 | F17: 출하 건별 | G17: 생산관리부서 기록철 | J17: 미확인 | K17: 작성·검토·승인 | L17: 미확정 — 기록별 기준 확인
A18: 12 | B18: ='01_현장양식목록'!B18 | C18: ='01_현장양식목록'!C18 | D18: 생산부서 | E18: 공정담당 | F18: 작업 시작·교대·조건변경 후 | G18: 생산부서 기록철 | J18: 미확인 | K18: 작성·검토·승인 | L18: 미확정 — 기록별 기준 확인
... A50: 44 | B50: ='01_현장양식목록'!B50 | C50: ='01_현장양식목록'!C50 | D50: 품질부서 | E50: 개선과제 담당 | F50: 과제 등록·진척 점검·종결 시 | G50: 품질부서 기록철 | J50: 미확인 | K50: 작성·검토·승인 | L50: 미확정 — 기록별 기준 확인

Sheet 03_번호배정대조표
A1: 현장 양식 문서번호 대조표
A2: (주)신화에이치앤티 | SH-FM-122 Rev.00
A4: 목록 NO | B4: 배정 문서번호 | C4: 현장 기록명 | D4: Master명·신규 양식명 | E4: 배정 구분 | F4: 개정 | G4: 적용 상태 | H4: 배정 근거
A5: 4 | B5: SH-FM-101 | C5: 설비 일상점검 및 고장이력 | D5: 설비 일상점검 및 고장이력 | E5: 신규 번호 배정 | F5: Rev.00 | G5: 양식 등록·승인 필요 | H5: 현장 작성계획 신규 배정
A6: 5 | B6: SH-FM-102 | C6: 생산·검사·출하 LOT 이력 | D6: 생산·검사·출하 LOT 이력 | E6: 신규 번호 배정 | F6: Rev.00 | G6: 양식 등록·승인 필요 | H6: 현장 작성계획 신규 배정
A7: 7 | B7: SH-FM-023 | C7: 계측기대장 및 교정기록 | D7: 계측기관리대장 | E7: 기존 번호 연결 | F7: Rev.00 | G7: 실제 양식·승인 확인 | H7: FM_MASTER_REV00_INITIAL_FINAL_QA.xlsx / 01_FM_Master
A8: 8 | B8: SH-FM-024 | C8: MSA 및 Gauge R&R 기록 | D8: MSA관리 | E8: 기존 번호 연결 | F8: Rev.00 | G8: 실제 양식·승인 확인 | H8: FM_MASTER_REV00_INITIAL_FINAL_QA.xlsx / 01_FM_Master
A9: 9 | B9: SH-FM-103 | C9: 금형·치공구 관리이력 | D9: 금형·치공구 관리이력 | E9: 신규 번호 배정 | F9: Rev.00 | G9: 양식 등록·승인 필요 | H9: 현장 작성계획 신규 배정
A10: 10 | B10: SH-FM-104 | C10: 자재 입고·보관·불출 기록 | D10: 자재 입고·보관·불출 기록 | E10: 신규 번호 배정 | F10: Rev.00 | G10: 양식 등록·승인 필요 | H10: 현장 작성계획 신규 배정
A11: 11 | B11: SH-FM-105 | C11: 포장·라벨 및 출하검증 기록 | D11: 포장·라벨 및 출하검증 기록 | E11: 신규 번호 배정 | F11: Rev.00 | G11: 양식 등록·승인 필요 | H11: 현장 작성계획 신규 배정
A12: 12 | B12: SH-FM-106 | C12: 공정조건 설정 및 확인기록 | D12: 공정조건 설정 및 확인기록 | E12: 신규 번호 배정 | F12: Rev.00 | G12: 양식 등록·승인 필요 | H12: 현장 작성계획 신규 배정
A13: 13 | B13: SH-FM-107 | C13: 오류방지 장치 점검기록 | D13: 오류방지 장치 점검기록 | E13: 신규 번호 배정 | F13: Rev.00 | G13: 양식 등록·승인 필요 | H13: 현장 작성계획 신규 배정
A14: 14 | B14: SH-FM-108 | C14: 품번전환 및 라인 클리어런스 기록 | D14: 품번전환 및 라인 클리어런스 기록 | E14: 신규 번호 배정 | F14: Rev.00 | G14: 양식 등록·승인 필요 | H14: 현장 작성계획 신규 배정
A15: 15 | B15: SH-FM-109 | C15: 선별검사 결과기록 | D15: 선별검사 결과기록 | E15: 신규 번호 배정 | F15: Rev.00 | G15: 양식 등록·승인 필요 | H15: 현장 작성계획 신규 배정
A16: 16 | B16: SH-FM-110 | C16: 교대 인수인계 기록 | D16: 교대 인수인계 기록 | E16: 신규 번호 배정 | F16: Rev.00 | G16: 양식 등록·승인 필요 | H16: 현장 작성계획 신규 배정
... A30: 37 | B30: SH-FM-121 | C30: 교육일지·참석 및 역량평가 기록 | D30: 교육일지·참석 및 역량평가 기록 | E30: 신규 번호 배정 | F30: Rev.00 | G30: 양식 등록·승인 필요 | H30: 현장 작성계획 신규 배정

Sheet 04_문서관리및연결
A1: 문서 관리정보 및 양식 연결
A3: 문서번호 / 개정 | C3: SH-FM-122 / Rev.00
A4: 문서명 | C4: 현장양식목록 및 작성계획
A5: 관리부서 / 검토담당 | C5: 품질부서 / 품질책임자 김흥수
A6: 전산 보관위치 | C6: 품질부서 QMS 문서관리 폴더 / 현장양식목록·작성계획
A7: 배포처 | C7: 품질·생산·생산관리·자재구매·설비관리·교육 주관부서
A8: 보존기간 | C8: 유효기간 중 보관 / 폐지·대체 후 5년 / 고객·법규의 장기 보존 요구 우선
A10: 승인·등록 상태 | C10: 승인 전 / 문서관리대장 등록 전
A11: 시행일 / 등록일 | C11: 시행일: __________________ 등록일: __________________
A12: 운영 방식 | C12: 연계 QMS Rev.03 / FM 자체 Rev.00 / 승인·배포·운영기록 별도 확인
A14: 현장 양식 파일 목록
A16: NO | B16: 문서번호 | C16: 양식명·기록명 | D16: 실제 파일명 | E16: 시트명 | F16: 제작 확인 | G16: 사용승인 | H16: 확인·조치사항
A17: 1 | B17: SH-FM-033 | C17: 생산조건 및 초품확인표 | F17: 실물 대조 필요 | G17: 승인 전 | H17: 파일·시트·개정 확인
A18: 2 | B18: SH-FM-034 | C18: 공정검사 기록표 | F18: 실물 대조 필요 | G18: 승인 전 | H18: 파일·시트·개정 확인
A19: 3 | B19: SH-FM-071 | C19: 부적합품 관련 관리기록 | F19: 실물 대조 필요 | G19: 승인 전 | H19: 파일·시트·개정 확인
A20: 4 | B20: SH-FM-101 | C20: 설비 일상점검 및 고장이력 | D20: SH-FM-101-121_현장작성양식_Rev00.xlsx | E20: SH-FM-101 | F20: 제작본 확인 | G20: 승인 전 | H20: 담당자·보존기간 확정 후 승인
A21: 5 | B21: SH-FM-102 | C21: 생산·검사·출하 LOT 이력 | D21: SH-FM-101-121_현장작성양식_Rev00.xlsx | E21: SH-FM-102 | F21: 제작본 확인 | G21: 승인 전 | H21: 담당자·보존기간 확정 후 승인
A22: 6 | B22: SH-FM-059 | C22: 구매품추적관리대장 | F22: 실물 대조 필요 | G22: 승인 전 | H22: 파일·시트·개정 확인
A23: 7 | B23: SH-FM-023 | C23: 계측기대장 및 교정기록 | F23: 실물 대조 필요 | G23: 승인 전 | H23: 파일·시트·개정 확인
A24: 8 | B24: SH-FM-024 | C24: MSA 및 Gauge R&R 기록 | F24: 실물 대조 필요 | G24: 승인 전 | H24: 파일·시트·개정 확인
A25: 9 | B25: SH-FM-103 | C25: 금형·치공구 관리이력 | D25: SH-FM-101-121_현장작성양식_Rev00.xlsx | E25: SH-FM-103 | F25: 제작본 확인 | G25: 승인 전 | H25: 담당자·보존기간 확정 후 승인
A26: 10 | B26: SH-FM-104 | C26: 자재 입고·보관·불출 기록 | D26: SH-FM-101-121_현장작성양식_Rev00.xlsx | E26: SH-FM-104 | F26: 제작본 확인 | G26: 승인 전 | H26: 담당자·보존기간 확정 후 승인
A27: 11 | B27: SH-FM-105 | C27: 포장·라벨 및 출하검증 기록 | D27: SH-FM-101-121_현장작성양식_Rev00.xlsx | E27: SH-FM-105 | F27: 제작본 확인 | G27: 승인 전 | H27: 담당자·보존기간 확정 후 승인
A28: 12 | B28: SH-FM-106 | C28: 공정조건 설정 및 확인기록 | D28: SH-FM-101-121_현장작성양식_Rev00.xlsx | E28: SH-FM-106 | F28: 제작본 확인 | G28: 승인 전 | H28: 담당자·보존기간 확정 후 승인
A29: 13 | B29: SH-FM-107 | C29: 오류방지 장치 점검기록 | D29: SH-FM-101-121_현장작성양식_Rev00.xlsx | E29: SH-FM-107 | F29: 제작본 확인 | G29: 승인 전 | H29: 담당자·보존기간 확정 후 승인
A30: 14 | B30: SH-FM-108 | C30: 품번전환 및 라인 클리어런스 기록 | D30: SH-FM-101-121_현장작성양식_Rev00.xlsx | E30: SH-FM-108 | F30: 제작본 확인 | G30: 승인 전 | H30: 담당자·보존기간 확정 후 승인
A31: 15 | B31: SH-FM-109 | C31: 선별검사 결과기록 | D31: SH-FM-101-121_현장작성양식_Rev00.xlsx | E31: SH-FM-109 | F31: 제작본 확인 | G31: 승인 전 | H31: 담당자·보존기간 확정 후 승인
A32: 16 | B32: SH-FM-110 | C32: 교대 인수인계 기록 | D32: SH-FM-101-121_현장작성양식_Rev00.xlsx | E32: SH-FM-110 | F32: 제작본 확인 | G32: 승인 전 | H32: 담당자·보존기간 확정 후 승인
A33: 17 | B33: SH-FM-022 | C33: 예방보전 계획 및 실시기록 | F33: 실물 대조 필요 | G33: 승인 전 | H33: 파일·시트·개정 확인
A34: 18 | B34: SH-FM-111 | C34: 청정도·청소 및 이물점검 기록 | D34: SH-FM-101-121_현장작성양식_Rev00.xlsx | E34: SH-FM-111 | F34: 제작본 확인 | G34: 승인 전 | H34: 담당자·보존기간 확정 후 승인
A35: 19 | B35: SH-FM-037 | C35: 재작업·수리 전후 검사기록 | F35: 실물 대조 필요 | G35: 승인 전 | H35: 파일·시트·개정 확인
A36: 20 | B36: SH-FM-066 | C36: 제품안전 요구사항대장 | D36: SH-FM-066-069_078-080_094_096_공식양식_Rev00.xlsx | E36: SH-FM-066 | F36: 실제 파일·시트 확인 | G36: 승인 표기 / 증빙 미확인 | H36: 승인일 9/3·기준일 9/4 구분 후 근거 연결
A37: 21 | B37: SH-FM-067 | C37: 제품안전 특성관리대장 | D37: SH-FM-066-069_078-080_094_096_공식양식_Rev00.xlsx | E37: SH-FM-067 | F37: 실제 파일·시트 확인 | G37: 승인 표기 / 증빙 미확인 | H37: 승인일 9/3·기준일 9/4 구분 후 근거 연결
A38: 22 | B38: SH-FM-068 | C38: 제품안전 에스컬레이션 보고서 | D38: SH-FM-066-069_078-080_094_096_공식양식_Rev00.xlsx | E38: SH-FM-068 | F38: 실제 파일·시트 확인 | G38: 승인 표기 / 증빙 미확인 | H38: 승인일 9/3·기준일 9/4 구분 후 근거 연결
A39: 23 | B39: SH-FM-069 | C39: 제품안전 연간점검표 | D39: SH-FM-066-069_078-080_094_096_공식양식_Rev00.xlsx | E39: SH-FM-069 | F39: 실제 파일·시트 확인 | G39: 승인 표기 / 증빙 미확인 | H39: 승인일 9/3·기준일 9/4 구분 후 근거 연결
A40: 24 | B40: SH-FM-112 | C40: 비상계획·훈련 및 복구검증 기록 | D40: SH-FM-101-121_현장작성양식_Rev00.xlsx | E40: SH-FM-112 | F40: 제작본 확인 | G40: 승인 전 | H40: 담당자·보존기간 확정 후 승인
A41: 25 | B41: SH-FM-113 | C41: 공정감사 및 LPA 기록 | D41: SH-FM-101-121_현장작성양식_Rev00.xlsx | E41: SH-FM-113 | F41: 제작본 확인 | G41: 승인 전 | H41: 담당자·보존기간 확정 후 승인
A42: 26 | B42: SH-FM-043 | C42: 제품공정변경검토서 | F42: 실물 대조 필요 | G42: 승인 전 | H42: 파일·시트·개정 확인
A43: 27 | B43: SH-FM-052 | C43: 초기유동관리계획서 | F43: 실물 대조 필요 | G43: 승인 전 | H43: 파일·시트·개정 확인
A44: 28 | B44: SH-FM-040 | C44: 고객불만 및 8D 기록 | F44: 실물 대조 필요 | G44: 승인 전 | H44: 파일·시트·개정 확인
...
