Workbook

Sheet 개당원가분석
A1: 개당 원가분석표 R2 (일 2,500개 기준)
A2: R1 + 검토보고서(2026-10-28) 반영본. A안=R1 입력 그대로 재현, B안=보고서 검증 시나리오(로스 3%·부담률 15%·OEE 90%·박스 10입수·기타경비 100원). B안은 확정 원가가 아니며, 현장확인 시트의 증빙 확보 후 입력 시트 값을 교체해야 합니다.
A3: 문서번호 | B3: 미정 (승인 후 문서관리 체계에서 부여) | F3: 작성 | G3: 검토 / 승인
A4: Rev / 기준일 | B4: R2 / 2026-10-28 (R1 기반) | F4: (직책·성명·일자 기재) | G4: (직책·성명·일자 기재)
A5: 문서 상태 | B5: 검토 중 (미승인) — 가정값 포함, 견적 확정 근거로 사용 금지 | F5: 견적 유효기간 | G5: =IF(입력!C54="","(미입력)",입력!C54) -> (미입력)
A8: ※ 위 직책·성명·일자는 확정 후 담당자가 직접 기재합니다. 이 파일은 임의로 채우지 않았습니다.
A9: 항목 | B9: 단위 | C9: A안 (R1 재현) | D9: B안 (보수·검증) | E9: 차이 (B-A) | F9: 차이율 | G9: 산식 / 비고
A10: 1. 재료비 (개당)
A11: 파이프 A 중량 | B11: kg | C11: =PI()*(입력!C23-입력!C24)*입력!C24*입력!C25*입력!C22/1000000 -> 0.32466161 | D11: =PI()*(입력!D23-입력!D24)*입력!D24*입력!D25*입력!D22/1000000 -> 0.32466161 | E11: =D11-C11 -> 0 | F11: =IF(C11=0,"-",D11/C11-1) -> 0 | G11: π×(OD-t)×t×L×비중
A12: 파이프 B 중량 | B12: kg | C12: =PI()*(입력!C23-입력!C24)*입력!C24*입력!C26*입력!C22/1000000 -> 0.23509978 | D12: =PI()*(입력!D23-입력!D24)*입력!D24*입력!D26*입력!D22/1000000 -> 0.23509978 | E12: =D12-C12 -> 0 | F12: =IF(C12=0,"-",D12/C12-1) -> 0
A13: 파이프 소재비 | B13: 원 | C13: =(C11+C12)*입력!C21*(1+입력!C27) -> 2910.7592 | D13: =(D11+D12)*입력!D21*(1+입력!D27) -> 2998.082 | E13: =D13-C13 -> 87.322777 | F13: =IF(C13=0,"-",D13/C13-1) -> 0.03 | G13: 중량×단가×(1+로스)
A14: 프랜지 | B14: 원 | C14: =입력!C29*입력!C30 -> 1600 | D14: =입력!D29*입력!D30 -> 1600 | E14: =D14-C14 -> 0 | F14: =IF(C14=0,"-",D14/C14-1) -> 0
A15: 다이캐스팅 | B15: 원 | C15: =입력!C31*입력!C32 -> 600 | D15: =입력!D31*입력!D32 -> 600 | E15: =D15-C15 -> 0 | F15: =IF(C15=0,"-",D15/C15-1) -> 0
A16: 포장지 | B16: 원 | C16: =입력!C33*입력!C34 -> 3 | D16: =입력!D33*입력!D34 -> 3 | E16: =D16-C16 -> 0 | F16: =IF(C16=0,"-",D16/C16-1) -> 0
A17: 박스 | B17: 원 | C17: =입력!C35/입력!C36 -> 120 | D17: =입력!D35/입력!D36 -> 12 | E17: =D17-C17 -> -108 | F17: =IF(C17=0,"-",D17/C17-1) -> -0.9 | G17: 단가 ÷ 입수
A18: 라벨 | B18: 원 | C18: =입력!C37*입력!C38 -> 16 | D18: =입력!D37*입력!D38 -> 16 | E18: =D18-C18 -> 0 | F18: =IF(C18=0,"-",D18/C18-1) -> 0
A19: 부품·포장재 소계 | B19: 원 | C19: =C14+C15+C16+C17+C18 -> 2339 | D19: =D14+D15+D16+D17+D18 -> 2231 | E19: =D19-C19 -> -108 | F19: =IF(C19=0,"-",D19/C19-1) -> -0.046173578
A20: 재료비 | B20: 원 | C20: =C13+C19 -> 5249.7592 | D20: =D13+D19 -> 5229.082 | E20: =D20-C20 -> -20.677223 | F20: =IF(C20=0,"-",D20/C20-1) -> -0.0039386994 | G20: 파이프 + 부품·포장재
A21: 2. 노무비·제조경비 (개당)
A22: 코킹 인건비 | B22: 원 | C22: =CT계산!C31 -> 232.72727 | D22: =CT계산!D31 -> 334.54545 | E22: =D22-C22 -> 101.81818 | F22: =IF(C22=0,"-",D22/C22-1) -> 0.4375 | G22: CT계산 시트
A23: 조립 인건비 | B23: 원 | C23: =CT계산!C32 -> 232.72727 | D23: =CT계산!D32 -> 267.63636 | E23: =D23-C23 -> 34.909091 | F23: =IF(C23=0,"-",D23/C23-1) -> 0.15 | G23: CT계산 시트
A24: 노무비 | B24: 원 | C24: =C22+C23 -> 465.45455 | D24: =D22+D23 -> 602.18182 | E24: =D24-C24 -> 136.72727 | F24: =IF(C24=0,"-",D24/C24-1) -> 0.29375
A25: 세척비 | B25: 원 | C25: =입력!C43 -> 80 | D25: =입력!D43 -> 80 | E25: =D25-C25 -> 0 | F25: =IF(C25=0,"-",D25/C25-1) -> 0
A26: 감가상각 | B26: 원 | C26: =입력!C44 -> 0 | D26: =입력!D44 -> 0 | E26: =D26-C26 -> 0 | F26: =IF(C26=0,"-",D26/C26-1) -> -
A27: 전력·가스 | B27: 원 | C27: =입력!C45 -> 0 | D27: =입력!D45 -> 0 | E27: =D27-C27 -> 0 | F27: =IF(C27=0,"-",D27/C27-1) -> -
A28: 유지보수 | B28: 원 | C28: =입력!C46 -> 0 | D28: =입력!D46 -> 0 | E28: =D28-C28 -> 0 | F28: =IF(C28=0,"-",D28/C28-1) -> -
A29: 공구·소모품 | B29: 원 | C29: =입력!C47 -> 0 | D29: =입력!D47 -> 0 | E29: =D29-C29 -> 0 | F29: =IF(C29=0,"-",D29/C29-1) -> -
A30: 기타 경비 | B30: 원 | C30: =입력!C48 -> 0 | D30: =입력!D48 -> 100 | E30: =D30-C30 -> 100 | F30: =IF(C30=0,"-",D30/C30-1) -> -
A31: 제조경비 | B31: 원 | C31: =C25+C26+C27+C28+C29+C30 -> 80 | D31: =D25+D26+D27+D28+D29+D30 -> 180 | E31: =D31-C31 -> 100 | F31: =IF(C31=0,"-",D31/C31-1) -> 1.25
A32: 공정비 (노무비+제조경비) | B32: 원 | C32: =C24+C31 -> 545.45455 | D32: =D24+D31 -> 782.18182 | E32: =D32-C32 -> 236.72727 | F32: =IF(C32=0,"-",D32/C32-1) -> 0.434 | G32: R1 "공정비"와 동일 범위
A33: 3. 원가·판매가 (개당)
A34: 제조원가 (재료비+공정비) | B34: 원 | C34: =C20+C32 -> 5795.2138 | D34: =D20+D32 -> 6011.2638 | E34: =D34-C34 -> 216.05005 | F34: =IF(C34=0,"-",D34/C34-1) -> 0.037280773 | G34: R1 "직접원가"
A35: 양품 기준 직접원가 (불량 반영) | B35: 원 | C35: =C34/(1-입력!C49) -> 5795.2138 | D35: =D34/(1-입력!D49) -> 6011.2638 | E35: =D35-C35 -> 216.05005 | F35: =IF(C35=0,"-",D35/C35-1) -> 0.037280773 | G35: 제조원가 ÷ (1-불량률)
A36: 관리비·이익 가산액 | B36: 원 | C36: =C35*입력!C51 -> 637.47351 | D36: =D35*입력!D51 -> 661.23902 | E36: =D36-C36 -> 23.765505 | F36: =IF(C36=0,"-",D36/C36-1) -> 0.037280773 | G36: 직접원가 × 가산율
A37: 추정 판매가 (공급가, VAT 별도) | B37: 원 | C37: =C35+C36 -> 6432.6873 | D37: =D35+D36 -> 6672.5028 | E37: =D37-C37 -> 239.81555 | F37: =IF(C37=0,"-",D37/C37-1) -> 0.037280773
A38: 부가가치세 | B38: 원 | C38: =C37*입력!C53 -> 643.26873 | D38: =D37*입력!D53 -> 667.25028 | E38: =D38-C38 -> 23.981555 | F38: =IF(C38=0,"-",D38/C38-1) -> 0.037280773
A39: 판매가 (VAT 포함) | B39: 원 | C39: =C37+C38 -> 7075.956 | D39: =D37+D38 -> 7339.7531 | E39: =D39-C39 -> 263.79711 | F39: =IF(C39=0,"-",D39/C39-1) -> 0.037280773
A40: 매출 대비 가산액 비율 (실질 이익률 상한) | B40: % | C40: =C36/C37 -> 0.099099099 | D40: =D36/D37 -> 0.099099099 | E40: =D40-C40 -> 0 | G40: 11% 가산 ≠ 매출 11%
A41: 참고: 매출 대비 목표이익률 기준 환산 판매가 | B41: 원 | C41: =C35/(1-입력!C52) -> 6511.4761 | D41: =D35/(1-입력!D52) -> 6754.229 | E41: =D41-C41 -> 242.75286 | F41: =IF(C41=0,"-",D41/C41-1) -> 0.037280773 | G41: 직접원가 ÷ (1-목표 매출총이익률)
A42: 참고: 환산가 - 추정 판매가 | B42: 원 | C42: =C41-C37 -> 78.788861 | D42: =D41-D37 -> 81.726171 | E42: =D42-C42 -> 2.9373097 | F42: =IF(C42=0,"-",D42/C42-1) -> 0.037280773 | G42: (+)면 11% 매출이익을 위해 인상 필요
...

Sheet 입력
A1: 입력 시트 — 개당원가분석표 R2
A2: 파란색=입력값(잠금 해제). A안=R1 원본 입력 그대로(검증 기준), B안=검토보고서 검증 시나리오(확정값 아님). 노란색=가정/미확정, 주황색=시나리오 값. 확정 자료가 오면 해당 안의 칸만 바꾸세요.
A4: 항목 | B4: 단위 | C4: A안 (R1 재현) | D4: B안 (보수·검증) | E4: 값 상태 | F4: 근거 / 확인 필요
A5: 1. 생산 조건
A6: 일 생산수량 | B6: 개/일 | C6: 2500 | D6: 2500 | E6: 가정 | F6: 고객 발주량 확인 필요(R1 값)
A7: 월 근무일수 | B7: 일 | C7: 22 | D7: 22 | E7: 가정 | F7: 주5일 기준 가정. 실제 가동일·발주계획 확인
A8: 근무 시작 시각 | B8: 시 | C8: 8 | D8: 8 | E8: 가정 | F8: 08:00
A9: 근무 종료 시각 | B9: 시 | C9: 19 | D9: 19 | E9: 가정 | F9: 19:00 (종료>시작)
A10: 휴식 간격 | B10: 시간 | C10: 2 | D10: 2 | E10: 가정 | F10: 2시간마다 휴식
A11: 휴식 시간 (1회) | B11: 분 | C11: 15 | D11: 15 | E11: 가정 | F11: 실제 휴게 편성표로 확인
A12: 식사와 겹쳐 제외할 휴식 횟수 | B12: 회 | C12: 0 | D12: 0 | E12: 미확정 | F12: 점심·저녁과 겹치는 휴식이 있으면 입력(R1은 중복 미반영=0)
A13: 점심시간 | B13: 분 | C13: 40 | D13: 40 | E13: 가정 | F13: 실제 시간표 확인
A14: 저녁시간 | B14: 분 | C14: 20 | D14: 20 | E14: 가정 | F14: 실제 시간표 확인
A15: 설비 종합효율 OEE (가동×성능×양품) | B15: % | C15: 1 | D15: 0.9 | E15: 시나리오 | F15: A안 100%=R1(손실 미반영). B안 90%=검토보고서 예시, 실적 OEE로 교체 필요
A16: 로봇 1대 C/T | B16: 초/개 | C16: 46 | D16: 46 | E16: 사용자 제공 | F16: 타임스터디로 실측 확인 필요
A17: 로봇 1대당 작업자 | B17: 명/대 | C17: 1 | D17: 1 | E17: 사용자 제공
A18: 조립 1조 인원 | B18: 명/조 | C18: 4 | D18: 4 | E18: 가정 | F18: 병목공정CT 시트에서 공정별 검증
A19: 조립 조 수 | B19: 조 | C19: 1 | D19: 1 | E19: 가정 | F19: 병목공정CT 시트 판정이 "병목"이면 증가
A20: 2. 소재 (파이프)
A21: 소재 단가 | B21: 원/kg | C21: 5200 | D21: 5200 | E21: 사용자 제공 | F21: 최근 매입단가·발주서로 확인
A22: 소재 비중 | B22: g/cm³ | C22: 7.93 | D22: 7.93 | E22: 가정 | F22: STS304 가정(알루미늄 2.70, 일반강 7.85). 재질증명서 확인
A23: 외경 OD | B23: mm | C23: 25.4 | D23: 25.4 | E23: 가정 | F23: 외경 미제공 → 25.4mm 가정. 승인 도면으로 교체
A24: 두께 t | B24: mm | C24: 1.24 | D24: 1.24 | E24: 가정 | F24: 파이프 A·B 공통
A25: 파이프 A 길이 | B25: mm | C25: 435 | D25: 435 | E25: 가정 | F25: 도면 L 확인
A26: 파이프 B 길이 | B26: mm | C26: 315 | D26: 315 | E26: 가정 | F26: 도면 L 확인
A27: 소재 로스율 (추가 투입률) | B27: % | C27: 0 | D27: 0.03 | E27: 시나리오 | F27: 투입중량×(1+로스). A안 0%=R1, B안 3%=검토보고서 예시
A28: 3. 구매 부품·포장재 (개당)
A29: 프랜지 개당 수량 | B29: EA | C29: 1 | D29: 1 | E29: 가정 | F29: BOM 확인(명칭: 승인 BOM 기준 확정 전 원문 표기)
A30: 프랜지 단가 | B30: 원 | C30: 1600 | D30: 1600 | E30: 가정 | F30: 최근 매입명세 확인
A31: 다이캐스팅 개당 수량 | B31: EA | C31: 2 | D31: 2 | E31: 가정 | F31: 개당 2개 사용
A32: 다이캐스팅 단가 | B32: 원 | C32: 300 | D32: 300 | E32: 가정
A33: 포장지 개당 수량 | B33: EA | C33: 1 | D33: 1 | E33: 가정
A34: 포장지 단가 | B34: 원 | C34: 3 | D34: 3 | E34: 가정 | F34: R1 "3월짜리"를 3원으로 해석 — 거래품명 확인
A35: 박스 단가 | B35: 원 | C35: 120 | D35: 120 | E35: 가정
A36: 박스 1개당 제품 입수 | B36: 개 | C36: 1 | D36: 10 | E36: 시나리오 | F36: A안 1(제품당 박스1개)=R1, B안 10입수=검토보고서 예시. 포장사양서 확인
A37: 라벨 개당 수량 | B37: EA | C37: 2 | D37: 2 | E37: 가정 | F37: R1 "라벨 2대"를 2개로 해석
A38: 라벨 단가 | B38: 원 | C38: 8 | D38: 8 | E38: 가정
A39: 4. 노무·경비
A40: 1인 월급 (기본) | B40: 원/인·월 | C40: 3200000 | D40: 3200000 | E40: 사용자 제공 | F40: 급여 총액 확인(기본급·상여 구분)
A41: 1인 월 연장·수당 추가 | B41: 원/인·월 | C41: 0 | D41: 0 | E41: 미확정 | F41: 잔업·야간·수당. 08~19시 근무라 연장 발생 여부 확인(R1 미반영=0)
...

Sheet CT계산
A1: C/T(택타임) 및 인원 계산 — R2
A2: A안=R1과 동일 산식(OEE 100%), B안=OEE·부담률 등 시나리오 반영. 모든 값은 입력 시트에서 가져옵니다(초록=타 시트 참조).
A4: 항목 | B4: 단위 | C4: A안 (R1 재현) | D4: B안 (보수·검증) | F4: 산식 / 의미
A5: 1. 목표 C/T
A6: 총 체류시간 | B6: 분 | C6: =(입력!C9-입력!C8)*60 -> 660 | D6: =(입력!D9-입력!D8)*60 -> 660 | F6: 종료 - 시작
A7: 휴식 횟수 (산식) | B7: 회 | C7: =ROUNDDOWN((입력!C9-입력!C8)/입력!C10,0) -> 5 | D7: =ROUNDDOWN((입력!D9-입력!D8)/입력!D10,0) -> 5 | F7: 체류시간 ÷ 휴식 간격(내림)
A8: 휴식 횟수 (중복 제외 후) | B8: 회 | C8: =MAX(0,C7-입력!C12) -> 5 | D8: =MAX(0,D7-입력!D12) -> 5 | F8: 식사와 겹친 휴식 제외
A9: 휴식 합계 | B9: 분 | C9: =C8*입력!C11 -> 75 | D9: =D8*입력!D11 -> 75 | F9: 횟수 × 1회 시간
A10: 식사 합계 | B10: 분 | C10: =입력!C13+입력!C14 -> 60 | D10: =입력!D13+입력!D14 -> 60 | F10: 점심 + 저녁
A11: 실가동시간 | B11: 분 | C11: =C6-C9-C10 -> 525 | D11: =D6-D9-D10 -> 525 | F11: 체류 - 휴식 - 식사
A12: 실가동시간 | B12: 초 | C12: =C11*60 -> 31500 | D12: =D11*60 -> 31500
A13: 목표 C/T (이론 택트) | B13: 초/개 | C13: =C12/입력!C6 -> 12.6 | D13: =D12/입력!D6 -> 12.6 | F13: 실가동초 ÷ 일 생산수량
A14: OEE 반영 유효 택트 | B14: 초/개 | C14: =C13*입력!C15 -> 12.6 | D14: =D13*입력!D15 -> 11.34 | F14: 택트 × OEE (손실 반영 시 실제 요구 속도)
A15: 2. 로봇(코킹) 공정 검토
A16: 로봇 1대 일 이론능력 | B16: 개 | C16: =C12/입력!C16 -> 684.78261 | D16: =D12/입력!D16 -> 684.78261 | F16: 실가동초 ÷ C/T (OEE 미반영)
A17: 로봇 1대 일 실효능력 | B17: 개 | C17: =C16*입력!C15 -> 684.78261 | D17: =D16*입력!D15 -> 616.30435 | F17: 이론능력 × OEE
A18: 필요 로봇 대수 (OEE 반영) | B18: 대 | C18: =ROUNDUP(입력!C6/C17,0) -> 4 | D18: =ROUNDUP(입력!D6/D17,0) -> 5 | F18: ROUNDUP(수량 ÷ 실효능력)
A19: 참고: 필요 로봇 대수 (OEE 미반영, R1 방식) | B19: 대 | C19: =ROUNDUP(입력!C6/C16,0) -> 4 | D19: =ROUNDUP(입력!D6/D16,0) -> 4 | F19: R1 산식
A20: 로봇 전체 일 실효능력 | B20: 개 | C20: =C17*C18 -> 2739.1304 | D20: =D17*D18 -> 3081.5217
A21: 설비 부하율 (수량/실효능력) | B21: % | C21: =입력!C6/C20 -> 0.91269841 | D21: =입력!D6/D20 -> 0.81128748
A22: 일 능력 여유(+)/부족(-) | B22: 개 | C22: =C20-입력!C6 -> 239.13043 | D22: =D20-입력!D6 -> 581.52174
A23: 판정 | C23: =IF(C20>=입력!C6,"충족","부족") -> 충족 | D23: =IF(D20>=입력!D6,"충족","부족") -> 충족 | F23: 능력 ≥ 목표면 충족
A24: 참고: R1 로봇 대수 유지 시 일 과부족 | B24: 개 | C24: =C19*C17-입력!C6 -> 239.13043 | D24: =D19*D17-입력!D6 -> -34.782609 | F24: R1 로봇 대수로 OEE 반영 시 (-)면 목표 미달
A25: 3. 인원·노무비
A26: 코킹 총 인원 | B26: 명 | C26: =입력!C17*C18 -> 4 | D26: =입력!D17*D18 -> 5 | F26: 로봇 대수 × 1대당 인원
A27: 조립 총 인원 | B27: 명 | C27: =입력!C18*입력!C19 -> 4 | D27: =입력!D18*입력!D19 -> 4 | F27: 조당 인원 × 조 수
A28: 총 인원 | B28: 명 | C28: =C26+C27 -> 8 | D28: =D26+D27 -> 9
A29: 월 생산수량 | B29: 개 | C29: =입력!C6*입력!C7 -> 55000 | D29: =입력!D6*입력!D7 -> 55000 | F29: 일 생산수량 × 월 근무일수
A30: 월 노무비 총액 | B30: 원 | C30: =C28*(입력!C40+입력!C41)*(1+입력!C42) -> 25600000 | D30: =D28*(입력!D40+입력!D41)*(1+입력!D42) -> 33120000 | F30: 인원 × (월급+수당) × (1+부담률)
A31: 코킹 개당 인건비 | B31: 원 | C31: =C26*(입력!C40+입력!C41)*(1+입력!C42)/C29 -> 232.72727 | D31: =D26*(입력!D40+입력!D41)*(1+입력!D42)/D29 -> 334.54545
A32: 조립 개당 인건비 | B32: 원 | C32: =C27*(입력!C40+입력!C41)*(1+입력!C42)/C29 -> 232.72727 | D32: =D27*(입력!D40+입력!D41)*(1+입력!D42)/D29 -> 267.63636

Sheet 병목공정CT
A1: 조립 공정별 C/T 및 병목 판정 (신규)
A2: 공정별 실측 C/T(초)와 배치 인원을 입력하면 목표 택트 대비 병목 여부와 필요 인원을 계산합니다. 현재 값은 모두 미측정(빈칸)입니다 — 임의 값을 넣지 않았습니다.
A4: 공정 | B4: 실측 C/T (초/개) | C4: 배치 인원 (명) | D4: 인당 유효 C/T (초) | E4: 필요 인원 (A안 택트) | F4: 필요 인원 (B안 택트) | G4: 판정 (A안) | H4: 판정 (B안)
A5: 마킹 | D5: =IF(B5="","",IF(C5>0,B5/C5,"")) | E5: =IF(B5="","",ROUNDUP(B5/CT계산!$C$14,0)) | F5: =IF(B5="","",ROUNDUP(B5/CT계산!$D$14,0)) | G5: =IF(OR(B5="",C5=""),"미측정",IF(D5<=CT계산!$C$14,"충족","병목")) -> 미측정 | H5: =IF(OR(B5="",C5=""),"미측정",IF(D5<=CT계산!$D$14,"충족","병목")) -> 미측정
A6: 본딩 | D6: =IF(B6="","",IF(C6>0,B6/C6,"")) | E6: =IF(B6="","",ROUNDUP(B6/CT계산!$C$14,0)) | F6: =IF(B6="","",ROUNDUP(B6/CT계산!$D$14,0)) | G6: =IF(OR(B6="",C6=""),"미측정",IF(D6<=CT계산!$C$14,"충족","병목")) -> 미측정 | H6: =IF(OR(B6="",C6=""),"미측정",IF(D6<=CT계산!$D$14,"충족","병목")) -> 미측정
A7: 브라켓 체결 | D7: =IF(B7="","",IF(C7>0,B7/C7,"")) | E7: =IF(B7="","",ROUNDUP(B7/CT계산!$C$14,0)) | F7: =IF(B7="","",ROUNDUP(B7/CT계산!$D$14,0)) | G7: =IF(OR(B7="",C7=""),"미측정",IF(D7<=CT계산!$C$14,"충족","병목")) -> 미측정 | H7: =IF(OR(B7="",C7=""),"미측정",IF(D7<=CT계산!$D$14,"충족","병목")) -> 미측정
A8: 검사 | D8: =IF(B8="","",IF(C8>0,B8/C8,"")) | E8: =IF(B8="","",ROUNDUP(B8/CT계산!$C$14,0)) | F8: =IF(B8="","",ROUNDUP(B8/CT계산!$D$14,0)) | G8: =IF(OR(B8="",C8=""),"미측정",IF(D8<=CT계산!$C$14,"충족","병목")) -> 미측정 | H8: =IF(OR(B8="",C8=""),"미측정",IF(D8<=CT계산!$D$14,"충족","병목")) -> 미측정
A9: 포장 | D9: =IF(B9="","",IF(C9>0,B9/C9,"")) | E9: =IF(B9="","",ROUNDUP(B9/CT계산!$C$14,0)) | F9: =IF(B9="","",ROUNDUP(B9/CT계산!$D$14,0)) | G9: =IF(OR(B9="",C9=""),"미측정",IF(D9<=CT계산!$C$14,"충족","병목")) -> 미측정 | H9: =IF(OR(B9="",C9=""),"미측정",IF(D9<=CT계산!$D$14,"충족","병목")) -> 미측정
A11: 합계 / 요약
A12: 공정별 필요 인원 합 (A안 택트) | E12: =IF(COUNT(B5:B9)=0,"미측정",SUM(E5:E9)) -> 미측정
A13: 공정별 필요 인원 합 (B안 택트) | F13: =IF(COUNT(B5:B9)=0,"미측정",SUM(F5:F9)) -> 미측정
A14: 입력된 조립 인원 (입력 시트 조당 인원×조 수) | E14: =CT계산!C27 -> 4 | F14: =CT계산!D27 -> 4
A15: 조립 인원 충분 여부 | E15: =IF(ISNUMBER(E12),IF(E14>=E12,"충분","부족 — 조 수/인원 증가 검토"),"미측정") -> 미측정 | F15: =IF(ISNUMBER(F13),IF(F14>=F13,"충분","부족 — 조 수/인원 증가 검토"),"미측정") -> 미측정
A17: ※ 한 사람이 여러 공정을 겸하는 경우는 공정 합산 C/T를 한 행으로 묶어 입력하세요. 이 표는 공정 간 이동·대기 손실을 반영하지 않으므로 라인밸런싱 측정으로 재확인이 필요합니다.

Sheet 민감도
A1: 민감도 분석 — R2 (수식 연동)
A2: 입력 시트의 값이 바뀌면 자동으로 갱신됩니다. 시나리오 값은 예시이며 확정 원가가 아닙니다.
A4: 1. 월 가동일수별 (노무비 총액 고정, 일 생산수량 유지)
A5: 월 가동일수 | B5: A안 월생산(개) | C5: A안 판매가(원/개) | D5: A안 vs 기준 | E5: B안 월생산(개) | F5: B안 판매가(원/개) | G5: B안 vs 기준
A6: 18 | B6: =입력!$C$6*$A6 -> 45000 | C6: =((개당원가분석!$C$34-(CT계산!$C$31+CT계산!$C$32)+CT계산!$C$30/(입력!$C$6*$A6))/(1-입력!$C$49))*(1+입력!$C$51) -> 6547.4994 | D6: =C6-개당원가분석!$C$37 -> 114.81212 | E6: =입력!$D$6*$A6 -> 45000 | F6: =((개당원가분석!$D$34-(CT계산!$D$31+CT계산!$D$32)+CT계산!$D$30/(입력!$D$6*$A6))/(1-입력!$D$49))*(1+입력!$D$51) -> 6821.041 | G6: =F6-개당원가분석!$D$37 -> 148.53818
A7: 20 | B7: =입력!$C$6*$A7 -> 50000 | C7: =((개당원가분석!$C$34-(CT계산!$C$31+CT계산!$C$32)+CT계산!$C$30/(입력!$C$6*$A7))/(1-입력!$C$49))*(1+입력!$C$51) -> 6484.3527 | D7: =C7-개당원가분석!$C$37 -> 51.665455 | E7: =입력!$D$6*$A7 -> 50000 | F7: =((개당원가분석!$D$34-(CT계산!$D$31+CT계산!$D$32)+CT계산!$D$30/(입력!$D$6*$A7))/(1-입력!$D$49))*(1+입력!$D$51) -> 6739.345 | G7: =F7-개당원가분석!$D$37 -> 66.842182
A8: 22 | B8: =입력!$C$6*$A8 -> 55000 | C8: =((개당원가분석!$C$34-(CT계산!$C$31+CT계산!$C$32)+CT계산!$C$30/(입력!$C$6*$A8))/(1-입력!$C$49))*(1+입력!$C$51) -> 6432.6873 | D8: =C8-개당원가분석!$C$37 -> 0 | E8: =입력!$D$6*$A8 -> 55000 | F8: =((개당원가분석!$D$34-(CT계산!$D$31+CT계산!$D$32)+CT계산!$D$30/(입력!$D$6*$A8))/(1-입력!$D$49))*(1+입력!$D$51) -> 6672.5028 | G8: =F8-개당원가분석!$D$37 -> 0
A9: 24 | B9: =입력!$C$6*$A9 -> 60000 | C9: =((개당원가분석!$C$34-(CT계산!$C$31+CT계산!$C$32)+CT계산!$C$30/(입력!$C$6*$A9))/(1-입력!$C$49))*(1+입력!$C$51) -> 6389.6327 | D9: =C9-개당원가분석!$C$37 -> -43.054545 | E9: =입력!$D$6*$A9 -> 60000 | F9: =((개당원가분석!$D$34-(CT계산!$D$31+CT계산!$D$32)+CT계산!$D$30/(입력!$D$6*$A9))/(1-입력!$D$49))*(1+입력!$D$51) -> 6616.801 | G9: =F9-개당원가분석!$D$37 -> -55.701818
A10: 26 | B10: =입력!$C$6*$A10 -> 65000 | C10: =((개당원가분석!$C$34-(CT계산!$C$31+CT계산!$C$32)+CT계산!$C$30/(입력!$C$6*$A10))/(1-입력!$C$49))*(1+입력!$C$51) -> 6353.202 | D10: =C10-개당원가분석!$C$37 -> -79.485315 | E10: =입력!$D$6*$A10 -> 65000 | F10: =((개당원가분석!$D$34-(CT계산!$D$31+CT계산!$D$32)+CT계산!$D$30/(입력!$D$6*$A10))/(1-입력!$D$49))*(1+입력!$D$51) -> 6569.6687 | G10: =F10-개당원가분석!$D$37 -> -102.83413
A13: 2. OEE별 필요 로봇·인원·판매가 (B안 입력 기준, OEE만 변경)
A14: OEE | B14: 일 가능 생산량(R1 로봇수) | C14: 목표 대비(개) | D14: 필요 로봇(대) | E14: 총 인원(명) | F14: 개당 노무비(원) | G14: 판매가(원/개) | H14: 판정(R1 로봇수)
A15: 0.8 | B15: =CT계산!$D$19*CT계산!$D$12/입력!$D$16*$A15 -> 2191.3043 | C15: =B15-입력!$D$6 -> -308.69565 | D15: =ROUNDUP(입력!$D$6/(CT계산!$D$12/입력!$D$16*$A15),0) -> 5 | E15: =D15*입력!$D$17+CT계산!$D$27 -> 9 | F15: =E15*(입력!$D$40+입력!$D$41)*(1+입력!$D$42)/CT계산!$D$29 -> 602.18182 | G15: =((개당원가분석!$D$34-(CT계산!$D$31+CT계산!$D$32)+F15)/(1-입력!$D$49))*(1+입력!$D$51) -> 6672.5028 | H15: =IF(C15>=0,"충족","부족") -> 부족
A16: 0.85 | B16: =CT계산!$D$19*CT계산!$D$12/입력!$D$16*$A16 -> 2328.2609 | C16: =B16-입력!$D$6 -> -171.73913 | D16: =ROUNDUP(입력!$D$6/(CT계산!$D$12/입력!$D$16*$A16),0) -> 5 | E16: =D16*입력!$D$17+CT계산!$D$27 -> 9 | F16: =E16*(입력!$D$40+입력!$D$41)*(1+입력!$D$42)/CT계산!$D$29 -> 602.18182 | G16: =((개당원가분석!$D$34-(CT계산!$D$31+CT계산!$D$32)+F16)/(1-입력!$D$49))*(1+입력!$D$51) -> 6672.5028 | H16: =IF(C16>=0,"충족","부족") -> 부족
A17: 0.9 | B17: =CT계산!$D$19*CT계산!$D$12/입력!$D$16*$A17 -> 2465.2174 | C17: =B17-입력!$D$6 -> -34.782609 | D17: =ROUNDUP(입력!$D$6/(CT계산!$D$12/입력!$D$16*$A17),0) -> 5 | E17: =D17*입력!$D$17+CT계산!$D$27 -> 9 | F17: =E17*(입력!$D$40+입력!$D$41)*(1+입력!$D$42)/CT계산!$D$29 -> 602.18182 | G17: =((개당원가분석!$D$34-(CT계산!$D$31+CT계산!$D$32)+F17)/(1-입력!$D$49))*(1+입력!$D$51) -> 6672.5028 | H17: =IF(C17>=0,"충족","부족") -> 부족
A18: 0.95 | B18: =CT계산!$D$19*CT계산!$D$12/입력!$D$16*$A18 -> 2602.1739 | C18: =B18-입력!$D$6 -> 102.17391 | D18: =ROUNDUP(입력!$D$6/(CT계산!$D$12/입력!$D$16*$A18),0) -> 4 | E18: =D18*입력!$D$17+CT계산!$D$27 -> 8 | F18: =E18*(입력!$D$40+입력!$D$41)*(1+입력!$D$42)/CT계산!$D$29 -> 535.27273 | G18: =((개당원가분석!$D$34-(CT계산!$D$31+CT계산!$D$32)+F18)/(1-입력!$D$49))*(1+입력!$D$51) -> 6598.2337 | H18: =IF(C18>=0,"충족","부족") -> 충족
A19: 1 | B19: =CT계산!$D$19*CT계산!$D$12/입력!$D$16*$A19 -> 2739.1304 | C19: =B19-입력!$D$6 -> 239.13043 | D19: =ROUNDUP(입력!$D$6/(CT계산!$D$12/입력!$D$16*$A19),0) -> 4 | E19: =D19*입력!$D$17+CT계산!$D$27 -> 8 | F19: =E19*(입력!$D$40+입력!$D$41)*(1+입력!$D$42)/CT계산!$D$29 -> 535.27273 | G19: =((개당원가분석!$D$34-(CT계산!$D$31+CT계산!$D$32)+F19)/(1-입력!$D$49))*(1+입력!$D$51) -> 6598.2337 | H19: =IF(C19>=0,"충족","부족") -> 충족
A21: 3. 박스 입수별 (B안 기준, 박스 단가 유지)
A22: 박스 1개당 입수(개) | B22: 박스비(원/개) | C22: 판매가(원/개) | D22: 기준(B안) 대비
A23: 1 | B23: =입력!$D$35/$A23 -> 120 | C23: =((개당원가분석!$D$34-개당원가분석!$D$17+B23)/(1-입력!$D$49))*(1+입력!$D$51) -> 6792.3828 | D23: =C23-개당원가분석!$D$37 -> 119.88
A24: 5 | B24: =입력!$D$35/$A24 -> 24 | C24: =((개당원가분석!$D$34-개당원가분석!$D$17+B24)/(1-입력!$D$49))*(1+입력!$D$51) -> 6685.8228 | D24: =C24-개당원가분석!$D$37 -> 13.32
A25: 10 | B25: =입력!$D$35/$A25 -> 12 | C25: =((개당원가분석!$D$34-개당원가분석!$D$17+B25)/(1-입력!$D$49))*(1+입력!$D$51) -> 6672.5028 | D25: =C25-개당원가분석!$D$37 -> 0
A26: 20 | B26: =입력!$D$35/$A26 -> 6 | C26: =((개당원가분석!$D$34-개당원가분석!$D$17+B26)/(1-입력!$D$49))*(1+입력!$D$51) -> 6665.8428 | D26: =C26-개당원가분석!$D$37 -> -6.66

Sheet 검토반영
A1: 검토보고서 지적사항 반영표 (19건)
A2: 반영상태: 반영완료=R2 파일에서 구조·산식 수정 완료 / 구조반영·값확인=틀은 만들었고 실제 값은 증빙 확인 필요 / 보류=자료·결정 필요(임의 값 미입력).
A4: No | B4: 우선 | C4: 분야 | D4: 검토 지적 | E4: R2 반영 내용 | F4: 반영상태 | G4: 남은 조치 (담당)
A5: 01 | B5: P1 | C5: 소재 원가 | D5: OD 25.4·t 1.24·비중 7.93 가정값 | E5: OD·t·길이·비중을 입력 시트 개별 셀로 분리, 가정 상태 표시(노란색)·근거 안내 추가. 값 자체는 R1 유지 | F5: 구조반영·값확인 | G5: 승인 도면/실측 중량으로 교체 (생산기술/구매)
A6: 02 | B6: P1 | C6: 구매 부품비 | D6: BOM·단가 검증자료 미첨부 | E6: 부품별 수량·단가를 입력 셀로 분리하고 각 행에 확인 필요 사유 표기 | F6: 구조반영·값확인 | G6: 품번별 BOM·최근 매입명세 대조 (구매/품질)
A7: 03 | B7: P1 | C7: 소재 로스 | D7: 로스율 0% 미반영 | E7: 로스를 "추가 투입률"로 정의해 소재비 산식에 반영. A안 0%(R1), B안 3%(예시) | F7: 구조반영·값확인 | G7: 절단 스크랩·불량 실적으로 확정 (생산/품질)
A8: 04 | B8: P1 | C8: 설비 부하 | D8: OEE 미반영, 4대 필요 OEE 91.3% | E8: OEE 입력 추가, 필요 로봇=ROUNDUP(수량×C/T÷(가동초×OEE)). B안 OEE 90%에서 5대로 산정 | F8: 반영완료(OEE 실적은 확인) | G8: 실적 OEE(가동·성능·양품) 측정 (생산기술)
A9: 05 | B9: P1 | C9: 휴게시간 | D9: 휴식 5회 중 점심·저녁 중복 가능 | E9: "식사와 겹쳐 제외할 휴식 횟수" 입력 추가(기본 0=R1 유지), 중복 제외 후 횟수로 계산 | F9: 구조반영·값확인 | G9: 실제 근무/휴게 시간표 입력 (생산/인사)
A10: 06 | B10: P1 | C10: 조립 병목 | D10: 4명 1조 능력 미검증 | E10: 병목공정CT 시트 신설: 공정별 실측 C/T·인원으로 병목 판정·필요 인원 계산(현재 미측정) | F10: 구조반영·값확인 | G10: 5개 공정 C/T 타임스터디 (생산기술)
A11: 07 | B11: P1 | C11: 직접 노무비 | D11: 부담률 0%, 연장수당 누락 가능 | E11: 급여 부담률·1인 월 연장수당 입력 분리. A안 0%(R1), B안 부담률 15%(예시) | F11: 구조반영·값확인 | G11: 급여 총액·수당·사업주 부담비 확인 (인사/회계)
A12: 08 | B12: P1 | C12: 경비 누락 | D12: 감가상각·전력 등 0원 | E12: 감가상각·전력가스·유지보수·공구소모품 4항목 + 기타 입력행 분리, B안 기타 100원(예시) | F12: 구조반영·값확인 | G12: 설비/전력 데이터로 배부액 산정 (회계/생산기술)
A13: 09 | B13: P1 | C13: 마진 해석 | D13: 11% 가산 ≠ 매출 11% | E13: 매출 대비 가산액 비율(9.91%) 병기, 목표 매출총이익률 기준 환산 판매가·차액 추가. 관리비/이익 분리 정의는 보류 | F13: 부분반영(정책 결정 필요) | G13: 가산율의 관리비·이익 구성 결정 (영업/회계)
A14: 10 | B14: P2 | C14: 포장 단위 | D14: 박스 1개/제품 가정 | E14: 박스 단가와 "박스 1개당 입수"로 분리, 민감도 3절 추가. B안 10입수(예시) | F14: 구조반영·값확인 | G14: 포장사양서 확인 (물류/구매)
A15: 11 | B15: P2 | C15: 품질손실 | D15: 불량·재작업 구분 없음 | E15: 공정 불량률 입력 추가, 양품 기준 직접원가=제조원가÷(1-불량률)로 반영(기본 0%) | F15: 구조반영·값확인 | G15: 품질 실적·수율 확인 (품질/생산)
... A23: 19 | B23: P3 | C23: 항목 표기 | D23: "프랜지","3월짜리","라벨 2대" | E23: R1의 해석(3원·2개)은 유지하고 입력 시트 비고에 해석 근거와 확인 필요를 명시. 명칭은 승인 BOM 확정 전 변경 안 함 | F23: 보류 | G23: 정확한 거래품명 확인 (구매/품질)

Sheet 현장확인
A1: 현장 확인 및 반영 체크리스트
A2: 실제 확인값은 직접 기재하세요(자동 입력 없음). 증빙 확보·내부 승인 후 입력 시트의 해당 안 값을 교체하고 Rev를 올립니다.
A4: No | B4: 확인 항목 | C4: 현재 파일 기준 (R1) | D4: 반영 위치 (입력 시트) | E4: 실제 확인값 / 변경 요청 | F4: 필요 증빙 | G4: 주관부서(권장) | H4: 진행상태 | I4: 완료 예정일
A5: 01 | B5: 제품 품번·도면 Rev | C5: 원본 미기재 | D5: —(개당원가분석 문서정보) | F5: 고객 승인도면/BOM | G5: 생산기술 | H5: 미확인
A6: 02 | B6: 파이프 A/B OD, 두께, 길이 | C6: OD 25.4/t 1.24/L 435·315 | D6: 2. 소재 — OD, t, 길이 | F6: 도면·측정성적서 | G6: 생산기술 | H6: 미확인
A7: 03 | B7: 파이프 실제 재질·비중 | C7: STS 7.93 가정 | D7: 2. 소재 — 비중 | F7: 재질증명서 | G7: 구매/품질 | H7: 미확인
A8: 04 | B8: 파이프 1개 실측 중량 | C8: 0.55976kg 합계(계산) | D8: 개당원가분석 1절 — 파이프 A·B 중량 비교 | F8: 무게측정 기록 | G8: 품질/생산기술 | H8: 미확인
A9: 05 | B9: 파이프 최근 원재료 매입단가 | C9: 5200원/kg | D9: 2. 소재 — 소재 단가 | F9: 매입단가표·발주서 | G9: 구매 | H9: 미확인
A10: 06 | B10: 구매부품 및 부품수량 | C10: 프랜지 1·다이캐스팅 2 | D10: 3. 구매 부품·포장재 | F10: 품번별 BOM·단가표 | G10: 구매/품질 | H10: 미확인
A11: 07 | B11: 박스 1박스 입수·포장재 단위 | C11: 제품당 박스1·포장지3원 | D11: 3. 포장 — 박스 입수 | F11: 포장사양서 | G11: 생산관리/물류 | H11: 미확인
A12: 08 | B12: 로봇 1대 실제 가공 C/T | C12: 46초/개 | D12: 1. 생산 조건 — 로봇 C/T | F12: 표준작업/타임스터디 | G12: 생산기술 | H12: 미확인
A13: 09 | B13: 코킹 라인 실제 OEE | C13: 원본 미반영 | D13: 1. 생산 조건 — OEE | F13: 설비 운전/정지·양품 실적 | G13: 생산기술 | H13: 미확인
A14: 10 | B14: 조립 공정별 C/T·병목 | C14: 4명 1조 가정 | D14: 병목공정CT 시트 입력 | F14: 공정별 시간측정표 | G14: 생산/생산기술 | H14: 미확인
A15: 11 | B15: 근무시간·휴게·식사 시간표 | C15: 08:00~19:00/휴게 5회 | D15: 1. 생산 조건 — 시각·휴식·중복 제외 | F15: 근무/휴게 편성표 | G15: 생산/인사 | H15: 미확인
A16: 12 | B16: 급여 총액·수당·사업주 부담비 | C16: 320만/인·부담 0% | D16: 4. 노무·경비 — 월급·수당·부담률 | F16: 실질 원가 인건비 | G16: 인사/회계 | H16: 미확인
... A22: 18 | B22: 문서번호·Rev·승인·개정이력 | C22: 확인란 없음 | D22: 개당원가분석 문서정보 | F22: 내부 결재기준 | G22: 품질/회계 | H22: 미확인

Sheet 개정이력
A1: 개정이력
A2: R1은 변경하지 않았으며 R2는 별도 파일입니다. 작성·검토·승인 칸은 담당자가 직접 기재합니다.
A4: Rev | B4: 일자 | C4: 개정 내용 | D4: 작성 | E4: 검토 | F4: 승인
A5: R1 | B5: (원본 기재 없음) | C5: 개당원가분석표 최초 작성 (일 2,500개 기준)
A6: R2 | B6: 2026-10-28 | C6: 검토보고서(2026-10-28, 조건부 보완 필요) 지적 19건 반영: 입력/계산 시트 분리, A안(R1 재현)·B안(보수 시나리오) 병행, OEE·불량률·부담률·경비 항목 분리, 병목공정CT·민감도·반영표·현장확인 시트 신설, 시트 보호 및 입력 검증 추가. 확정 증빙이 없는 값은 R1 값 유지 또는 시나리오로 구분
