Workbook

Sheet 양식
B2: ■ 부적합품 관리대장
B4: 일자 | C4: 차종 | D4: 품명 | E4: 품번 | F4: 수량 | G4: 확인 | H4: 비고

Sheet 양식 (260818) 품번항목삭제,불량명항목추가
B2: ■ 부적합품 관리대장
B4: 일자 | C4: 차종 | D4: 품명 | E4: 불량명 | F4: 수량 | G4: 확인 | H4: 비고

Sheet 양식 (260909) 문서번호부여
B2: ■ 부적합품 관리대장
B4: 일자 | C4: 차종 | D4: 품명 | E4: 불량명 | F4: 수량 | G4: 확인 | H4: 비고

Sheet DATA
J1: 작성 | K1: 검토 | L1: 승인
B2: ■ 부적합품 관리대장_2026년 | G2: =SUM(G5:G5283) -> 5527 | J2: 박미광 | K2: 박철호 | L2: 조현우
B4: 일자 | C4: 공정 | D4: 차종 | E4: 품명 | F4: 불량명 | G4: 수량 | H4: 확인 | I4: 비고
B5: 46197 | C5: 1동 | D5: US4 | E5: =IFERROR(VLOOKUP(D5,Sheet1!B:F,4,0),"") | F5: 찍힘 | G5: 1
B6: 46202 | C6: 1동 | D6: JK1 | E6: =IFERROR(VLOOKUP(D6,Sheet1!B:F,4,0),"") | F6: 찍힘 | G6: 1
B7: 46206 | C7: 1동 | D7: CN8 HTR | E7: =IFERROR(VLOOKUP(D7,Sheet1!B:F,4,0),"") | F7: 작업불량(변형) | G7: 1
B8: 46210 | C8: 1동 | D8: NX5 | E8: =IFERROR(VLOOKUP(D8,Sheet1!B:F,4,0),"") | F8: 찍힘 | G8: 1
B9: 46213 | C9: 1동 | D9: V710 HTR AA | E9: =IFERROR(VLOOKUP(D9,Sheet1!B:F,4,0),"") | F9: 변형 | G9: 1
B10: 46216 | C10: 1동 | D10: V710 EVAP IN | E10: =IFERROR(VLOOKUP(D10,Sheet1!B:F,4,0),"") | F10: 작업불량 | G10: 1
B11: 46218 | C11: 1동 | D11: CN8 HTR OUT | E11: =IFERROR(VLOOKUP(D11,Sheet1!B:F,4,0),"") | F11: 작업불량 | G11: 1
B12: 46223 | C12: 1동 | D12: V710 HTR OUT RA | E12: =IFERROR(VLOOKUP(D12,Sheet1!B:F,4,0),"") -> OUTLET TUBE-HTR | F12: 찍힘 | G12: 1
B13: 46223 | C13: 1동 | D13: V710 HTR IN RA | E13: =IFERROR(VLOOKUP(D13,Sheet1!B:F,4,0),"") -> INLET TUBE-HTR | F13: 치수미달 | G13: 5
B14: 46223 | C14: 1동 | D14: V710 EVAP IN AA | E14: =IFERROR(VLOOKUP(D14,Sheet1!B:F,4,0),"") -> TUBE INLET-EVAP CORE | F14: 찍힘 | G14: 3
B15: 46223 | C15: 1동 | D15: V710 HTR IN AA | E15: =IFERROR(VLOOKUP(D15,Sheet1!B:F,4,0),"") -> INLET TUBE-HTR | F15: 밴딩 | G15: 1
B16: 46223 | C16: 1동 | D16: V710 HTR IN AA | E16: =IFERROR(VLOOKUP(D16,Sheet1!B:F,4,0),"") -> INLET TUBE-HTR | F16: 찍힘 | G16: 3
... B35: 46225 | C35: 6동 | D35: NX5 JUMP TUBE AA | E35: =IFERROR(VLOOKUP(D35,Sheet1!B:F,4,0),"") -> JUMP TUBE AA 핀무 | F35: 셋팅 | G35: 4
B36: 46225 | C36: 6동 | D36: NX5 JUMP TUBE AA | E36: =IFERROR(VLOOKUP(D36,Sheet1!B:F,4,0),"") -> JUMP TUBE AA 핀무 | F36: 설비 | G36: 4 | I36: 파스피다 고장 에러 Ø12
B37: 46225 | C37: 6동 | D37: NX5 JUMP TUBE AA | E37: =IFERROR(VLOOKUP(D37,Sheet1!B:F,4,0),"") -> JUMP TUBE AA 핀무 | F37: 셋팅 | G37: 4
B38: 46225 | C38: 6동 | D38: NX5 JUMP TUBE AA | E38: =IFERROR(VLOOKUP(D38,Sheet1!B:F,4,0),"") -> JUMP TUBE AA 핀무 | F38: 셋팅 | G38: 16 | I38: Ø9
B39: 46225 | C39: 6동 | D39: NX5 JUMP TUBE AA | E39: =IFERROR(VLOOKUP(D39,Sheet1!B:F,4,0),"") -> JUMP TUBE AA 핀무 | F39: 밴딩 | G39: 4 | I39: Ø9
B40: 46226 | C40: 1동 | D40: V710 EVAP OUT RA | E40: =IFERROR(VLOOKUP(D40,Sheet1!B:F,4,0),"") -> TUBE OUTLET-EVAP CORE | G40: 1
B41: 46226 | C41: 1동 | D41: V710 EVAP OUT AA | E41: =IFERROR(VLOOKUP(D41,Sheet1!B:F,4,0),"") -> TUBE OUTLET-EVAP CORE | F41: 셋팅 | G41: 22
B42: 46226 | C42: 1동 | D42: NEaW AMC | E42: =IFERROR(VLOOKUP(D42,Sheet1!B:F,4,0),"") -> FT-ASY-A/C JUMPER | F42: 작업불량(찍힘) | G42: 2
B43: 46226 | C43: 1동 | D43: NEaW AMC | E43: =IFERROR(VLOOKUP(D43,Sheet1!B:F,4,0),"") -> FT-ASY-A/C JUMPER | F43: 밴딩 | G43: 1
B44: 46226 | C44: 1동 | D44: NEaW AMC | E44: =IFERROR(VLOOKUP(D44,Sheet1!B:F,4,0),"") -> FT-ASY-A/C JUMPER | F44: 용접 | G44: 1
B45: 46226 | C45: 1동 | D45: NEaW AAA | E45: =IFERROR(VLOOKUP(D45,Sheet1!B:F,4,0),"") -> FT-ASY-A/C JUMPER | F45: 작업불량(찍힘) | G45: 3
B46: 46226 | C46: 1동 | D46: NEaW AAA | E46: =IFERROR(VLOOKUP(D46,Sheet1!B:F,4,0),"") -> FT-ASY-A/C JUMPER | F46: 용접과열,핀홀 | G46: 6
B47: 46226 | C47: 1동 | D47: NEaW AAA | E47: =IFERROR(VLOOKUP(D47,Sheet1!B:F,4,0),"") -> FT-ASY-A/C JUMPER | F47: 작업불량(찌그러짐) | G47: 5
B48: 46226 | C48: 1동 | D48: NEaW AAA | E48: =IFERROR(VLOOKUP(D48,Sheet1!B:F,4,0),"") -> FT-ASY-A/C JUMPER | G48: 2
B49: 46226 | C49: 1동 | D49: JLR ZA | E49: =IFERROR(VLOOKUP(D49,Sheet1!B:F,4,0),"") -> COOLANT SPOUT-WCAC | G49: 1
B50: 46226 | C50: 1동 | D50: JLR CA | E50: =IFERROR(VLOOKUP(D50,Sheet1!B:F,4,0),"") -> COOLANT SPOUT-WCAC | G50: 2
B51: 46226 | C51: 1동 | D51: CN8 AA | E51: =IFERROR(VLOOKUP(D51,Sheet1!B:F,4,0),"") | F51: 코킹 | G51: 17 | I51: Ø15
B52: 46226 | C52: 1동 | D52: V710 EVAP OUT RA | E52: =IFERROR(VLOOKUP(D52,Sheet1!B:F,4,0),"") -> TUBE OUTLET-EVAP CORE | F52: 찍힘 | G52: 1
B53: 46226 | C53: 1동 | D53: JLR ZA | E53: =IFERROR(VLOOKUP(D53,Sheet1!B:F,4,0),"") -> COOLANT SPOUT-WCAC | F53: 눌림 | G53: 1
B54: 46226 | C54: 1동 | D54: JLR CA | E54: =IFERROR(VLOOKUP(D54,Sheet1!B:F,4,0),"") -> COOLANT SPOUT-WCAC | F54: 찍힘 | G54: 2
B55: 46227 | C55: 1동 | D55: V710 HTR IN RA | E55: =IFERROR(VLOOKUP(D55,Sheet1!B:F,4,0),"") -> INLET TUBE-HTR | G55: 14
B56: 46227 | C56: 1동 | D56: JLR AA | E56: =IFERROR(VLOOKUP(D56,Sheet1!B:F,4,0),"") -> COOLANT SPOUT-WCAC | F56: 찍힘 | G56: 1
B57: 46227 | C57: 1동 | D57: JLR ZA | E57: =IFERROR(VLOOKUP(D57,Sheet1!B:F,4,0),"") -> COOLANT SPOUT-WCAC | F57: 찍힘 | G57: 4
B58: 46227 | C58: 1동 | D58: JLR ZA | E58: =IFERROR(VLOOKUP(D58,Sheet1!B:F,4,0),"") -> COOLANT SPOUT-WCAC | F58: 칼라 역조립 | G58: 2
B59: 46228 | C59: 1동 | D59: JLR ZA | E59: =IFERROR(VLOOKUP(D59,Sheet1!B:F,4,0),"") -> COOLANT SPOUT-WCAC | F59: 칼라 역조립 | G59: 2
...

Sheet Sheet1
B1: 1 | C1: 2 | D1: 3 | E1: 4 | F1: 5
B2: 차종Ⅰ | C2: 차종 Ⅱ | D2: 품번 | E2: 품명 | F2: 고객사
B3: JLR | C3: JLR | F3: 한온
B4: JLR AA | C4: JLR | D4: HW741D5LAA01 | E4: COOLANT SPOUT-WCAC | F4: 한온
B5: JLR BA | C5: JLR | D5: HW741D5LBA01 | E5: COOLANT SPOUT-WCAC | F5: 한온
B6: JLR CA | C6: JLR | D6: HW741D5LCA02 | E6: COOLANT SPOUT-WCAC | F6: 한온
B7: JLR ZA | C7: JLR | D7: HW741D5LZA01 | E7: COOLANT SPOUT-WCAC | F7: 한온
B8: JX1 HEV 16T AA | C8: JX1 16T | D8: FA1A8L9SAA03 | E8: FA-ASY-A/C-JUMPER | F8: 한온
B9: JX1 20T AA | C9: JX1 20T
B10: V710 EVAP IN AA | C10: V710 EVAP | D10: HE330G7FAA01 | E10: TUBE INLET-EVAP CORE | F10: 한온
B11: V710 EVAP OUT AA | C11: V710 EVAP | D11: HE331G7FAA01 | E11: TUBE OUTLET-EVAP CORE | F11: 한온
B12: V710 HTR IN AA | C12: V710 HTR | D12: HH260G7FAA01 | E12: INLET TUBE-HTR | F12: 한온
B13: V710 HTR OUT AA | C13: V710 HTR | D13: HH261G7FAA01 | E13: OUTLET TUBE-HTR | F13: 한온
B14: V710 EVAP IN RA | C14: V710 EVAP | D14: HE330G7FRA02 | E14: TUBE INLET-EVAP CORE | F14: 한온
B15: V710 EVAP OUT RA | C15: V710 EVAP | D15: HE331G7FRA02 | E15: TUBE OUTLET-EVAP CORE | F15: 한온
B16: V710 HTR IN RA | C16: V710 HTR | D16: HH260G7FRA01 | E16: INLET TUBE-HTR | F16: 한온
B17: V710 HTR OUT RA | C17: V710 HTR | D17: HH261G7FRA01 | E17: OUTLET TUBE-HTR | F17: 한온
B18: CN8 EVAP AA | C18: CN8 EVAP | D18: HE333HCNAA | E18: EVAP PIPE LHD | F18: 한온
B19: CN8 HTR IN AA | C19: CN8 HTR | D19: HH260HCNAA | E19: HTR PIPE IN LHD | F19: 한온
B20: CN8 HTR OUT AA | C20: CN8 HTR | D20: HH261HCNAA | E20: HTR OUT PIPE LHD | F20: 한온
B21: CN8 HEV HTR IN AA | C21: CN8 HEV HTR | D21: HH260L8FAA | E21: HEV HTR PIPE IN LHD | F21: 한온
... B42: NEaW AAA | C42: NEaW | D42: FA1A8HEAAA01 | E42: FT-ASY-A/C JUMPER | F42: 한온
B43: SX3 | C43: SX3 | F43: 한온
B44: JK1 HEV | C44: JK1 HEV | D44: FA1A8JKHAA02 | E44: FT-ASY-A/C JUMPER | F44: 한온
B45: JK1 EREV | C45: JKa EREV | D45: FA1A8JVRAA02 | E45: FT-ASY-A/C JUMPER | F45: 한온

Sheet Sheet2
B2: 결재 | C2: 작성 | D2: 검토 | E2: 승인
